Workbook

Sheet คู่มือ Guide
B1: คู่มือการใช้งาน / User Guide — Project Control: Plan vs Actual (v2)
B3: 1. ภาพรวมไฟล์ / Workbook Overview
B4: ไฟล์นี้ใช้ควบคุมและรายงานความก้าวหน้าโครงการก่อสร้างตามแนวทางสากล ได้แก่ การวัดผลงานถ่วงน้ำหนัก (Weighted Progress), S-Curve, Earned Value Management (EVM) และ Earned Schedule (ES) พร้อมทะเบียนขยายเวลาและการคำนวณค่าปรับ ใช้ซ้ำกับโครงการอื่นได้
B5: ชีต / Sheet | C5: ใช้ทำอะไร / Purpose | D5: ต้องกรอกอะไร / What to fill
B6: ตั้งค่า Setup | C6: ข้อมูลหลักของสัญญา วันที่ตรวจวัด รอบตัดงวด อัตราค่าปรับ และรายชื่อหมวดงาน (WBS ระดับ 1) | D6: ทุกช่องสีเหลือง (ตั้งค่าครั้งแรก) + เปลี่ยน Status Date ทุกงวด
B7: Dashboard | C7: สรุปตัวชี้วัดทั้งหมด (เวลา / ต้นทุน / ขยายเวลา-ค่าปรับ) พร้อมกราฟ S-Curve และกราฟ EVM | D7: ไม่ต้องกรอก – คำนวณอัตโนมัติ
B8: รายงาน Report | C8: รายงานประจำงวดพร้อมพิมพ์ (A4) ใช้ส่งผู้ว่าจ้าง/ผู้ควบคุมงาน มีช่องลงนาม | D8: กรอกเฉพาะหัวข้อ 6 ปัญหาและแนวทางแก้ไข
B9: แผนงาน Schedule | C9: รายการงานแบบ WBS: น้ำหนักงาน, แผนเดิม (Baseline), แผนเร่งรัด (Revised), ผลงานจริง, การวิเคราะห์รายรายการ และ Gantt Chart | D9: ครั้งแรก: หมวด รายการ น้ำหนัก วันตามแผน • ทุกงวด: วันเริ่ม/เสร็จจริง และ % จริง
B10: S-Curve | C10: ตารางรายงวดสำหรับ S-Curve และ EVM (PV / EV / AC) รวมถึงเงินเบิกจ่าย | D10: ทุกงวด: % จริงสะสม, AC ต้นทุนจริงในงวด, เงินเบิกจ่ายในงวด
B11: ขยายเวลา EOT | C11: ทะเบียนเหตุการณ์ล่าช้าและการขอขยายเวลา (EOT) – วันที่อนุมัติจะไปขยายวันสิ้นสุดสัญญาอัตโนมัติ | D11: ทุกครั้งที่มีเหตุการณ์ล่าช้า / ยื่นหนังสือ / ได้รับผลพิจารณา
B13: 2. สัญลักษณ์สี / Color Legend
B14: ช่องพื้นเหลือง ตัวน้ำเงิน | C14: ช่องที่ให้กรอก (Input) – แก้ไขได้
B15: ช่องพื้นขาว ตัวดำ | C15: สูตรคำนวณ – ถูกล็อกไว้กันแก้โดยไม่ตั้งใจ | D15: ปลดล็อก: รีวิว (Review) → ยกเลิกการป้องกันแผ่นงาน (ไม่มีรหัสผ่าน)
B16: Gantt สีฟ้า | C16: ช่วงเวลาตามแผนเดิม (Baseline)
B17: Gantt สีส้ม | C17: ช่วงที่ทำงานจริง (นอกช่วงแผน)
B18: Gantt สีเขียว | C18: ทำงานจริงตรงกับช่วงแผน
B19: หัวคอลัมน์ Gantt สีแดง | C19: งวดที่มีวันตรวจวัด (Status Date)
B20: แถวสีส้มอ่อนในชีต S-Curve | C20: งวดปัจจุบัน – กรอกผลงานจริงของงวดนี้
B21: สถานะสีแดง / เหลือง / เขียว | C21: ล่าช้ามาก / เฝ้าระวัง / ตามแผน
B23: 3. ขั้นตอนตั้งค่าโครงการใหม่ / New Project Setup
B24: 1) ชีต ตั้งค่า Setup: กรอกชื่อโครงการ คู่สัญญา มูลค่าสัญญา วันเริ่ม ระยะเวลา อัตราค่าปรับ และรายชื่อหมวดงาน (สูงสุด 10 หมวด)
B25: 2) ชีต แผนงาน Schedule: ลบข้อมูลเดิมในช่องสีเหลือง แล้วกรอกรายการงาน (สูงสุด 60 รายการ) เลือกหมวดจาก Drop-down รหัส WBS จะสร้างให้เอง
B26: 3) น้ำหนักงาน: กรอก 'น้ำหนักกำหนดเอง' หรือกรอก 'มูลค่า BOQ' อย่างเดียวแล้วระบบคำนวณน้ำหนักจากสัดส่วนมูลค่าให้ • รวมต้องได้ 100% (ดูช่องตรวจสอบใน Dashboard)
B27: 4) กรอกวันเริ่ม-เสร็จตามแผนเดิม (Baseline) – เมื่อได้รับอนุมัติแผนแล้ว ไม่ควรแก้ Baseline อีก ถ้าแผนเปลี่ยนให้ใช้คอลัมน์ Revised
B28: 5) ชีต S-Curve และ ขยายเวลา EOT: ลบข้อมูลเดิมในช่องสีเหลือง
B30: 4. ขั้นตอนอัปเดตทุกงวด / Periodic Update Routine
B31: 1) ตั้งค่า Setup → เปลี่ยน 'วันที่ตรวจวัดผลงาน (Status Date)'
B32: 2) แผนงาน Schedule → กรอกวันเริ่มจริง วันเสร็จจริง (เว้นว่างถ้ายังไม่เสร็จ) และ % ความคืบหน้าของแต่ละรายการ
B33: 3) S-Curve → ที่แถวสีส้ม กรอก Actual % สะสม (คัดลอกค่าจากแถวรวม คอลัมน์ '% งานนี้' ในชีตแผนงาน), AC ต้นทุนจริงในงวด และเงินเบิกจ่ายในงวด
B34: 4) ขยายเวลา EOT → บันทึกเหตุการณ์ล่าช้าใหม่ / อัปเดตผลพิจารณา
B35: 5) รายงาน Report → กรอกปัญหาและแนวทางแก้ไข แล้วสั่งพิมพ์ (A4 แนวตั้ง 2 หน้า)
... B38: 5. ความหมายของคอลัมน์ในชีตแผนงาน / Schedule Columns
B39: คอลัมน์ / Column | C39: ความหมาย / Meaning | D39: วิธีคำนวณ / How calculated
B40: WBS | C40: รหัสโครงสร้างงาน: เลขหมวด.ลำดับในหมวด เช่น 2.3 = หมวดที่ 2 รายการที่ 3 | D40: อัตโนมัติจากหมวดที่เลือก
B41: น้ำหนักที่ใช้ / Weight Used | C41: สัดส่วนความสำคัญของงานเทียบทั้งโครงการ ใช้ถ่วงน้ำหนักผลงาน | D41: ใช้น้ำหนักกำหนดเอง ถ้าไม่มีใช้ BOQ ÷ BOQ รวม
B42: งบประมาณ / Budget | C42: มูลค่างานของรายการตามสัดส่วนสัญญา | D42: น้ำหนัก × มูลค่าสัญญา
B43: BASELINE แผนเดิม | C43: แผนตามสัญญาที่ได้รับอนุมัติ ใช้เป็นเกณฑ์วัดผลตลอดโครงการ | D43: กรอกเอง
B44: REVISED แผนเร่งรัด | C44: แผนปรับปรุง/แผนเร่งรัดเพื่อกู้สถานการณ์ (Recovery Plan) – ไม่บังคับ | D44: ถ้าเว้นว่าง ระบบใช้ค่า Baseline
B45: % งานนี้ / % Complete | C45: ความคืบหน้าของรายการนั้นเอง (ไม่ใช่ % ของโครงการ) | D45: กรอกเอง จากการวัดหน้างาน
B46: % แผน ณ Status | C46: รายการนี้ควรเสร็จกี่ % ณ วันตรวจวัด | D46: กระจายเชิงเส้นตามวันเริ่ม-เสร็จแผน
...

Sheet ตั้งค่า Setup
B1: ตั้งค่าโครงการ / Project Setup
B2: กรอกเฉพาะช่องสีเหลือง • Fill in yellow cells only
B3: รายการ / Item | C3: ค่า / Value | D3: หมายเหตุ / Note
B4: ชื่อโครงการ (ไทย) / Project name (TH) | C4: โครงการก่อสร้างอาคาร (แก้ไขชื่อได้)
B5: ชื่อโครงการ (อังกฤษ) / Project name (EN) | C5: Building Construction Project
B6: ผู้ว่าจ้าง / Employer
B7: ผู้รับจ้าง / Contractor
B8: เลขที่สัญญา / Contract No.
B9: มูลค่าสัญญา / Contract Value = BAC (บาท) | C9: 12108000 | D9: อ่านจากเอกสารแผนงาน (Summary) – กรุณาตรวจสอบกับสัญญา
B10: วันเริ่มสัญญา / Commencement Date | C10: 46073 | D10: จากเอกสารแผนงาน 20-Feb-26
B11: ระยะเวลาสัญญา / Contract Duration (วัน/days) | C11: 270 | D11: จากเอกสารแผนงาน 270 วัน
B12: วันสิ้นสุดตามสัญญาเดิม / Original Completion | C12: =C10+C11-1 -> 46342 | D12: นับวันเริ่มเป็นวันที่ 1 (เอกสารระบุ 17-Nov-26 – พิมพ์ทับได้)
B13: ขยายเวลาที่อนุมัติแล้ว / Approved EOT (วัน) | C13: =SUM('ขยายเวลา EOT'!$J$8:$J$57) -> 0 | D13: ดึงจากชีต ขยายเวลา EOT อัตโนมัติ
B14: วันสิ้นสุดหลังขยายเวลา / Revised Completion | C14: =C12+C13 -> 46342 | D14: วันสิ้นสุดสัญญาเดิม + วันขยายเวลาที่อนุมัติ
B15: วันที่ตรวจวัดผลงาน / Status Date | C15: 46293 | D15: เปลี่ยนทุกครั้งที่อัปเดตรายงาน
B16: รอบตัดงวด S-Curve / Reporting Period | C16: ทุก 10 วัน / 10-day | D16: ทุก 10 วัน (ตัดวันที่ 10, 20, สิ้นเดือน) / รายสัปดาห์ / รายเดือน
B17: อัตราค่าปรับต่อวัน / LD Rate (% of contract per day) | C17: 0.001 | D17: ตัวอย่าง 0.10% – กรุณาใส่อัตราตามสัญญาจริง
B18: ค่าปรับขั้นต่ำต่อวัน / Minimum LD per day (บาท) | C18: 100 | D18: ตามที่สัญญากำหนด (ถ้าไม่มีใส่ 0)
B19: เกณฑ์เตือนค่าปรับสะสม / LD Warning Threshold | C19: 0.1 | D19: หลายสัญญากำหนดให้ผู้ว่าจ้างพิจารณาบอกเลิกได้เมื่อค่าปรับเกิน 10%
B20: ช่วงแผนงานล่วงหน้า / Look-ahead (วัน/days) | C20: 30 | D20: ใช้ในรายงานประจำงวด
B21: รายงานงวดที่ / Report No. | C21: 1
B22: ผู้จัดทำรายงาน / Prepared by
B24: หมวดงาน (WBS ระดับ 1) / Work Categories | C24: ชื่อหมวด / Category name | D24: หมายเหตุ
B25: เลขหมวด = ลำดับในตาราง (ใช้สร้างรหัส WBS เช่น 2.3)
B26: หมวดที่ 1 | C26: งานเตรียมการ / Preliminaries | D26: ตัวอย่างการจัดหมวดจากแผนงานเดิม – แก้ไขได้
B27: หมวดที่ 2 | C27: งานโครงสร้าง / Structural Works
B28: หมวดที่ 3 | C28: งานสถาปัตยกรรม / Architectural Works
B29: หมวดที่ 4 | C29: งานระบบ / MEP Works
B30: หมวดที่ 5 | C30: งานภายนอกและทดสอบระบบ / External & Commissioning
B31: หมวดที่ 6
B32: หมวดที่ 7
B33: หมวดที่ 8
B34: หมวดที่ 9
B35: หมวดที่ 10
B36: หมวดที่ 11
B37: หมวดที่ 12
B38: หมวดที่ 13
B39: หมวดที่ 14
B40: หมวดที่ 15
B41: หมวดที่ 16
...

Sheet Dashboard
B1: แดชบอร์ดควบคุมโครงการ / Project Control Dashboard
B2: คำนวณอัตโนมัติทั้งหมด • All values are calculated
B3: ข้อมูลอ้างอิง / Reference | C3: ค่า / Value | D3: ความหมาย / Meaning
B4: โครงการ / Project | C4: ='ตั้งค่า Setup'!C4 -> โครงการก่อสร้างอาคาร (แก้ไขชื่อได้)
B5: วันที่ตรวจวัด / Status Date | C5: ='ตั้งค่า Setup'!$C$15 -> 46293
B6: แหล่งข้อมูลผลงานจริง / Actual Data Source | C6: =IF(COUNT('แผนงาน Schedule'!$O$7:$O$66)>0,"ชีตแผนงาน (รายรายการ)","ชีต S-Curve (ค่าสะสมล่าสุด)") -> ชีต S-Curve (ค่าสะสมล่าสุด) | D6: ถ้ากรอก % จริงรายรายการ จะใช้ข้อมูลรายรายการก่อน
B7: ข้อมูลจริง ณ วันที่ / Data Date | C7: =IF(COUNT('แผนงาน Schedule'!$O$7:$O$66)>0,'ตั้งค่า Setup'!$C$15,IFERROR(INDEX('S-Curve'!$C$7:$C$86,MATCH(9.99E+307,'S-Curve'!$F$7:$F$86)),'ตั้งค่า Setup'!$C$15)) -> 46142 | D7: ถ้าไม่ตรงวันที่ตรวจวัด (สีแดง) = ยังไม่อัปเดตผลงานจริงล่าสุด
B8: ด้านเวลา / SCHEDULE PERFORMANCE | C8: ค่า / Value | D8: ความหมาย / Meaning
B9: วันเริ่มสัญญา / Commencement | C9: ='ตั้งค่า Setup'!$C$10 -> 46073
B10: วันสิ้นสุดสัญญาเดิม / Original Completion | C10: ='ตั้งค่า Setup'!C12 -> 46342
B11: ขยายเวลาที่อนุมัติ / Approved EOT (วัน) | C11: ='ตั้งค่า Setup'!C13 -> 0 | D11: จากทะเบียนขยายเวลา
B12: วันสิ้นสุดหลังขยายเวลา / Revised Completion | C12: ='ตั้งค่า Setup'!$C$14 -> 46342
B13: วันที่ดำเนินการแล้ว / Days Elapsed | C13: ='ตั้งค่า Setup'!$C$15-'ตั้งค่า Setup'!$C$10+1 -> 221 | D13: ณ วันที่ตรวจวัด นับวันเริ่มเป็นวันที่ 1
B14: % เวลาที่ใช้ไป / Time Elapsed | C14: =IFERROR(C13/(C12-C9+1),0) -> 0.81851852 | D14: เทียบกับระยะเวลารวมหลังขยายเวลา
B15: วันคงเหลือ / Days Remaining | C15: =C12-C5 -> 49 | D15: ติดลบ = เลยกำหนดสัญญาแล้ว
B16: % แผนเดิม / Baseline Planned % | C16: =SUMPRODUCT('แผนงาน Schedule'!$F$7:$F$66,('แผนงาน Schedule'!$I$7:$I$66<=C7)+('แผนงาน Schedule'!$H$7:$H$66<=C7)*('แผนงาน Schedule'!$I$7:$I$66>C7)*(C7-'แผนงาน Schedule'!$H$7:$H$66+1)/('แผนงาน Schedule'!$I$7:$I$66-'แผนงาน Schedule'!$H$7:$H$66+1)) -> 0.20820323 | D16: ผลงานที่ควรทำได้ตามแผนสัญญา ณ Data Date
B17: % แผนเร่งรัด / Revised Planned % | C17: =IF(C63,SUMPRODUCT('แผนงาน Schedule'!$F$7:$F$66,('แผนงาน Schedule'!$AA$7:$AA$66<=C7)+('แผนงาน Schedule'!$Z$7:$Z$66<=C7)*('แผนงาน Schedule'!$AA$7:$AA$66>C7)*(C7-'แผนงาน Schedule'!$Z$7:$Z$66+1)/('แผนงาน Schedule'!$AA$7:$AA$66-'แผนงาน Schedule'!$Z$7:$Z$66+1)),C16) -> 0.20820323 | D17: ถ้ายังไม่มีแผนเร่งรัด จะเท่ากับแผนเดิม
B18: ผลต่างเทียบแผนเร่งรัด / Variance vs Revised | C18: =C19-C17 -> -0.15690323 | D18: ใช้ติดตามว่าเดินตามแผนเร่งรัดได้หรือไม่
B19: % ผลงานจริง / Actual % | C19: =IF(COUNT('แผนงาน Schedule'!$O$7:$O$66)>0,'แผนงาน Schedule'!$O$67,IFERROR(INDEX('S-Curve'!$F$7:$F$86,MATCH(9.99E+307,'S-Curve'!$F$7:$F$86)),0)) -> 0.0513
B20: ผลต่าง / Variance (Actual − Baseline) | C20: =C19-C16 -> -0.15690323 | D20: ติดลบ = ช้ากว่าแผน
B21: ผลต่างคิดเป็นวัน / Variance in Days | C21: =C20*C69 -> -42.363871 | D21: ผลต่าง % × ระยะเวลาสัญญา (วิธีรายงานแบบไทย)
B22: SPI (ดัชนีเวลา) | C22: =IFERROR(C37/C36,0) -> 0.24639388 | D22: EV ÷ PV • ≥1 ตามแผน / 0.9–1 เฝ้าระวัง / <0.9 ล่าช้ามาก
B23: Earned Schedule – ES (วัน) | C23: =C68 -> 22.27852 | D23: งานที่ทำได้จริง เท่ากับแผนของวันที่เท่าใด (นับจากวันเริ่ม)
B24: Actual Time – AT (วัน) | C24: =C7-C9+1 -> 70 | D24: เวลาที่ใช้จริงถึง Data Date
B25: SV(t) – ช้ากว่าแผนจริง (วัน) | C25: =C23-C24 -> -47.72148 | D25: ติดลบ = ช้ากว่าแผนกี่วัน (แม่นกว่า SPI ในช่วงท้ายโครงการ)
B26: SPI(t) (ดัชนีเวลาเชิงวัน) | C26: =IFERROR(C23/C24,0) -> 0.31826457 | D26: ES ÷ AT
B27: คาดการณ์วันแล้วเสร็จ / Forecast Completion | C27: =IF(C19>=1,C7,IF(COUNT('แผนงาน Schedule'!$O$7:$O$66)>0,MAX('แผนงาน Schedule'!$V$7:$V$66),IFERROR(C9+ROUND(C69/C26,0)-1,"-"))) -> 46920 | D27: ถ้ามี % รายรายการ ใช้วันเสร็จคาดการณ์รายงาน • ถ้าไม่มี ใช้ IEAC(t) = ระยะเวลา ÷ SPI(t)
B28: คาดว่าล่าช้ากว่าสัญญา / Forecast Delay (วัน) | C28: =IFERROR(MAX(0,C27-C12),"-") -> 578 | D28: เทียบกับวันสิ้นสุดหลังขยายเวลา
B29: อัตราผลงานจริงเฉลี่ย / Actual Rate (%/วัน) | C29: =IFERROR(C19/C24,0) -> 0.00073285714
B30: อัตราที่ต้องทำ / Required Rate (%/วัน) | C30: =IF(C19>=1,0,IF(C12-C7>0,(1-C19)/(C12-C7),"เลยกำหนดแล้ว")) -> 0.0047435 | D30: เพื่อให้เสร็จทันวันสิ้นสุดหลังขยายเวลา
B31: ต้องเร่งงาน / Acceleration Needed (เท่า) | C31: =IFERROR(C30/C29,"-") -> 6.4726121 | D31: เท่าของอัตราผลงานปัจจุบัน
B32: สถานะโครงการ / Overall Status | C32: =IF(C19>=1,"แล้วเสร็จ / Completed",IF(C22>=1,"ตามแผน / On Track",IF(C22>=0.9,"เฝ้าระวัง / At Risk","ล่าช้ามาก / Critical Delay"))) -> ล่าช้ามาก / Critical Delay
B33: จำนวนรายการที่ล่าช้า / Items Behind | C33: =COUNTIF('แผนงาน Schedule'!$X$7:$X$66,"*ล่าช้า*")+COUNTIF('แผนงาน Schedule'!$X$7:$X$66,"*เกินกำหนด*") -> 15 | D33: จากชีตแผนงาน (ต้องกรอก % รายรายการ)
B34: ด้านต้นทุน / COST PERFORMANCE (EVM) | C34: ค่า / Value | D34: ความหมาย / Meaning
B35: BAC – งบประมาณรวม / Budget at Completion | C35: ='ตั้งค่า Setup'!$C$9 -> 12108000 | D35: มูลค่าสัญญา
B36: PV – มูลค่างานตามแผน / Planned Value | C36: =C16*C35 -> 2520924.7 | D36: มูลค่างานที่ควรทำได้ตามแผน
B37: EV – มูลค่างานที่ทำได้จริง / Earned Value | C37: =C19*C35 -> 621140.4 | D37: มูลค่างานที่ทำเสร็จจริง (ตามราคาสัญญา)
B38: AC – ต้นทุนจริงสะสม / Actual Cost | C38: =SUMIFS('S-Curve'!$K$7:$K$86,'S-Curve'!$C$7:$C$86,"<="&C7) -> 0 | D38: เงินที่จ่ายไปจริง (กรอกในชีต S-Curve) • ถ้าเป็น 0 จะไม่คำนวณ CPI
B39: SV – ผลต่างด้านเวลา (บาท) / Schedule Variance | C39: =C37-C36 -> -1899784.3 | D39: EV − PV • ติดลบ = งานช้ากว่าแผน
B40: CV – ผลต่างด้านต้นทุน / Cost Variance | C40: =IF(C38>0,C37-C38,"-") -> - | D40: EV − AC • ติดลบ = ใช้เงินเกินมูลค่างานที่ได้
...

Sheet รายงาน Report
B1: รายงานความก้าวหน้าโครงการ / PROJECT PROGRESS REPORT
B2: โครงการ / Project: | D2: ='ตั้งค่า Setup'!C4&IF('ตั้งค่า Setup'!C5<>""," ("&'ตั้งค่า Setup'!C5&")","") -> โครงการก่อสร้างอาคาร (แก้ไขชื่อได้) (Building Construction Project) | G2: รายงานงวดที่ / Report No.: | I2: ='ตั้งค่า Setup'!C21 -> 1
B3: ผู้ว่าจ้าง / Employer: | D3: ='ตั้งค่า Setup'!C6&"" | G3: วันที่ตรวจวัด / Status Date: | I3: ='ตั้งค่า Setup'!$C$15 -> 46293
B4: ผู้รับจ้าง / Contractor: | D4: ='ตั้งค่า Setup'!C7&"" | G4: เลขที่สัญญา / Contract No.: | I4: ='ตั้งค่า Setup'!C8&""
B6: 1. สรุปผลการดำเนินงาน / Executive Summary
B7: ระยะเวลาที่ใช้ไป / Time Elapsed | D7: =Dashboard!C14 -> 0.81851852
B8: แผนเดิม / Baseline Planned | D8: =Dashboard!C16 -> 0.20820323
B9: แผนเร่งรัด / Revised Planned | D9: =Dashboard!C17 -> 0.20820323
B10: ผลงานจริง / Actual Progress | D10: =Dashboard!C19 -> 0.0513
B11: ผลต่าง / Variance | D11: =Dashboard!C20 -> -0.15690323
B12: SPI | SPI(t) | D12: =TEXT(Dashboard!C22,"0.00")&" | "&TEXT(Dashboard!C26,"0.00") -> 0.25 | 0.32
B13: ช้ากว่าแผน / SV(t) (วัน) | D13: =Dashboard!C25 -> -47.72148
B14: คาดว่าแล้วเสร็จ / Forecast Completion | D14: =Dashboard!C27 -> 46920
B15: คาดว่าล่าช้า / Forecast Delay (วัน) | D15: =Dashboard!C28 -> 578
B16: ค่าปรับคาดการณ์ / Forecast LD (฿) | D16: =Dashboard!C55 -> 6998424
B17: CPI (ดัชนีต้นทุน) | D17: =Dashboard!C41 -> -
B18: สถานะ / Status | D18: =Dashboard!C32 -> ล่าช้ามาก / Critical Delay
B19: ข้อมูลจริง ณ / Data Date | D19: =Dashboard!C7 -> 46142
B21: 2. ความก้าวหน้าตามหมวดงาน / Progress by WBS Category
B22: หมวด No. | C22: หมวดงาน / Category | D22: น้ำหนัก Weight | E22: แผน ณ Data Date Planned | F22: จริง Actual | G22: ผลต่าง Variance | H22: SPI | I22: ผลงานแผน (% โครงการ) | J22: ผลงานจริง (% โครงการ)
B23: =IF('ตั้งค่า Setup'!$C$26="","",1) -> 1 | C23: =IF('ตั้งค่า Setup'!$C$26="","",'ตั้งค่า Setup'!$C$26) -> งานเตรียมการ / Preliminaries | D23: =IF(C23="","",SUMIF('แผนงาน Schedule'!$B$7:$B$66,C23,'แผนงาน Schedule'!$F$7:$F$66)) -> 0.0811 | E23: =IF(OR(C23="",N(D23)=0),"",I23/D23) -> 1 | F23: =IF(OR(C23="",N(D23)=0),"",J23/D23) -> 0 | G23: =IF(E23="","",F23-E23) -> -1 | H23: =IF(OR(E23="",N(E23)=0),"",F23/E23) -> 0 | I23: =IF(C23="","",SUMPRODUCT(('แผนงาน Schedule'!$B$7:$B$66=C23)*'แผนงาน Schedule'!$F$7:$F$66*(('แผนงาน Schedule'!$I$7:$I$66<=Dashboard!$C$7)+('แผนงาน Schedule'!$H$7:$H$66<=Dashboard!$C$7)*('แผนงาน Schedule'!$I$7:$I$66>Dashboard!$C$7)*(Dashboard!$C$7-'แผนงาน Schedule'!$H$7:$H$66+1)/('แผนงาน Schedule'!$I$7:$I$66-'แผนงาน Schedule'!$H$7:$H$66+1)))) -> 0.0811 | J23: =IF(C23="","",SUMPRODUCT(('แผนงาน Schedule'!$B$7:$B$66=C23)*'แผนงาน Schedule'!$F$7:$F$66*'แผนงาน Schedule'!$O$7:$O$66)) -> 0
B24: =IF('ตั้งค่า Setup'!$C$27="","",2) -> 2 | C24: =IF('ตั้งค่า Setup'!$C$27="","",'ตั้งค่า Setup'!$C$27) -> งานโครงสร้าง / Structural Works | D24: =IF(C24="","",SUMIF('แผนงาน Schedule'!$B$7:$B$66,C24,'แผนงาน Schedule'!$F$7:$F$66)) -> 0.285 | E24: =IF(OR(C24="",N(D24)=0),"",I24/D24) -> 0.44597623 | F24: =IF(OR(C24="",N(D24)=0),"",J24/D24) -> 0 | G24: =IF(E24="","",F24-E24) -> -0.44597623 | H24: =IF(OR(E24="",N(E24)=0),"",F24/E24) -> 0 | I24: =IF(C24="","",SUMPRODUCT(('แผนงาน Schedule'!$B$7:$B$66=C24)*'แผนงาน Schedule'!$F$7:$F$66*(('แผนงาน Schedule'!$I$7:$I$66<=Dashboard!$C$7)+('แผนงาน Schedule'!$H$7:$H$66<=Dashboard!$C$7)*('แผนงาน Schedule'!$I$7:$I$66>Dashboard!$C$7)*(Dashboard!$C$7-'แผนงาน Schedule'!$H$7:$H$66+1)/('แผนงาน Schedule'!$I$7:$I$66-'แผนงาน Schedule'!$H$7:$H$66+1)))) -> 0.12710323 | J24: =IF(C24="","",SUMPRODUCT(('แผนงาน Schedule'!$B$7:$B$66=C24)*'แผนงาน Schedule'!$F$7:$F$66*'แผนงาน Schedule'!$O$7:$O$66)) -> 0
B25: =IF('ตั้งค่า Setup'!$C$28="","",3) -> 3 | C25: =IF('ตั้งค่า Setup'!$C$28="","",'ตั้งค่า Setup'!$C$28) -> งานสถาปัตยกรรม / Architectural Works | D25: =IF(C25="","",SUMIF('แผนงาน Schedule'!$B$7:$B$66,C25,'แผนงาน Schedule'!$F$7:$F$66)) -> 0.2407 | E25: =IF(OR(C25="",N(D25)=0),"",I25/D25) -> 0 | F25: =IF(OR(C25="",N(D25)=0),"",J25/D25) -> 0 | G25: =IF(E25="","",F25-E25) -> 0 | H25: =IF(OR(E25="",N(E25)=0),"",F25/E25) | I25: =IF(C25="","",SUMPRODUCT(('แผนงาน Schedule'!$B$7:$B$66=C25)*'แผนงาน Schedule'!$F$7:$F$66*(('แผนงาน Schedule'!$I$7:$I$66<=Dashboard!$C$7)+('แผนงาน Schedule'!$H$7:$H$66<=Dashboard!$C$7)*('แผนงาน Schedule'!$I$7:$I$66>Dashboard!$C$7)*(Dashboard!$C$7-'แผนงาน Schedule'!$H$7:$H$66+1)/('แผนงาน Schedule'!$I$7:$I$66-'แผนงาน Schedule'!$H$7:$H$66+1)))) -> 0 | J25: =IF(C25="","",SUMPRODUCT(('แผนงาน Schedule'!$B$7:$B$66=C25)*'แผนงาน Schedule'!$F$7:$F$66*'แผนงาน Schedule'!$O$7:$O$66)) -> 0
B26: =IF('ตั้งค่า Setup'!$C$29="","",4) -> 4 | C26: =IF('ตั้งค่า Setup'!$C$29="","",'ตั้งค่า Setup'!$C$29) -> งานระบบ / MEP Works | D26: =IF(C26="","",SUMIF('แผนงาน Schedule'!$B$7:$B$66,C26,'แผนงาน Schedule'!$F$7:$F$66)) -> 0.2769 | E26: =IF(OR(C26="",N(D26)=0),"",I26/D26) -> 0 | F26: =IF(OR(C26="",N(D26)=0),"",J26/D26) -> 0 | G26: =IF(E26="","",F26-E26) -> 0 | H26: =IF(OR(E26="",N(E26)=0),"",F26/E26) | I26: =IF(C26="","",SUMPRODUCT(('แผนงาน Schedule'!$B$7:$B$66=C26)*'แผนงาน Schedule'!$F$7:$F$66*(('แผนงาน Schedule'!$I$7:$I$66<=Dashboard!$C$7)+('แผนงาน Schedule'!$H$7:$H$66<=Dashboard!$C$7)*('แผนงาน Schedule'!$I$7:$I$66>Dashboard!$C$7)*(Dashboard!$C$7-'แผนงาน Schedule'!$H$7:$H$66+1)/('แผนงาน Schedule'!$I$7:$I$66-'แผนงาน Schedule'!$H$7:$H$66+1)))) -> 0 | J26: =IF(C26="","",SUMPRODUCT(('แผนงาน Schedule'!$B$7:$B$66=C26)*'แผนงาน Schedule'!$F$7:$F$66*'แผนงาน Schedule'!$O$7:$O$66)) -> 0
B27: =IF('ตั้งค่า Setup'!$C$30="","",5) -> 5 | C27: =IF('ตั้งค่า Setup'!$C$30="","",'ตั้งค่า Setup'!$C$30) -> งานภายนอกและทดสอบระบบ / External & Commissioning | D27: =IF(C27="","",SUMIF('แผนงาน Schedule'!$B$7:$B$66,C27,'แผนงาน Schedule'!$F$7:$F$66)) -> 0.1163 | E27: =IF(OR(C27="",N(D27)=0),"",I27/D27) -> 0 | F27: =IF(OR(C27="",N(D27)=0),"",J27/D27) -> 0 | G27: =IF(E27="","",F27-E27) -> 0 | H27: =IF(OR(E27="",N(E27)=0),"",F27/E27) | I27: =IF(C27="","",SUMPRODUCT(('แผนงาน Schedule'!$B$7:$B$66=C27)*'แผนงาน Schedule'!$F$7:$F$66*(('แผนงาน Schedule'!$I$7:$I$66<=Dashboard!$C$7)+('แผนงาน Schedule'!$H$7:$H$66<=Dashboard!$C$7)*('แผนงาน Schedule'!$I$7:$I$66>Dashboard!$C$7)*(Dashboard!$C$7-'แผนงาน Schedule'!$H$7:$H$66+1)/('แผนงาน Schedule'!$I$7:$I$66-'แผนงาน Schedule'!$H$7:$H$66+1)))) -> 0 | J27: =IF(C27="","",SUMPRODUCT(('แผนงาน Schedule'!$B$7:$B$66=C27)*'แผนงาน Schedule'!$F$7:$F$66*'แผนงาน Schedule'!$O$7:$O$66)) -> 0
B28: =IF('ตั้งค่า Setup'!$C$31="","",6) | C28: =IF('ตั้งค่า Setup'!$C$31="","",'ตั้งค่า Setup'!$C$31) | D28: =IF(C28="","",SUMIF('แผนงาน Schedule'!$B$7:$B$66,C28,'แผนงาน Schedule'!$F$7:$F$66)) | E28: =IF(OR(C28="",N(D28)=0),"",I28/D28) | F28: =IF(OR(C28="",N(D28)=0),"",J28/D28) | G28: =IF(E28="","",F28-E28) | H28: =IF(OR(E28="",N(E28)=0),"",F28/E28) | I28: =IF(C28="","",SUMPRODUCT(('แผนงาน Schedule'!$B$7:$B$66=C28)*'แผนงาน Schedule'!$F$7:$F$66*(('แผนงาน Schedule'!$I$7:$I$66<=Dashboard!$C$7)+('แผนงาน Schedule'!$H$7:$H$66<=Dashboard!$C$7)*('แผนงาน Schedule'!$I$7:$I$66>Dashboard!$C$7)*(Dashboard!$C$7-'แผนงาน Schedule'!$H$7:$H$66+1)/('แผนงาน Schedule'!$I$7:$I$66-'แผนงาน Schedule'!$H$7:$H$66+1)))) | J28: =IF(C28="","",SUMPRODUCT(('แผนงาน Schedule'!$B$7:$B$66=C28)*'แผนงาน Schedule'!$F$7:$F$66*'แผนงาน Schedule'!$O$7:$O$66))
B29: =IF('ตั้งค่า Setup'!$C$32="","",7) | C29: =IF('ตั้งค่า Setup'!$C$32="","",'ตั้งค่า Setup'!$C$32) | D29: =IF(C29="","",SUMIF('แผนงาน Schedule'!$B$7:$B$66,C29,'แผนงาน Schedule'!$F$7:$F$66)) | E29: =IF(OR(C29="",N(D29)=0),"",I29/D29) | F29: =IF(OR(C29="",N(D29)=0),"",J29/D29) | G29: =IF(E29="","",F29-E29) | H29: =IF(OR(E29="",N(E29)=0),"",F29/E29) | I29: =IF(C29="","",SUMPRODUCT(('แผนงาน Schedule'!$B$7:$B$66=C29)*'แผนงาน Schedule'!$F$7:$F$66*(('แผนงาน Schedule'!$I$7:$I$66<=Dashboard!$C$7)+('แผนงาน Schedule'!$H$7:$H$66<=Dashboard!$C$7)*('แผนงาน Schedule'!$I$7:$I$66>Dashboard!$C$7)*(Dashboard!$C$7-'แผนงาน Schedule'!$H$7:$H$66+1)/('แผนงาน Schedule'!$I$7:$I$66-'แผนงาน Schedule'!$H$7:$H$66+1)))) | J29: =IF(C29="","",SUMPRODUCT(('แผนงาน Schedule'!$B$7:$B$66=C29)*'แผนงาน Schedule'!$F$7:$F$66*'แผนงาน Schedule'!$O$7:$O$66))
B30: =IF('ตั้งค่า Setup'!$C$33="","",8) | C30: =IF('ตั้งค่า Setup'!$C$33="","",'ตั้งค่า Setup'!$C$33) | D30: =IF(C30="","",SUMIF('แผนงาน Schedule'!$B$7:$B$66,C30,'แผนงาน Schedule'!$F$7:$F$66)) | E30: =IF(OR(C30="",N(D30)=0),"",I30/D30) | F30: =IF(OR(C30="",N(D30)=0),"",J30/D30) | G30: =IF(E30="","",F30-E30) | H30: =IF(OR(E30="",N(E30)=0),"",F30/E30) | I30: =IF(C30="","",SUMPRODUCT(('แผนงาน Schedule'!$B$7:$B$66=C30)*'แผนงาน Schedule'!$F$7:$F$66*(('แผนงาน Schedule'!$I$7:$I$66<=Dashboard!$C$7)+('แผนงาน Schedule'!$H$7:$H$66<=Dashboard!$C$7)*('แผนงาน Schedule'!$I$7:$I$66>Dashboard!$C$7)*(Dashboard!$C$7-'แผนงาน Schedule'!$H$7:$H$66+1)/('แผนงาน Schedule'!$I$7:$I$66-'แผนงาน Schedule'!$H$7:$H$66+1)))) | J30: =IF(C30="","",SUMPRODUCT(('แผนงาน Schedule'!$B$7:$B$66=C30)*'แผนงาน Schedule'!$F$7:$F$66*'แผนงาน Schedule'!$O$7:$O$66))
B31: =IF('ตั้งค่า Setup'!$C$34="","",9) | C31: =IF('ตั้งค่า Setup'!$C$34="","",'ตั้งค่า Setup'!$C$34) | D31: =IF(C31="","",SUMIF('แผนงาน Schedule'!$B$7:$B$66,C31,'แผนงาน Schedule'!$F$7:$F$66)) | E31: =IF(OR(C31="",N(D31)=0),"",I31/D31) | F31: =IF(OR(C31="",N(D31)=0),"",J31/D31) | G31: =IF(E31="","",F31-E31) | H31: =IF(OR(E31="",N(E31)=0),"",F31/E31) | I31: =IF(C31="","",SUMPRODUCT(('แผนงาน Schedule'!$B$7:$B$66=C31)*'แผนงาน Schedule'!$F$7:$F$66*(('แผนงาน Schedule'!$I$7:$I$66<=Dashboard!$C$7)+('แผนงาน Schedule'!$H$7:$H$66<=Dashboard!$C$7)*('แผนงาน Schedule'!$I$7:$I$66>Dashboard!$C$7)*(Dashboard!$C$7-'แผนงาน Schedule'!$H$7:$H$66+1)/('แผนงาน Schedule'!$I$7:$I$66-'แผนงาน Schedule'!$H$7:$H$66+1)))) | J31: =IF(C31="","",SUMPRODUCT(('แผนงาน Schedule'!$B$7:$B$66=C31)*'แผนงาน Schedule'!$F$7:$F$66*'แผนงาน Schedule'!$O$7:$O$66))
B32: =IF('ตั้งค่า Setup'!$C$35="","",10) | C32: =IF('ตั้งค่า Setup'!$C$35="","",'ตั้งค่า Setup'!$C$35) | D32: =IF(C32="","",SUMIF('แผนงาน Schedule'!$B$7:$B$66,C32,'แผนงาน Schedule'!$F$7:$F$66)) | E32: =IF(OR(C32="",N(D32)=0),"",I32/D32) | F32: =IF(OR(C32="",N(D32)=0),"",J32/D32) | G32: =IF(E32="","",F32-E32) | H32: =IF(OR(E32="",N(E32)=0),"",F32/E32) | I32: =IF(C32="","",SUMPRODUCT(('แผนงาน Schedule'!$B$7:$B$66=C32)*'แผนงาน Schedule'!$F$7:$F$66*(('แผนงาน Schedule'!$I$7:$I$66<=Dashboard!$C$7)+('แผนงาน Schedule'!$H$7:$H$66<=Dashboard!$C$7)*('แผนงาน Schedule'!$I$7:$I$66>Dashboard!$C$7)*(Dashboard!$C$7-'แผนงาน Schedule'!$H$7:$H$66+1)/('แผนงาน Schedule'!$I$7:$I$66-'แผนงาน Schedule'!$H$7:$H$66+1)))) | J32: =IF(C32="","",SUMPRODUCT(('แผนงาน Schedule'!$B$7:$B$66=C32)*'แผนงาน Schedule'!$F$7:$F$66*'แผนงาน Schedule'!$O$7:$O$66))
B33: =IF('ตั้งค่า Setup'!$C$36="","",11) | C33: =IF('ตั้งค่า Setup'!$C$36="","",'ตั้งค่า Setup'!$C$36) | D33: =IF(C33="","",SUMIF('แผนงาน Schedule'!$B$7:$B$66,C33,'แผนงาน Schedule'!$F$7:$F$66)) | E33: =IF(OR(C33="",N(D33)=0),"",I33/D33) | F33: =IF(OR(C33="",N(D33)=0),"",J33/D33) | G33: =IF(E33="","",F33-E33) | H33: =IF(OR(E33="",N(E33)=0),"",F33/E33) | I33: =IF(C33="","",SUMPRODUCT(('แผนงาน Schedule'!$B$7:$B$66=C33)*'แผนงาน Schedule'!$F$7:$F$66*(('แผนงาน Schedule'!$I$7:$I$66<=Dashboard!$C$7)+('แผนงาน Schedule'!$H$7:$H$66<=Dashboard!$C$7)*('แผนงาน Schedule'!$I$7:$I$66>Dashboard!$C$7)*(Dashboard!$C$7-'แผนงาน Schedule'!$H$7:$H$66+1)/('แผนงาน Schedule'!$I$7:$I$66-'แผนงาน Schedule'!$H$7:$H$66+1)))) | J33: =IF(C33="","",SUMPRODUCT(('แผนงาน Schedule'!$B$7:$B$66=C33)*'แผนงาน Schedule'!$F$7:$F$66*'แผนงาน Schedule'!$O$7:$O$66))
B34: =IF('ตั้งค่า Setup'!$C$37="","",12) | C34: =IF('ตั้งค่า Setup'!$C$37="","",'ตั้งค่า Setup'!$C$37) | D34: =IF(C34="","",SUMIF('แผนงาน Schedule'!$B$7:$B$66,C34,'แผนงาน Schedule'!$F$7:$F$66)) | E34: =IF(OR(C34="",N(D34)=0),"",I34/D34) | F34: =IF(OR(C34="",N(D34)=0),"",J34/D34) | G34: =IF(E34="","",F34-E34) | H34: =IF(OR(E34="",N(E34)=0),"",F34/E34) | I34: =IF(C34="","",SUMPRODUCT(('แผนงาน Schedule'!$B$7:$B$66=C34)*'แผนงาน Schedule'!$F$7:$F$66*(('แผนงาน Schedule'!$I$7:$I$66<=Dashboard!$C$7)+('แผนงาน Schedule'!$H$7:$H$66<=Dashboard!$C$7)*('แผนงาน Schedule'!$I$7:$I$66>Dashboard!$C$7)*(Dashboard!$C$7-'แผนงาน Schedule'!$H$7:$H$66+1)/('แผนงาน Schedule'!$I$7:$I$66-'แผนงาน Schedule'!$H$7:$H$66+1)))) | J34: =IF(C34="","",SUMPRODUCT(('แผนงาน Schedule'!$B$7:$B$66=C34)*'แผนงาน Schedule'!$F$7:$F$66*'แผนงาน Schedule'!$O$7:$O$66))
B35: =IF('ตั้งค่า Setup'!$C$38="","",13) | C35: =IF('ตั้งค่า Setup'!$C$38="","",'ตั้งค่า Setup'!$C$38) | D35: =IF(C35="","",SUMIF('แผนงาน Schedule'!$B$7:$B$66,C35,'แผนงาน Schedule'!$F$7:$F$66)) | E35: =IF(OR(C35="",N(D35)=0),"",I35/D35) | F35: =IF(OR(C35="",N(D35)=0),"",J35/D35) | G35: =IF(E35="","",F35-E35) | H35: =IF(OR(E35="",N(E35)=0),"",F35/E35) | I35: =IF(C35="","",SUMPRODUCT(('แผนงาน Schedule'!$B$7:$B$66=C35)*'แผนงาน Schedule'!$F$7:$F$66*(('แผนงาน Schedule'!$I$7:$I$66<=Dashboard!$C$7)+('แผนงาน Schedule'!$H$7:$H$66<=Dashboard!$C$7)*('แผนงาน Schedule'!$I$7:$I$66>Dashboard!$C$7)*(Dashboard!$C$7-'แผนงาน Schedule'!$H$7:$H$66+1)/('แผนงาน Schedule'!$I$7:$I$66-'แผนงาน Schedule'!$H$7:$H$66+1)))) | J35: =IF(C35="","",SUMPRODUCT(('แผนงาน Schedule'!$B$7:$B$66=C35)*'แผนงาน Schedule'!$F$7:$F$66*'แผนงาน Schedule'!$O$7:$O$66))
B36: =IF('ตั้งค่า Setup'!$C$39="","",14) | C36: =IF('ตั้งค่า Setup'!$C$39="","",'ตั้งค่า Setup'!$C$39) | D36: =IF(C36="","",SUMIF('แผนงาน Schedule'!$B$7:$B$66,C36,'แผนงาน Schedule'!$F$7:$F$66)) | E36: =IF(OR(C36="",N(D36)=0),"",I36/D36) | F36: =IF(OR(C36="",N(D36)=0),"",J36/D36) | G36: =IF(E36="","",F36-E36) | H36: =IF(OR(E36="",N(E36)=0),"",F36/E36) | I36: =IF(C36="","",SUMPRODUCT(('แผนงาน Schedule'!$B$7:$B$66=C36)*'แผนงาน Schedule'!$F$7:$F$66*(('แผนงาน Schedule'!$I$7:$I$66<=Dashboard!$C$7)+('แผนงาน Schedule'!$H$7:$H$66<=Dashboard!$C$7)*('แผนงาน Schedule'!$I$7:$I$66>Dashboard!$C$7)*(Dashboard!$C$7-'แผนงาน Schedule'!$H$7:$H$66+1)/('แผนงาน Schedule'!$I$7:$I$66-'แผนงาน Schedule'!$H$7:$H$66+1)))) | J36: =IF(C36="","",SUMPRODUCT(('แผนงาน Schedule'!$B$7:$B$66=C36)*'แผนงาน Schedule'!$F$7:$F$66*'แผนงาน Schedule'!$O$7:$O$66))
B37: =IF('ตั้งค่า Setup'!$C$40="","",15) | C37: =IF('ตั้งค่า Setup'!$C$40="","",'ตั้งค่า Setup'!$C$40) | D37: =IF(C37="","",SUMIF('แผนงาน Schedule'!$B$7:$B$66,C37,'แผนงาน Schedule'!$F$7:$F$66)) | E37: =IF(OR(C37="",N(D37)=0),"",I37/D37) | F37: =IF(OR(C37="",N(D37)=0),"",J37/D37) | G37: =IF(E37="","",F37-E37) | H37: =IF(OR(E37="",N(E37)=0),"",F37/E37) | I37: =IF(C37="","",SUMPRODUCT(('แผนงาน Schedule'!$B$7:$B$66=C37)*'แผนงาน Schedule'!$F$7:$F$66*(('แผนงาน Schedule'!$I$7:$I$66<=Dashboard!$C$7)+('แผนงาน Schedule'!$H$7:$H$66<=Dashboard!$C$7)*('แผนงาน Schedule'!$I$7:$I$66>Dashboard!$C$7)*(Dashboard!$C$7-'แผนงาน Schedule'!$H$7:$H$66+1)/('แผนงาน Schedule'!$I$7:$I$66-'แผนงาน Schedule'!$H$7:$H$66+1)))) | J37: =IF(C37="","",SUMPRODUCT(('แผนงาน Schedule'!$B$7:$B$66=C37)*'แผนงาน Schedule'!$F$7:$F$66*'แผนงาน Schedule'!$O$7:$O$66))
B38: =IF('ตั้งค่า Setup'!$C$41="","",16) | C38: =IF('ตั้งค่า Setup'!$C$41="","",'ตั้งค่า Setup'!$C$41) | D38: =IF(C38="","",SUMIF('แผนงาน Schedule'!$B$7:$B$66,C38,'แผนงาน Schedule'!$F$7:$F$66)) | E38: =IF(OR(C38="",N(D38)=0),"",I38/D38) | F38: =IF(OR(C38="",N(D38)=0),"",J38/D38) | G38: =IF(E38="","",F38-E38) | H38: =IF(OR(E38="",N(E38)=0),"",F38/E38) | I38: =IF(C38="","",SUMPRODUCT(('แผนงาน Schedule'!$B$7:$B$66=C38)*'แผนงาน Schedule'!$F$7:$F$66*(('แผนงาน Schedule'!$I$7:$I$66<=Dashboard!$C$7)+('แผนงาน Schedule'!$H$7:$H$66<=Dashboard!$C$7)*('แผนงาน Schedule'!$I$7:$I$66>Dashboard!$C$7)*(Dashboard!$C$7-'แผนงาน Schedule'!$H$7:$H$66+1)/('แผนงาน Schedule'!$I$7:$I$66-'แผนงาน Schedule'!$H$7:$H$66+1)))) | J38: =IF(C38="","",SUMPRODUCT(('แผนงาน Schedule'!$B$7:$B$66=C38)*'แผนงาน Schedule'!$F$7:$F$66*'แผนงาน Schedule'!$O$7:$O$66))
B39: =IF('ตั้งค่า Setup'!$C$42="","",17) | C39: =IF('ตั้งค่า Setup'!$C$42="","",'ตั้งค่า Setup'!$C$42) | D39: =IF(C39="","",SUMIF('แผนงาน Schedule'!$B$7:$B$66,C39,'แผนงาน Schedule'!$F$7:$F$66)) | E39: =IF(OR(C39="",N(D39)=0),"",I39/D39) | F39: =IF(OR(C39="",N(D39)=0),"",J39/D39) | G39: =IF(E39="","",F39-E39) | H39: =IF(OR(E39="",N(E39)=0),"",F39/E39) | I39: =IF(C39="","",SUMPRODUCT(('แผนงาน Schedule'!$B$7:$B$66=C39)*'แผนงาน Schedule'!$F$7:$F$66*(('แผนงาน Schedule'!$I$7:$I$66<=Dashboard!$C$7)+('แผนงาน Schedule'!$H$7:$H$66<=Dashboard!$C$7)*('แผนงาน Schedule'!$I$7:$I$66>Dashboard!$C$7)*(Dashboard!$C$7-'แผนงาน Schedule'!$H$7:$H$66+1)/('แผนงาน Schedule'!$I$7:$I$66-'แผนงาน Schedule'!$H$7:$H$66+1)))) | J39: =IF(C39="","",SUMPRODUCT(('แผนงาน Schedule'!$B$7:$B$66=C39)*'แผนงาน Schedule'!$F$7:$F$66*'แผนงาน Schedule'!$O$7:$O$66))
B40: =IF('ตั้งค่า Setup'!$C$43="","",18) | C40: =IF('ตั้งค่า Setup'!$C$43="","",'ตั้งค่า Setup'!$C$43) | D40: =IF(C40="","",SUMIF('แผนงาน Schedule'!$B$7:$B$66,C40,'แผนงาน Schedule'!$F$7:$F$66)) | E40: =IF(OR(C40="",N(D40)=0),"",I40/D40) | F40: =IF(OR(C40="",N(D40)=0),"",J40/D40) | G40: =IF(E40="","",F40-E40) | H40: =IF(OR(E40="",N(E40)=0),"",F40/E40) | I40: =IF(C40="","",SUMPRODUCT(('แผนงาน Schedule'!$B$7:$B$66=C40)*'แผนงาน Schedule'!$F$7:$F$66*(('แผนงาน Schedule'!$I$7:$I$66<=Dashboard!$C$7)+('แผนงาน Schedule'!$H$7:$H$66<=Dashboard!$C$7)*('แผนงาน Schedule'!$I$7:$I$66>Dashboard!$C$7)*(Dashboard!$C$7-'แผนงาน Schedule'!$H$7:$H$66+1)/('แผนงาน Schedule'!$I$7:$I$66-'แผนงาน Schedule'!$H$7:$H$66+1)))) | J40: =IF(C40="","",SUMPRODUCT(('แผนงาน Schedule'!$B$7:$B$66=C40)*'แผนงาน Schedule'!$F$7:$F$66*'แผนงาน Schedule'!$O$7:$O$66))
B41: =IF('ตั้งค่า Setup'!$C$44="","",19) | C41: =IF('ตั้งค่า Setup'!$C$44="","",'ตั้งค่า Setup'!$C$44) | D41: =IF(C41="","",SUMIF('แผนงาน Schedule'!$B$7:$B$66,C41,'แผนงาน Schedule'!$F$7:$F$66)) | E41: =IF(OR(C41="",N(D41)=0),"",I41/D41) | F41: =IF(OR(C41="",N(D41)=0),"",J41/D41) | G41: =IF(E41="","",F41-E41) | H41: =IF(OR(E41="",N(E41)=0),"",F41/E41) | I41: =IF(C41="","",SUMPRODUCT(('แผนงาน Schedule'!$B$7:$B$66=C41)*'แผนงาน Schedule'!$F$7:$F$66*(('แผนงาน Schedule'!$I$7:$I$66<=Dashboard!$C$7)+('แผนงาน Schedule'!$H$7:$H$66<=Dashboard!$C$7)*('แผนงาน Schedule'!$I$7:$I$66>Dashboard!$C$7)*(Dashboard!$C$7-'แผนงาน Schedule'!$H$7:$H$66+1)/('แผนงาน Schedule'!$I$7:$I$66-'แผนงาน Schedule'!$H$7:$H$66+1)))) | J41: =IF(C41="","",SUMPRODUCT(('แผนงาน Schedule'!$B$7:$B$66=C41)*'แผนงาน Schedule'!$F$7:$F$66*'แผนงาน Schedule'!$O$7:$O$66))
B42: =IF('ตั้งค่า Setup'!$C$45="","",20) | C42: =IF('ตั้งค่า Setup'!$C$45="","",'ตั้งค่า Setup'!$C$45) | D42: =IF(C42="","",SUMIF('แผนงาน Schedule'!$B$7:$B$66,C42,'แผนงาน Schedule'!$F$7:$F$66)) | E42: =IF(OR(C42="",N(D42)=0),"",I42/D42) | F42: =IF(OR(C42="",N(D42)=0),"",J42/D42) | G42: =IF(E42="","",F42-E42) | H42: =IF(OR(E42="",N(E42)=0),"",F42/E42) | I42: =IF(C42="","",SUMPRODUCT(('แผนงาน Schedule'!$B$7:$B$66=C42)*'แผนงาน Schedule'!$F$7:$F$66*(('แผนงาน Schedule'!$I$7:$I$66<=Dashboard!$C$7)+('แผนงาน Schedule'!$H$7:$H$66<=Dashboard!$C$7)*('แผนงาน Schedule'!$I$7:$I$66>Dashboard!$C$7)*(Dashboard!$C$7-'แผนงาน Schedule'!$H$7:$H$66+1)/('แผนงาน Schedule'!$I$7:$I$66-'แผนงาน Schedule'!$H$7:$H$66+1)))) | J42: =IF(C42="","",SUMPRODUCT(('แผนงาน Schedule'!$B$7:$B$66=C42)*'แผนงาน Schedule'!$F$7:$F$66*'แผนงาน Schedule'!$O$7:$O$66))
...

Sheet งวดงาน Installments
A1: งวดงานตามสัญญา / Contract Payment Installments
A2: กรอกตามงวดงานที่ระบุในสัญญา/TOR • ระบบแสดงสถานะ ความล่าช้า และเช็คว่าผลงานถึงเกณฑ์ของงวดแล้วหรือยัง
A3: ตัวอย่างการกรอก: 1 | งานฐานรากและโครงสร้างชั้น 1 แล้วเสร็จ | 25% | 30-Apr-26 | 3,000,000 | ส่งมอบ 28-Apr-26 | ตรวจรับ 5-May-26
A6: งวดที่ No. | B6: เนื้องานที่ต้องแล้วเสร็จในงวด Scope of Installment | C6: ผลงานสะสม ที่กำหนด (%) | D6: กำหนดแล้วเสร็จ Due Date | E6: จำนวนเงิน (บาท) Amount | F6: % ของ ค่าจ้าง | G6: วันที่ส่งมอบงาน Submitted | H6: วันที่ตรวจรับ Accepted | I6: เบิกจ่ายแล้ว (บาท) | J6: ผลงานปัจจุบัน เทียบเกณฑ์ | K6: สถานะ Status | L6: ล่าช้า (วัน) | M6: หมายเหตุ Remarks
F7: =IF(E7="","",E7/'ตั้งค่า Setup'!$C$9) | I7: =IF(OR(E7="",H7=""),"",E7) | J7: =IF(OR(B7="",C7=""),"",IF(Dashboard!$C$19>=C7,"✓ ถึงเกณฑ์แล้ว","ยังขาด "&TEXT(C7-Dashboard!$C$19,"0.00%"))) | K7: =IF(B7="","",IF(H7<>"","ตรวจรับแล้ว",IF(G7<>"","ส่งมอบแล้ว รอตรวจรับ",IF(D7="","-",IF('ตั้งค่า Setup'!$C$15>D7,"เกินกำหนด",IF(D7-'ตั้งค่า Setup'!$C$15<=14,"ใกล้ครบกำหนด (≤14 วัน)","ยังไม่ถึงกำหนด")))))) | L7: =IF(OR(B7="",D7=""),"",MAX(0,IF(G7<>"",G7,IF(H7<>"",H7,'ตั้งค่า Setup'!$C$15))-D7))
F8: =IF(E8="","",E8/'ตั้งค่า Setup'!$C$9) | I8: =IF(OR(E8="",H8=""),"",E8) | J8: =IF(OR(B8="",C8=""),"",IF(Dashboard!$C$19>=C8,"✓ ถึงเกณฑ์แล้ว","ยังขาด "&TEXT(C8-Dashboard!$C$19,"0.00%"))) | K8: =IF(B8="","",IF(H8<>"","ตรวจรับแล้ว",IF(G8<>"","ส่งมอบแล้ว รอตรวจรับ",IF(D8="","-",IF('ตั้งค่า Setup'!$C$15>D8,"เกินกำหนด",IF(D8-'ตั้งค่า Setup'!$C$15<=14,"ใกล้ครบกำหนด (≤14 วัน)","ยังไม่ถึงกำหนด")))))) | L8: =IF(OR(B8="",D8=""),"",MAX(0,IF(G8<>"",G8,IF(H8<>"",H8,'ตั้งค่า Setup'!$C$15))-D8))
F9: =IF(E9="","",E9/'ตั้งค่า Setup'!$C$9) | I9: =IF(OR(E9="",H9=""),"",E9) | J9: =IF(OR(B9="",C9=""),"",IF(Dashboard!$C$19>=C9,"✓ ถึงเกณฑ์แล้ว","ยังขาด "&TEXT(C9-Dashboard!$C$19,"0.00%"))) | K9: =IF(B9="","",IF(H9<>"","ตรวจรับแล้ว",IF(G9<>"","ส่งมอบแล้ว รอตรวจรับ",IF(D9="","-",IF('ตั้งค่า Setup'!$C$15>D9,"เกินกำหนด",IF(D9-'ตั้งค่า Setup'!$C$15<=14,"ใกล้ครบกำหนด (≤14 วัน)","ยังไม่ถึงกำหนด")))))) | L9: =IF(OR(B9="",D9=""),"",MAX(0,IF(G9<>"",G9,IF(H9<>"",H9,'ตั้งค่า Setup'!$C$15))-D9))
F10: =IF(E10="","",E10/'ตั้งค่า Setup'!$C$9) | I10: =IF(OR(E10="",H10=""),"",E10) | J10: =IF(OR(B10="",C10=""),"",IF(Dashboard!$C$19>=C10,"✓ ถึงเกณฑ์แล้ว","ยังขาด "&TEXT(C10-Dashboard!$C$19,"0.00%"))) | K10: =IF(B10="","",IF(H10<>"","ตรวจรับแล้ว",IF(G10<>"","ส่งมอบแล้ว รอตรวจรับ",IF(D10="","-",IF('ตั้งค่า Setup'!$C$15>D10,"เกินกำหนด",IF(D10-'ตั้งค่า Setup'!$C$15<=14,"ใกล้ครบกำหนด (≤14 วัน)","ยังไม่ถึงกำหนด")))))) | L10: =IF(OR(B10="",D10=""),"",MAX(0,IF(G10<>"",G10,IF(H10<>"",H10,'ตั้งค่า Setup'!$C$15))-D10))
F11: =IF(E11="","",E11/'ตั้งค่า Setup'!$C$9) | I11: =IF(OR(E11="",H11=""),"",E11) | J11: =IF(OR(B11="",C11=""),"",IF(Dashboard!$C$19>=C11,"✓ ถึงเกณฑ์แล้ว","ยังขาด "&TEXT(C11-Dashboard!$C$19,"0.00%"))) | K11: =IF(B11="","",IF(H11<>"","ตรวจรับแล้ว",IF(G11<>"","ส่งมอบแล้ว รอตรวจรับ",IF(D11="","-",IF('ตั้งค่า Setup'!$C$15>D11,"เกินกำหนด",IF(D11-'ตั้งค่า Setup'!$C$15<=14,"ใกล้ครบกำหนด (≤14 วัน)","ยังไม่ถึงกำหนด")))))) | L11: =IF(OR(B11="",D11=""),"",MAX(0,IF(G11<>"",G11,IF(H11<>"",H11,'ตั้งค่า Setup'!$C$15))-D11))
F12: =IF(E12="","",E12/'ตั้งค่า Setup'!$C$9) | I12: =IF(OR(E12="",H12=""),"",E12) | J12: =IF(OR(B12="",C12=""),"",IF(Dashboard!$C$19>=C12,"✓ ถึงเกณฑ์แล้ว","ยังขาด "&TEXT(C12-Dashboard!$C$19,"0.00%"))) | K12: =IF(B12="","",IF(H12<>"","ตรวจรับแล้ว",IF(G12<>"","ส่งมอบแล้ว รอตรวจรับ",IF(D12="","-",IF('ตั้งค่า Setup'!$C$15>D12,"เกินกำหนด",IF(D12-'ตั้งค่า Setup'!$C$15<=14,"ใกล้ครบกำหนด (≤14 วัน)","ยังไม่ถึงกำหนด")))))) | L12: =IF(OR(B12="",D12=""),"",MAX(0,IF(G12<>"",G12,IF(H12<>"",H12,'ตั้งค่า Setup'!$C$15))-D12))
F13: =IF(E13="","",E13/'ตั้งค่า Setup'!$C$9) | I13: =IF(OR(E13="",H13=""),"",E13) | J13: =IF(OR(B13="",C13=""),"",IF(Dashboard!$C$19>=C13,"✓ ถึงเกณฑ์แล้ว","ยังขาด "&TEXT(C13-Dashboard!$C$19,"0.00%"))) | K13: =IF(B13="","",IF(H13<>"","ตรวจรับแล้ว",IF(G13<>"","ส่งมอบแล้ว รอตรวจรับ",IF(D13="","-",IF('ตั้งค่า Setup'!$C$15>D13,"เกินกำหนด",IF(D13-'ตั้งค่า Setup'!$C$15<=14,"ใกล้ครบกำหนด (≤14 วัน)","ยังไม่ถึงกำหนด")))))) | L13: =IF(OR(B13="",D13=""),"",MAX(0,IF(G13<>"",G13,IF(H13<>"",H13,'ตั้งค่า Setup'!$C$15))-D13))
F14: =IF(E14="","",E14/'ตั้งค่า Setup'!$C$9) | I14: =IF(OR(E14="",H14=""),"",E14) | J14: =IF(OR(B14="",C14=""),"",IF(Dashboard!$C$19>=C14,"✓ ถึงเกณฑ์แล้ว","ยังขาด "&TEXT(C14-Dashboard!$C$19,"0.00%"))) | K14: =IF(B14="","",IF(H14<>"","ตรวจรับแล้ว",IF(G14<>"","ส่งมอบแล้ว รอตรวจรับ",IF(D14="","-",IF('ตั้งค่า Setup'!$C$15>D14,"เกินกำหนด",IF(D14-'ตั้งค่า Setup'!$C$15<=14,"ใกล้ครบกำหนด (≤14 วัน)","ยังไม่ถึงกำหนด")))))) | L14: =IF(OR(B14="",D14=""),"",MAX(0,IF(G14<>"",G14,IF(H14<>"",H14,'ตั้งค่า Setup'!$C$15))-D14))
F15: =IF(E15="","",E15/'ตั้งค่า Setup'!$C$9) | I15: =IF(OR(E15="",H15=""),"",E15) | J15: =IF(OR(B15="",C15=""),"",IF(Dashboard!$C$19>=C15,"✓ ถึงเกณฑ์แล้ว","ยังขาด "&TEXT(C15-Dashboard!$C$19,"0.00%"))) | K15: =IF(B15="","",IF(H15<>"","ตรวจรับแล้ว",IF(G15<>"","ส่งมอบแล้ว รอตรวจรับ",IF(D15="","-",IF('ตั้งค่า Setup'!$C$15>D15,"เกินกำหนด",IF(D15-'ตั้งค่า Setup'!$C$15<=14,"ใกล้ครบกำหนด (≤14 วัน)","ยังไม่ถึงกำหนด")))))) | L15: =IF(OR(B15="",D15=""),"",MAX(0,IF(G15<>"",G15,IF(H15<>"",H15,'ตั้งค่า Setup'!$C$15))-D15))
F16: =IF(E16="","",E16/'ตั้งค่า Setup'!$C$9) | I16: =IF(OR(E16="",H16=""),"",E16) | J16: =IF(OR(B16="",C16=""),"",IF(Dashboard!$C$19>=C16,"✓ ถึงเกณฑ์แล้ว","ยังขาด "&TEXT(C16-Dashboard!$C$19,"0.00%"))) | K16: =IF(B16="","",IF(H16<>"","ตรวจรับแล้ว",IF(G16<>"","ส่งมอบแล้ว รอตรวจรับ",IF(D16="","-",IF('ตั้งค่า Setup'!$C$15>D16,"เกินกำหนด",IF(D16-'ตั้งค่า Setup'!$C$15<=14,"ใกล้ครบกำหนด (≤14 วัน)","ยังไม่ถึงกำหนด")))))) | L16: =IF(OR(B16="",D16=""),"",MAX(0,IF(G16<>"",G16,IF(H16<>"",H16,'ตั้งค่า Setup'!$C$15))-D16))
F17: =IF(E17="","",E17/'ตั้งค่า Setup'!$C$9) | I17: =IF(OR(E17="",H17=""),"",E17) | J17: =IF(OR(B17="",C17=""),"",IF(Dashboard!$C$19>=C17,"✓ ถึงเกณฑ์แล้ว","ยังขาด "&TEXT(C17-Dashboard!$C$19,"0.00%"))) | K17: =IF(B17="","",IF(H17<>"","ตรวจรับแล้ว",IF(G17<>"","ส่งมอบแล้ว รอตรวจรับ",IF(D17="","-",IF('ตั้งค่า Setup'!$C$15>D17,"เกินกำหนด",IF(D17-'ตั้งค่า Setup'!$C$15<=14,"ใกล้ครบกำหนด (≤14 วัน)","ยังไม่ถึงกำหนด")))))) | L17: =IF(OR(B17="",D17=""),"",MAX(0,IF(G17<>"",G17,IF(H17<>"",H17,'ตั้งค่า Setup'!$C$15))-D17))
F18: =IF(E18="","",E18/'ตั้งค่า Setup'!$C$9) | I18: =IF(OR(E18="",H18=""),"",E18) | J18: =IF(OR(B18="",C18=""),"",IF(Dashboard!$C$19>=C18,"✓ ถึงเกณฑ์แล้ว","ยังขาด "&TEXT(C18-Dashboard!$C$19,"0.00%"))) | K18: =IF(B18="","",IF(H18<>"","ตรวจรับแล้ว",IF(G18<>"","ส่งมอบแล้ว รอตรวจรับ",IF(D18="","-",IF('ตั้งค่า Setup'!$C$15>D18,"เกินกำหนด",IF(D18-'ตั้งค่า Setup'!$C$15<=14,"ใกล้ครบกำหนด (≤14 วัน)","ยังไม่ถึงกำหนด")))))) | L18: =IF(OR(B18="",D18=""),"",MAX(0,IF(G18<>"",G18,IF(H18<>"",H18,'ตั้งค่า Setup'!$C$15))-D18))
... F26: =IF(E26="","",E26/'ตั้งค่า Setup'!$C$9) | I26: =IF(OR(E26="",H26=""),"",E26) | J26: =IF(OR(B26="",C26=""),"",IF(Dashboard!$C$19>=C26,"✓ ถึงเกณฑ์แล้ว","ยังขาด "&TEXT(C26-Dashboard!$C$19,"0.00%"))) | K26: =IF(B26="","",IF(H26<>"","ตรวจรับแล้ว",IF(G26<>"","ส่งมอบแล้ว รอตรวจรับ",IF(D26="","-",IF('ตั้งค่า Setup'!$C$15>D26,"เกินกำหนด",IF(D26-'ตั้งค่า Setup'!$C$15<=14,"ใกล้ครบกำหนด (≤14 วัน)","ยังไม่ถึงกำหนด")))))) | L26: =IF(OR(B26="",D26=""),"",MAX(0,IF(G26<>"",G26,IF(H26<>"",H26,'ตั้งค่า Setup'!$C$15))-D26))
B27: รวม / TOTAL | E27: =SUM(E7:E26) -> 0 | F27: =SUM(F7:F26) -> 0 | I27: =SUM(I7:I26) -> 0 | K27: =IF(COUNT(E7:E26)=0,"",IF(ABS(E27-'ตั้งค่า Setup'!$C$9)<1,"✓ ตรงกับมูลค่าสัญญา","⚠ ต่างจากมูลค่าสัญญา "&TEXT(E27-'ตั้งค่า Setup'!$C$9,"#,##0")))

Sheet บันทึกสัปดาห์ Weekly Log
A1: บันทึกผลการปฏิบัติงานประจำสัปดาห์ / Weekly Site Log
A2: กรอกทุกสัปดาห์ 1 แถว • ข้อมูลในแถวของสัปดาห์ที่เลือกจะไปแสดงในชีต รายงานกรรมการ Weekly อัตโนมัติ
B3: ข้อมูลสำหรับหนังสือรายงาน / Memo Details | C3: ค่า / Value | D3: หมายเหตุ
B4: ส่วนราชการ / หน่วยงาน
B5: เลขที่หนังสือ (ที่) | D5: เช่น กท 1234/2569
B6: วันที่ลงนามสัญญา | D6: ใช้ในย่อหน้าอ้างถึงสัญญา
B7: ชื่อผู้ควบคุมงาน | D7: ผู้ลงนามในรายงาน
B8: ตำแหน่งผู้ควบคุมงาน | C8: ผู้ควบคุมงาน
B9: ประธานกรรมการตรวจรับพัสดุ
B10: กรรมการตรวจรับพัสดุ คนที่ 1
B11: กรรมการตรวจรับพัสดุ คนที่ 2
B12: รายงานสัปดาห์ที่ (เลือก) | C12: =MAX(1,INT(('ตั้งค่า Setup'!$C$15-'ตั้งค่า Setup'!$C$10+1)/7)) -> 31 | D12: ค่าเริ่มต้น = สัปดาห์ล่าสุดที่ครบ 7 วันแล้ว (พิมพ์ทับได้)
B13: วันที่ออกรายงาน | C13: ='ตั้งค่า Setup'!$C$15 -> 46293 | D13: ค่าเริ่มต้น = Status Date (พิมพ์ทับได้)
A15: ตารางบันทึกรายสัปดาห์ (แถวสีส้ม = สัปดาห์ที่เลือกรายงาน) • ช่วงวันที่คำนวณจากวันเริ่มสัญญา ทุก 7 วัน
A16: สัปดาห์ ที่ | B16: จาก From | C16: ถึง To | D16: % แผน สะสม | E16: % จริง สะสม (กรอก) | F16: ผลงาน สัปดาห์นี้ | G16: ผลต่าง (จริง−แผน) | H16: คนงานเฉลี่ย (คน/วัน) | I16: เครื่องจักรหลัก Machinery | J16: วันทำงาน / หยุด-ฝนตก | K16: งานที่ดำเนินการในสัปดาห์นี้ Work Done This Week | L16: แผนงานสัปดาห์หน้า Plan Next Week | M16: วัสดุเข้าหน่วยงาน / การทดสอบ Materials & Tests | N16: ปัญหา อุปสรรค Issues | O16: ความเห็นผู้ควบคุมงาน Supervisor's Opinion
A17: =IF('ตั้งค่า Setup'!$C$10+7*0>MAX('ตั้งค่า Setup'!$C$69,'ตั้งค่า Setup'!$C$15)+7,"",1) -> 1 | B17: =IF(A17="","",'ตั้งค่า Setup'!$C$10+7*0) -> 46073 | C17: =IF(A17="","",B17+6) -> 46079 | D17: =IF(A17="","",SUMPRODUCT('แผนงาน Schedule'!$F$7:$F$66,('แผนงาน Schedule'!$I$7:$I$66<=C17)+('แผนงาน Schedule'!$H$7:$H$66<=C17)*('แผนงาน Schedule'!$I$7:$I$66>C17)*(C17-'แผนงาน Schedule'!$H$7:$H$66+1)/('แผนงาน Schedule'!$I$7:$I$66-'แผนงาน Schedule'!$H$7:$H$66+1))) -> 0.02015 | F17: =IF(E17="","",E17-0) | G17: =IF(OR(E17="",D17=""),"",E17-D17)
A18: =IF('ตั้งค่า Setup'!$C$10+7*1>MAX('ตั้งค่า Setup'!$C$69,'ตั้งค่า Setup'!$C$15)+7,"",2) -> 2 | B18: =IF(A18="","",'ตั้งค่า Setup'!$C$10+7*1) -> 46080 | C18: =IF(A18="","",B18+6) -> 46086 | D18: =IF(A18="","",SUMPRODUCT('แผนงาน Schedule'!$F$7:$F$66,('แผนงาน Schedule'!$I$7:$I$66<=C18)+('แผนงาน Schedule'!$H$7:$H$66<=C18)*('แผนงาน Schedule'!$I$7:$I$66>C18)*(C18-'แผนงาน Schedule'!$H$7:$H$66+1)/('แผนงาน Schedule'!$I$7:$I$66-'แผนงาน Schedule'!$H$7:$H$66+1))) -> 0.039514583 | F18: =IF(E18="","",E18-N(E17)) | G18: =IF(OR(E18="",D18=""),"",E18-D18)
A19: =IF('ตั้งค่า Setup'!$C$10+7*2>MAX('ตั้งค่า Setup'!$C$69,'ตั้งค่า Setup'!$C$15)+7,"",3) -> 3 | B19: =IF(A19="","",'ตั้งค่า Setup'!$C$10+7*2) -> 46087 | C19: =IF(A19="","",B19+6) -> 46093 | D19: =IF(A19="","",SUMPRODUCT('แผนงาน Schedule'!$F$7:$F$66,('แผนงาน Schedule'!$I$7:$I$66<=C19)+('แผนงาน Schedule'!$H$7:$H$66<=C19)*('แผนงาน Schedule'!$I$7:$I$66>C19)*(C19-'แผนงาน Schedule'!$H$7:$H$66+1)/('แผนงาน Schedule'!$I$7:$I$66-'แผนงาน Schedule'!$H$7:$H$66+1))) -> 0.046105691 | F19: =IF(E19="","",E19-N(E18)) | G19: =IF(OR(E19="",D19=""),"",E19-D19)
A20: =IF('ตั้งค่า Setup'!$C$10+7*3>MAX('ตั้งค่า Setup'!$C$69,'ตั้งค่า Setup'!$C$15)+7,"",4) -> 4 | B20: =IF(A20="","",'ตั้งค่า Setup'!$C$10+7*3) -> 46094 | C20: =IF(A20="","",B20+6) -> 46100 | D20: =IF(A20="","",SUMPRODUCT('แผนงาน Schedule'!$F$7:$F$66,('แผนงาน Schedule'!$I$7:$I$66<=C20)+('แผนงาน Schedule'!$H$7:$H$66<=C20)*('แผนงาน Schedule'!$I$7:$I$66>C20)*(C20-'แผนงาน Schedule'!$H$7:$H$66+1)/('แผนงาน Schedule'!$I$7:$I$66-'แผนงาน Schedule'!$H$7:$H$66+1))) -> 0.062881993 | F20: =IF(E20="","",E20-N(E19)) | G20: =IF(OR(E20="",D20=""),"",E20-D20)
A21: =IF('ตั้งค่า Setup'!$C$10+7*4>MAX('ตั้งค่า Setup'!$C$69,'ตั้งค่า Setup'!$C$15)+7,"",5) -> 5 | B21: =IF(A21="","",'ตั้งค่า Setup'!$C$10+7*4) -> 46101 | C21: =IF(A21="","",B21+6) -> 46107 | D21: =IF(A21="","",SUMPRODUCT('แผนงาน Schedule'!$F$7:$F$66,('แผนงาน Schedule'!$I$7:$I$66<=C21)+('แผนงาน Schedule'!$H$7:$H$66<=C21)*('แผนงาน Schedule'!$I$7:$I$66>C21)*(C21-'แผนงาน Schedule'!$H$7:$H$66+1)/('แผนงาน Schedule'!$I$7:$I$66-'แผนงาน Schedule'!$H$7:$H$66+1))) -> 0.083700848 | F21: =IF(E21="","",E21-N(E20)) | G21: =IF(OR(E21="",D21=""),"",E21-D21)
A22: =IF('ตั้งค่า Setup'!$C$10+7*5>MAX('ตั้งค่า Setup'!$C$69,'ตั้งค่า Setup'!$C$15)+7,"",6) -> 6 | B22: =IF(A22="","",'ตั้งค่า Setup'!$C$10+7*5) -> 46108 | C22: =IF(A22="","",B22+6) -> 46114 | D22: =IF(A22="","",SUMPRODUCT('แผนงาน Schedule'!$F$7:$F$66,('แผนงาน Schedule'!$I$7:$I$66<=C22)+('แผนงาน Schedule'!$H$7:$H$66<=C22)*('แผนงาน Schedule'!$I$7:$I$66>C22)*(C22-'แผนงาน Schedule'!$H$7:$H$66+1)/('แผนงาน Schedule'!$I$7:$I$66-'แผนงาน Schedule'!$H$7:$H$66+1))) -> 0.1045197 | F22: =IF(E22="","",E22-N(E21)) | G22: =IF(OR(E22="",D22=""),"",E22-D22)
A23: =IF('ตั้งค่า Setup'!$C$10+7*6>MAX('ตั้งค่า Setup'!$C$69,'ตั้งค่า Setup'!$C$15)+7,"",7) -> 7 | B23: =IF(A23="","",'ตั้งค่า Setup'!$C$10+7*6) -> 46115 | C23: =IF(A23="","",B23+6) -> 46121 | D23: =IF(A23="","",SUMPRODUCT('แผนงาน Schedule'!$F$7:$F$66,('แผนงาน Schedule'!$I$7:$I$66<=C23)+('แผนงาน Schedule'!$H$7:$H$66<=C23)*('แผนงาน Schedule'!$I$7:$I$66>C23)*(C23-'แผนงาน Schedule'!$H$7:$H$66+1)/('แผนงาน Schedule'!$I$7:$I$66-'แผนงาน Schedule'!$H$7:$H$66+1))) -> 0.12533856 | F23: =IF(E23="","",E23-N(E22)) | G23: =IF(OR(E23="",D23=""),"",E23-D23)
A24: =IF('ตั้งค่า Setup'!$C$10+7*7>MAX('ตั้งค่า Setup'!$C$69,'ตั้งค่า Setup'!$C$15)+7,"",8) -> 8 | B24: =IF(A24="","",'ตั้งค่า Setup'!$C$10+7*7) -> 46122 | C24: =IF(A24="","",B24+6) -> 46128 | D24: =IF(A24="","",SUMPRODUCT('แผนงาน Schedule'!$F$7:$F$66,('แผนงาน Schedule'!$I$7:$I$66<=C24)+('แผนงาน Schedule'!$H$7:$H$66<=C24)*('แผนงาน Schedule'!$I$7:$I$66>C24)*(C24-'แผนงาน Schedule'!$H$7:$H$66+1)/('แผนงาน Schedule'!$I$7:$I$66-'แผนงาน Schedule'!$H$7:$H$66+1))) -> 0.14973698 | F24: =IF(E24="","",E24-N(E23)) | G24: =IF(OR(E24="",D24=""),"",E24-D24)
A25: =IF('ตั้งค่า Setup'!$C$10+7*8>MAX('ตั้งค่า Setup'!$C$69,'ตั้งค่า Setup'!$C$15)+7,"",9) -> 9 | B25: =IF(A25="","",'ตั้งค่า Setup'!$C$10+7*8) -> 46129 | C25: =IF(A25="","",B25+6) -> 46135 | D25: =IF(A25="","",SUMPRODUCT('แผนงาน Schedule'!$F$7:$F$66,('แผนงาน Schedule'!$I$7:$I$66<=C25)+('แผนงาน Schedule'!$H$7:$H$66<=C25)*('แผนงาน Schedule'!$I$7:$I$66>C25)*(C25-'แผนงาน Schedule'!$H$7:$H$66+1)/('แผนงาน Schedule'!$I$7:$I$66-'แผนงาน Schedule'!$H$7:$H$66+1))) -> 0.18000913 | F25: =IF(E25="","",E25-N(E24)) | G25: =IF(OR(E25="",D25=""),"",E25-D25)
A26: =IF('ตั้งค่า Setup'!$C$10+7*9>MAX('ตั้งค่า Setup'!$C$69,'ตั้งค่า Setup'!$C$15)+7,"",10) -> 10 | B26: =IF(A26="","",'ตั้งค่า Setup'!$C$10+7*9) -> 46136 | C26: =IF(A26="","",B26+6) -> 46142 | D26: =IF(A26="","",SUMPRODUCT('แผนงาน Schedule'!$F$7:$F$66,('แผนงาน Schedule'!$I$7:$I$66<=C26)+('แผนงาน Schedule'!$H$7:$H$66<=C26)*('แผนงาน Schedule'!$I$7:$I$66>C26)*(C26-'แผนงาน Schedule'!$H$7:$H$66+1)/('แผนงาน Schedule'!$I$7:$I$66-'แผนงาน Schedule'!$H$7:$H$66+1))) -> 0.20820323 | F26: =IF(E26="","",E26-N(E25)) | G26: =IF(OR(E26="",D26=""),"",E26-D26)
A27: =IF('ตั้งค่า Setup'!$C$10+7*10>MAX('ตั้งค่า Setup'!$C$69,'ตั้งค่า Setup'!$C$15)+7,"",11) -> 11 | B27: =IF(A27="","",'ตั้งค่า Setup'!$C$10+7*10) -> 46143 | C27: =IF(A27="","",B27+6) -> 46149 | D27: =IF(A27="","",SUMPRODUCT('แผนงาน Schedule'!$F$7:$F$66,('แผนงาน Schedule'!$I$7:$I$66<=C27)+('แผนงาน Schedule'!$H$7:$H$66<=C27)*('แผนงาน Schedule'!$I$7:$I$66>C27)*(C27-'แผนงาน Schedule'!$H$7:$H$66+1)/('แผนงาน Schedule'!$I$7:$I$66-'แผนงาน Schedule'!$H$7:$H$66+1))) -> 0.22224839 | F27: =IF(E27="","",E27-N(E26)) | G27: =IF(OR(E27="",D27=""),"",E27-D27)
A28: =IF('ตั้งค่า Setup'!$C$10+7*11>MAX('ตั้งค่า Setup'!$C$69,'ตั้งค่า Setup'!$C$15)+7,"",12) -> 12 | B28: =IF(A28="","",'ตั้งค่า Setup'!$C$10+7*11) -> 46150 | C28: =IF(A28="","",B28+6) -> 46156 | D28: =IF(A28="","",SUMPRODUCT('แผนงาน Schedule'!$F$7:$F$66,('แผนงาน Schedule'!$I$7:$I$66<=C28)+('แผนงาน Schedule'!$H$7:$H$66<=C28)*('แผนงาน Schedule'!$I$7:$I$66>C28)*(C28-'แผนงาน Schedule'!$H$7:$H$66+1)/('แผนงาน Schedule'!$I$7:$I$66-'แผนงาน Schedule'!$H$7:$H$66+1))) -> 0.24612432 | F28: =IF(E28="","",E28-N(E27)) | G28: =IF(OR(E28="",D28=""),"",E28-D28)
A29: =IF('ตั้งค่า Setup'!$C$10+7*12>MAX('ตั้งค่า Setup'!$C$69,'ตั้งค่า Setup'!$C$15)+7,"",13) -> 13 | B29: =IF(A29="","",'ตั้งค่า Setup'!$C$10+7*12) -> 46157 | C29: =IF(A29="","",B29+6) -> 46163 | D29: =IF(A29="","",SUMPRODUCT('แผนงาน Schedule'!$F$7:$F$66,('แผนงาน Schedule'!$I$7:$I$66<=C29)+('แผนงาน Schedule'!$H$7:$H$66<=C29)*('แผนงาน Schedule'!$I$7:$I$66>C29)*(C29-'แผนงาน Schedule'!$H$7:$H$66+1)/('แผนงาน Schedule'!$I$7:$I$66-'แผนงาน Schedule'!$H$7:$H$66+1))) -> 0.26533462 | F29: =IF(E29="","",E29-N(E28)) | G29: =IF(OR(E29="",D29=""),"",E29-D29)
A30: =IF('ตั้งค่า Setup'!$C$10+7*13>MAX('ตั้งค่า Setup'!$C$69,'ตั้งค่า Setup'!$C$15)+7,"",14) -> 14 | B30: =IF(A30="","",'ตั้งค่า Setup'!$C$10+7*13) -> 46164 | C30: =IF(A30="","",B30+6) -> 46170 | D30: =IF(A30="","",SUMPRODUCT('แผนงาน Schedule'!$F$7:$F$66,('แผนงาน Schedule'!$I$7:$I$66<=C30)+('แผนงาน Schedule'!$H$7:$H$66<=C30)*('แผนงาน Schedule'!$I$7:$I$66>C30)*(C30-'แผนงาน Schedule'!$H$7:$H$66+1)/('แผนงาน Schedule'!$I$7:$I$66-'แผนงาน Schedule'!$H$7:$H$66+1))) -> 0.28253846 | F30: =IF(E30="","",E30-N(E29)) | G30: =IF(OR(E30="",D30=""),"",E30-D30)
A31: =IF('ตั้งค่า Setup'!$C$10+7*14>MAX('ตั้งค่า Setup'!$C$69,'ตั้งค่า Setup'!$C$15)+7,"",15) -> 15 | B31: =IF(A31="","",'ตั้งค่า Setup'!$C$10+7*14) -> 46171 | C31: =IF(A31="","",B31+6) -> 46177 | D31: =IF(A31="","",SUMPRODUCT('แผนงาน Schedule'!$F$7:$F$66,('แผนงาน Schedule'!$I$7:$I$66<=C31)+('แผนงาน Schedule'!$H$7:$H$66<=C31)*('แผนงาน Schedule'!$I$7:$I$66>C31)*(C31-'แผนงาน Schedule'!$H$7:$H$66+1)/('แผนงาน Schedule'!$I$7:$I$66-'แผนงาน Schedule'!$H$7:$H$66+1))) -> 0.30996631 | F31: =IF(E31="","",E31-N(E30)) | G31: =IF(OR(E31="",D31=""),"",E31-D31)
A32: =IF('ตั้งค่า Setup'!$C$10+7*15>MAX('ตั้งค่า Setup'!$C$69,'ตั้งค่า Setup'!$C$15)+7,"",16) -> 16 | B32: =IF(A32="","",'ตั้งค่า Setup'!$C$10+7*15) -> 46178 | C32: =IF(A32="","",B32+6) -> 46184 | D32: =IF(A32="","",SUMPRODUCT('แผนงาน Schedule'!$F$7:$F$66,('แผนงาน Schedule'!$I$7:$I$66<=C32)+('แผนงาน Schedule'!$H$7:$H$66<=C32)*('แผนงาน Schedule'!$I$7:$I$66>C32)*(C32-'แผนงาน Schedule'!$H$7:$H$66+1)/('แผนงาน Schedule'!$I$7:$I$66-'แผนงาน Schedule'!$H$7:$H$66+1))) -> 0.330316 | F32: =IF(E32="","",E32-N(E31)) | G32: =IF(OR(E32="",D32=""),"",E32-D32)
A33: =IF('ตั้งค่า Setup'!$C$10+7*16>MAX('ตั้งค่า Setup'!$C$69,'ตั้งค่า Setup'!$C$15)+7,"",17) -> 17 | B33: =IF(A33="","",'ตั้งค่า Setup'!$C$10+7*16) -> 46185 | C33: =IF(A33="","",B33+6) -> 46191 | D33: =IF(A33="","",SUMPRODUCT('แผนงาน Schedule'!$F$7:$F$66,('แผนงาน Schedule'!$I$7:$I$66<=C33)+('แผนงาน Schedule'!$H$7:$H$66<=C33)*('แผนงาน Schedule'!$I$7:$I$66>C33)*(C33-'แผนงาน Schedule'!$H$7:$H$66+1)/('แผนงาน Schedule'!$I$7:$I$66-'แผนงาน Schedule'!$H$7:$H$66+1))) -> 0.35623381 | F33: =IF(E33="","",E33-N(E32)) | G33: =IF(OR(E33="",D33=""),"",E33-D33)
A34: =IF('ตั้งค่า Setup'!$C$10+7*17>MAX('ตั้งค่า Setup'!$C$69,'ตั้งค่า Setup'!$C$15)+7,"",18) -> 18 | B34: =IF(A34="","",'ตั้งค่า Setup'!$C$10+7*17) -> 46192 | C34: =IF(A34="","",B34+6) -> 46198 | D34: =IF(A34="","",SUMPRODUCT('แผนงาน Schedule'!$F$7:$F$66,('แผนงาน Schedule'!$I$7:$I$66<=C34)+('แผนงาน Schedule'!$H$7:$H$66<=C34)*('แผนงาน Schedule'!$I$7:$I$66>C34)*(C34-'แผนงาน Schedule'!$H$7:$H$66+1)/('แผนงาน Schedule'!$I$7:$I$66-'แผนงาน Schedule'!$H$7:$H$66+1))) -> 0.38817097 | F34: =IF(E34="","",E34-N(E33)) | G34: =IF(OR(E34="",D34=""),"",E34-D34)
A35: =IF('ตั้งค่า Setup'!$C$10+7*18>MAX('ตั้งค่า Setup'!$C$69,'ตั้งค่า Setup'!$C$15)+7,"",19) -> 19 | B35: =IF(A35="","",'ตั้งค่า Setup'!$C$10+7*18) -> 46199 | C35: =IF(A35="","",B35+6) -> 46205 | D35: =IF(A35="","",SUMPRODUCT('แผนงาน Schedule'!$F$7:$F$66,('แผนงาน Schedule'!$I$7:$I$66<=C35)+('แผนงาน Schedule'!$H$7:$H$66<=C35)*('แผนงาน Schedule'!$I$7:$I$66>C35)*(C35-'แผนงาน Schedule'!$H$7:$H$66+1)/('แผนงาน Schedule'!$I$7:$I$66-'แผนงาน Schedule'!$H$7:$H$66+1))) -> 0.40634656 | F35: =IF(E35="","",E35-N(E34)) | G35: =IF(OR(E35="",D35=""),"",E35-D35)
A36: =IF('ตั้งค่า Setup'!$C$10+7*19>MAX('ตั้งค่า Setup'!$C$69,'ตั้งค่า Setup'!$C$15)+7,"",20) -> 20 | B36: =IF(A36="","",'ตั้งค่า Setup'!$C$10+7*19) -> 46206 | C36: =IF(A36="","",B36+6) -> 46212 | D36: =IF(A36="","",SUMPRODUCT('แผนงาน Schedule'!$F$7:$F$66,('แผนงาน Schedule'!$I$7:$I$66<=C36)+('แผนงาน Schedule'!$H$7:$H$66<=C36)*('แผนงาน Schedule'!$I$7:$I$66>C36)*(C36-'แผนงาน Schedule'!$H$7:$H$66+1)/('แผนงาน Schedule'!$I$7:$I$66-'แผนงาน Schedule'!$H$7:$H$66+1))) -> 0.43484825 | F36: =IF(E36="","",E36-N(E35)) | G36: =IF(OR(E36="",D36=""),"",E36-D36)
A37: =IF('ตั้งค่า Setup'!$C$10+7*20>MAX('ตั้งค่า Setup'!$C$69,'ตั้งค่า Setup'!$C$15)+7,"",21) -> 21 | B37: =IF(A37="","",'ตั้งค่า Setup'!$C$10+7*20) -> 46213 | C37: =IF(A37="","",B37+6) -> 46219 | D37: =IF(A37="","",SUMPRODUCT('แผนงาน Schedule'!$F$7:$F$66,('แผนงาน Schedule'!$I$7:$I$66<=C37)+('แผนงาน Schedule'!$H$7:$H$66<=C37)*('แผนงาน Schedule'!$I$7:$I$66>C37)*(C37-'แผนงาน Schedule'!$H$7:$H$66+1)/('แผนงาน Schedule'!$I$7:$I$66-'แผนงาน Schedule'!$H$7:$H$66+1))) -> 0.49079098 | F37: =IF(E37="","",E37-N(E36)) | G37: =IF(OR(E37="",D37=""),"",E37-D37)
A38: =IF('ตั้งค่า Setup'!$C$10+7*21>MAX('ตั้งค่า Setup'!$C$69,'ตั้งค่า Setup'!$C$15)+7,"",22) -> 22 | B38: =IF(A38="","",'ตั้งค่า Setup'!$C$10+7*21) -> 46220 | C38: =IF(A38="","",B38+6) -> 46226 | D38: =IF(A38="","",SUMPRODUCT('แผนงาน Schedule'!$F$7:$F$66,('แผนงาน Schedule'!$I$7:$I$66<=C38)+('แผนงาน Schedule'!$H$7:$H$66<=C38)*('แผนงาน Schedule'!$I$7:$I$66>C38)*(C38-'แผนงาน Schedule'!$H$7:$H$66+1)/('แผนงาน Schedule'!$I$7:$I$66-'แผนงาน Schedule'!$H$7:$H$66+1))) -> 0.5485179 | F38: =IF(E38="","",E38-N(E37)) | G38: =IF(OR(E38="",D38=""),"",E38-D38)
A39: =IF('ตั้งค่า Setup'!$C$10+7*22>MAX('ตั้งค่า Setup'!$C$69,'ตั้งค่า Setup'!$C$15)+7,"",23) -> 23 | B39: =IF(A39="","",'ตั้งค่า Setup'!$C$10+7*22) -> 46227 | C39: =IF(A39="","",B39+6) -> 46233 | D39: =IF(A39="","",SUMPRODUCT('แผนงาน Schedule'!$F$7:$F$66,('แผนงาน Schedule'!$I$7:$I$66<=C39)+('แผนงาน Schedule'!$H$7:$H$66<=C39)*('แผนงาน Schedule'!$I$7:$I$66>C39)*(C39-'แผนงาน Schedule'!$H$7:$H$66+1)/('แผนงาน Schedule'!$I$7:$I$66-'แผนงาน Schedule'!$H$7:$H$66+1))) -> 0.60603701 | F39: =IF(E39="","",E39-N(E38)) | G39: =IF(OR(E39="",D39=""),"",E39-D39)
A40: =IF('ตั้งค่า Setup'!$C$10+7*23>MAX('ตั้งค่า Setup'!$C$69,'ตั้งค่า Setup'!$C$15)+7,"",24) -> 24 | B40: =IF(A40="","",'ตั้งค่า Setup'!$C$10+7*23) -> 46234 | C40: =IF(A40="","",B40+6) -> 46240 | D40: =IF(A40="","",SUMPRODUCT('แผนงาน Schedule'!$F$7:$F$66,('แผนงาน Schedule'!$I$7:$I$66<=C40)+('แผนงาน Schedule'!$H$7:$H$66<=C40)*('แผนงาน Schedule'!$I$7:$I$66>C40)*(C40-'แผนงาน Schedule'!$H$7:$H$66+1)/('แผนงาน Schedule'!$I$7:$I$66-'แผนงาน Schedule'!$H$7:$H$66+1))) -> 0.64864612 | F40: =IF(E40="","",E40-N(E39)) | G40: =IF(OR(E40="",D40=""),"",E40-D40)
A41: =IF('ตั้งค่า Setup'!$C$10+7*24>MAX('ตั้งค่า Setup'!$C$69,'ตั้งค่า Setup'!$C$15)+7,"",25) -> 25 | B41: =IF(A41="","",'ตั้งค่า Setup'!$C$10+7*24) -> 46241 | C41: =IF(A41="","",B41+6) -> 46247 | D41: =IF(A41="","",SUMPRODUCT('แผนงาน Schedule'!$F$7:$F$66,('แผนงาน Schedule'!$I$7:$I$66<=C41)+('แผนงาน Schedule'!$H$7:$H$66<=C41)*('แผนงาน Schedule'!$I$7:$I$66>C41)*(C41-'แผนงาน Schedule'!$H$7:$H$66+1)/('แผนงาน Schedule'!$I$7:$I$66-'แผนงาน Schedule'!$H$7:$H$66+1))) -> 0.69125524 | F41: =IF(E41="","",E41-N(E40)) | G41: =IF(OR(E41="",D41=""),"",E41-D41)
...

Sheet รายงานกรรมการ Weekly
B1: บันทึกข้อความ
B2: ส่วนราชการ | C2: ='บันทึกสัปดาห์ Weekly Log'!C4&""
B3: ที่ | C3: ='บันทึกสัปดาห์ Weekly Log'!C5&"" | G3: วันที่ | H3: =IF(N('บันทึกสัปดาห์ Weekly Log'!$C$13)=0,"-",DAY('บันทึกสัปดาห์ Weekly Log'!$C$13)&" "&CHOOSE(MONTH('บันทึกสัปดาห์ Weekly Log'!$C$13),"มกราคม","กุมภาพันธ์","มีนาคม","เมษายน","พฤษภาคม","มิถุนายน","กรกฎาคม","สิงหาคม","กันยายน","ตุลาคม","พฤศจิกายน","ธันวาคม")&" "&(YEAR('บันทึกสัปดาห์ Weekly Log'!$C$13)+543)) -> 28 กันยายน 2569
B4: เรื่อง | C4: ="รายงานผลการปฏิบัติงานของผู้รับจ้าง ประจำสัปดาห์ที่ "&'บันทึกสัปดาห์ Weekly Log'!$C$12&" ("&IF(N(INDEX('บันทึกสัปดาห์ Weekly Log'!$B$17:$B$120,'บันทึกสัปดาห์ Weekly Log'!$C$12))=0,"-",DAY(INDEX('บันทึกสัปดาห์ Weekly Log'!$B$17:$B$120,'บันทึกสัปดาห์ Weekly Log'!$C$12))&" "&CHOOSE(MONTH(INDEX('บันทึกสัปดาห์ Weekly Log'!$B$17:$B$120,'บันทึกสัปดาห์ Weekly Log'!$C$12)),"ม.ค.","ก.พ.","มี.ค.","เม.ย.","พ.ค.","มิ.ย.","ก.ค.","ส.ค.","ก.ย.","ต.ค.","พ.ย.","ธ.ค.")&" "&RIGHT(YEAR(INDEX('บันทึกสัปดาห์ Weekly Log'!$B$17:$B$120,'บันทึกสัปดาห์ Weekly Log'!$C$12))+543,2))&" – "&IF(N(INDEX('บันทึกสัปดาห์ Weekly Log'!$C$17:$C$120,'บันทึกสัปดาห์ Weekly Log'!$C$12))=0,"-",DAY(INDEX('บันทึกสัปดาห์ Weekly Log'!$C$17:$C$120,'บันทึกสัปดาห์ Weekly Log'!$C$12))&" "&CHOOSE(MONTH(INDEX('บันทึกสัปดาห์ Weekly Log'!$C$17:$C$120,'บันทึกสัปดาห์ Weekly Log'!$C$12)),"ม.ค.","ก.พ.","มี.ค.","เม.ย.","พ.ค.","มิ.ย.","ก.ค.","ส.ค.","ก.ย.","ต.ค.","พ.ย.","ธ.ค.")&" "&RIGHT(YEAR(INDEX('บันทึกสัปดาห์ Weekly Log'!$C$17:$C$120,'บันทึกสัปดาห์ Weekly Log'!$C$12))+543,2))&")" -> รายงานผลการปฏิบัติงานของผู้รับจ้าง ประจำสัปดาห์ที่ 31 (18 ก.ย. 69 – 24 ก.ย. 69)
B5: เรียน | C5: ประธานกรรมการตรวจรับพัสดุ
B6: =" ตามที่ "&IF('ตั้งค่า Setup'!C6="","(ผู้ว่าจ้าง)",'ตั้งค่า Setup'!C6)&" ได้ทำสัญญาจ้าง "&IF('ตั้งค่า Setup'!C7="","(ผู้รับจ้าง)",'ตั้งค่า Setup'!C7)&" ดำเนินการ"&'ตั้งค่า Setup'!C4&" ตามสัญญาเลขที่ "&IF('ตั้งค่า Setup'!C8="","……",'ตั้งค่า Setup'!C8)&" ลงวันที่ "&IF(N('บันทึกสัปดาห์ Weekly Log'!$C$6)=0,"……",IF(N('บันทึกสัปดาห์ Weekly Log'!$C$6)=0,"-",DAY('บันทึกสัปดาห์ Weekly Log'!$C$6)&" "&CHOOSE(MONTH('บันทึกสัปดาห์ Weekly Log'!$C$6),"มกราคม","กุมภาพันธ์","มีนาคม","เมษายน","พฤษภาคม","มิถุนายน","กรกฎาคม","สิงหาคม","กันยายน","ตุลาคม","พฤศจิกายน","ธันวาคม")&" "&(YEAR('บันทึกสัปดาห์ Weekly Log'!$C$6)+543)))&" วงเงิน "&TEXT('ตั้งค่า Setup'!$C$9,"#,##0.00")&" บาท"&" ระยะเวลาดำเนินการ "&'ตั้งค่า Setup'!$C$11&" วัน เริ่มสัญญาวันที่ "&IF(N('ตั้งค่า Setup'!$C$10)=0,"-",DAY('ตั้งค่า Setup'!$C$10)&" "&CHOOSE(MONTH('ตั้งค่า Setup'!$C$10),"มกราคม","กุมภาพันธ์","มีนาคม","เมษายน","พฤษภาคม","มิถุนายน","กรกฎาคม","สิงหาคม","กันยายน","ตุลาคม","พฤศจิกายน","ธันวาคม")&" "&(YEAR('ตั้งค่า Setup'!$C$10)+543))&" สิ้นสุดสัญญาวันที่ "&IF(N('ตั้งค่า Setup'!$C$14)=0,"-",DAY('ตั้งค่า Setup'!$C$14)&" "&CHOOSE(MONTH('ตั้งค่า Setup'!$C$14),"มกราคม","กุมภาพันธ์","มีนาคม","เมษายน","พฤษภาคม","มิถุนายน","กรกฎาคม","สิงหาคม","กันยายน","ตุลาคม","พฤศจิกายน","ธันวาคม")&" "&(YEAR('ตั้งค่า Setup'!$C$14)+543))&IF('ตั้งค่า Setup'!$C$13>0," (รวมการขยายเวลา "&'ตั้งค่า Setup'!$C$13&" วัน)","")&" นั้น"&CHAR(10)&" ข้าพเจ้าในฐานะผู้ควบคุมงาน ขอรายงานผลการปฏิบัติงานของผู้รับจ้าง ประจำสัปดาห์ที่ "&'บันทึกสัปดาห์ Weekly Log'!$C$12&" ดังนี้" -> ตามที่ (ผู้ว่าจ้าง) ได้ทำสัญญาจ้าง (ผู้รับจ้าง) ดำเนินการโครงการก่อสร้างอาคาร (แก้ไขชื่อได้) ตามสัญญาเลขที่ …… ลงวันที่ …… วงเงิน 12,108,000.00 บาท ระยะเวลาดำเนินการ 270 วัน เริ่มสัญญาวันที่ 20 กุมภาพันธ์ 2569 สิ้นสุดสัญญาวันที่ 16 พฤศจิกายน 2569 นั้น ข้าพเจ้าในฐานะผู้ควบคุมงาน ขอรายงานผลการปฏิบัติงานของผู้รับจ้าง ประจำสัปดาห์ที่ 31 ดังนี้
B8: 1. ความก้าวหน้าของงาน ณ สิ้นสัปดาห์
B9: ผลงานตามแผนสะสม | D9: =INDEX('บันทึกสัปดาห์ Weekly Log'!$D$17:$D$120,'บันทึกสัปดาห์ Weekly Log'!$C$12) -> 0.84962
B10: ผลงานจริงสะสม | D10: =IF(INDEX('บันทึกสัปดาห์ Weekly Log'!$E$17:$E$120,'บันทึกสัปดาห์ Weekly Log'!$C$12)="","ยังไม่กรอก",INDEX('บันทึกสัปดาห์ Weekly Log'!$E$17:$E$120,'บันทึกสัปดาห์ Weekly Log'!$C$12)) -> ยังไม่กรอก
B11: ผลงานเร็ว (+) / ช้า (−) กว่าแผน | D11: =IF(INDEX('บันทึกสัปดาห์ Weekly Log'!$E$17:$E$120,'บันทึกสัปดาห์ Weekly Log'!$C$12)="","-",INDEX('บันทึกสัปดาห์ Weekly Log'!$E$17:$E$120,'บันทึกสัปดาห์ Weekly Log'!$C$12)-INDEX('บันทึกสัปดาห์ Weekly Log'!$D$17:$D$120,'บันทึกสัปดาห์ Weekly Log'!$C$12)) -> -
B12: คิดเป็นจำนวนวัน | D12: =IF(INDEX('บันทึกสัปดาห์ Weekly Log'!$E$17:$E$120,'บันทึกสัปดาห์ Weekly Log'!$C$12)="","-",ROUND((INDEX('บันทึกสัปดาห์ Weekly Log'!$E$17:$E$120,'บันทึกสัปดาห์ Weekly Log'!$C$12)-INDEX('บันทึกสัปดาห์ Weekly Log'!$D$17:$D$120,'บันทึกสัปดาห์ Weekly Log'!$C$12))*'ตั้งค่า Setup'!$C$11,0)) -> -
B13: ผลงานที่ทำได้ในสัปดาห์นี้ | D13: =IF(INDEX('บันทึกสัปดาห์ Weekly Log'!$E$17:$E$120,'บันทึกสัปดาห์ Weekly Log'!$C$12)="","-",INDEX('บันทึกสัปดาห์ Weekly Log'!$F$17:$F$120,'บันทึกสัปดาห์ Weekly Log'!$C$12)) -> -
B14: ผลงานสัปดาห์ที่แล้ว | D14: =IF('บันทึกสัปดาห์ Weekly Log'!$C$12<=1,"-",IF(INDEX('บันทึกสัปดาห์ Weekly Log'!$F$17:$F$120,'บันทึกสัปดาห์ Weekly Log'!$C$12-1)="","-",INDEX('บันทึกสัปดาห์ Weekly Log'!$F$17:$F$120,'บันทึกสัปดาห์ Weekly Log'!$C$12-1))) -> -
B15: ระยะเวลาดำเนินการแล้ว | D15: =(INDEX('บันทึกสัปดาห์ Weekly Log'!$C$17:$C$120,'บันทึกสัปดาห์ Weekly Log'!$C$12)-'ตั้งค่า Setup'!$C$10+1)&" วัน ("&TEXT((INDEX('บันทึกสัปดาห์ Weekly Log'!$C$17:$C$120,'บันทึกสัปดาห์ Weekly Log'!$C$12)-'ตั้งค่า Setup'!$C$10+1)/('ตั้งค่า Setup'!$C$14-'ตั้งค่า Setup'!$C$10+1),"0.0%")&")" -> 217 วัน (80.4%)
B16: ระยะเวลาคงเหลือตามสัญญา | D16: =IF('ตั้งค่า Setup'!$C$14-INDEX('บันทึกสัปดาห์ Weekly Log'!$C$17:$C$120,'บันทึกสัปดาห์ Weekly Log'!$C$12)>=0,('ตั้งค่า Setup'!$C$14-INDEX('บันทึกสัปดาห์ Weekly Log'!$C$17:$C$120,'บันทึกสัปดาห์ Weekly Log'!$C$12))&" วัน","เลยกำหนด "&(INDEX('บันทึกสัปดาห์ Weekly Log'!$C$17:$C$120,'บันทึกสัปดาห์ Weekly Log'!$C$12)-'ตั้งค่า Setup'!$C$14)&" วัน") -> 53 วัน
