Workbook

Sheet คู่มือ Guide
B1: คู่มือการใช้งาน / User Guide — Project Control v3 (Multi Work-Package)
B3: 1. ภาพรวมไฟล์ / Workbook Overview
B4: ไฟล์นี้ออกแบบสำหรับโครงการที่มีงานหลายส่วน (เช่น อาคาร รั้ว รางระบายน้ำ ถนน-ลาน ถมดิน โรงจอดรถ) ซึ่งหลายส่วนก่อสร้างพร้อมกันได้ ใช้ WBS 3 ระดับในแผนงานชีตเดียว ทำให้ S-Curve, EVM, ค่าปรับ และรายงานคำนวณจากฐานเดียวกันทั้งสัญญา และยังดูผลแยกรายงานส่วนได้
B5: ⚠ ข้อมูลทั้งหมดในไฟล์นี้เป็นข้อมูลตัวอย่าง (EXAMPLE) เพื่อสาธิตการทำงาน – ดูวิธีล้างข้อมูลในหัวข้อ 4
B6: ชีต / Sheet | C6: ใช้ทำอะไร / Purpose | D6: ต้องกรอกอะไร / What to fill
B7: ตั้งค่า Setup | C7: ข้อมูลสัญญา วันที่ตรวจวัด อัตราค่าปรับ รายชื่องานส่วน (ระดับ 1) และหมวดงาน (ระดับ 2) | D7: ช่องสีเหลืองทั้งหมด (ครั้งแรก) + Status Date ทุกงวด
B8: Dashboard | C8: ตัวชี้วัดรวมทั้งโครงการ: เวลา ต้นทุน ขยายเวลา-ค่าปรับ พร้อมกราฟ S-Curve, EVM และกราฟแท่งรายงานส่วน | D8: ไม่ต้องกรอก
B9: สรุปงานส่วน Summary | C9: สรุปผลแยกรายงานส่วนและรายหมวดงาน พร้อม Gantt ระดับงานส่วน แสดงงานที่ทำขนานกัน | D9: ไม่ต้องกรอก
B10: รายงาน Report | C10: รายงานประจำงวด A4 พร้อมพิมพ์ มีหัวข้อความก้าวหน้ารายงานส่วน | D10: หัวข้อ 6 ปัญหาและแนวทางแก้ไข
B11: แผนงาน Schedule | C11: รายการงานทั้งหมด (สูงสุด 150 รายการ) แบบ WBS 3 ระดับ พร้อม Baseline / Revised / Actual และ Gantt | D11: ครั้งแรก: งานส่วน หมวด รายการ BOQ/น้ำหนัก วันแผน • ทุกงวด: วันจริง % จริง
B12: S-Curve | C12: ตารางรายงวดสำหรับ S-Curve และ EVM รวมทั้งโครงการ | D12: ทุกงวด: Actual % สะสม, AC ในงวด, เบิกจ่ายในงวด
B13: ขยายเวลา EOT | C13: ทะเบียนเหตุการณ์ล่าช้าและการขอขยายเวลา | D13: เมื่อมีเหตุการณ์ / ยื่นหนังสือ / ได้ผลพิจารณา
B15: 2. โครงสร้างงาน 3 ระดับ / 3-Level WBS
B16: ระดับ / Level | C16: ความหมาย / Meaning | D16: ตัวอย่าง / Example
B17: ระดับ 1 งานส่วน / Work Package | C17: แบ่งตามสิ่งก่อสร้างหรือพื้นที่ – ใช้ดูว่าแต่ละส่วนคืบหน้าเท่าไร | D17: อาคาร / รั้ว / รางระบายน้ำ / ถนน-ลาน / ถมดิน / โรงจอดรถ
B18: ระดับ 2 หมวดงาน / Discipline | C18: แบ่งตามประเภทงานหรือทีมช่าง – ใช้ดูภาระงานของแต่ละทีม | D18: งานดิน / โครงสร้าง / สถาปัตย์ / ระบบ
B19: ระดับ 3 รายการงาน / Work Item | C19: งานย่อยที่วัดผลได้จริงหน้างาน | D19: งานเสาเข็มอาคาร / งานฐานรากรั้ว
B20: รหัส WBS | C20: สร้างอัตโนมัติ: งานส่วน.หมวดงาน.ลำดับ | D20: 2.3.01 = อาคาร • งานโครงสร้าง • รายการที่ 1
B22: 3. งานที่ก่อสร้างพร้อมกัน / Parallel Work
B23: • แต่ละรายการงานมีวันเริ่ม-เสร็จของตัวเอง ใส่วันที่ซ้อนทับกันได้ตามจริง เช่น งานรางระบายน้ำ (ส.ค.–ต.ค.) ทำพร้อมงานเสาเข็มอาคาร (ก.ย.–ต.ค.) และงานฐานรากรั้ว (ก.ย.–ต.ค.)
B24: • ระบบรวมผลตามน้ำหนักงาน (มูลค่า) โดยอัตโนมัติ – งานส่วนที่มีมูลค่ามากมีผลต่อ % รวมมากกว่า
B25: • Gantt ในชีต สรุปงานส่วน แสดงช่วงเวลาของทุกงานส่วนในหน้าเดียว เห็นทันทีว่าช่วงไหนมีกี่ส่วนทำขนานกัน (ใช้วางแผนกำลังคน/เครื่องจักร)
B26: • ถ้างานหนึ่งต้องรออีกงานหนึ่งเสร็จ (เช่น ถนนต้องรอรางระบายน้ำ) ให้ตั้งวันเริ่มของงานถัดไปหลังวันเสร็จของงานก่อนหน้าเอง – ไฟล์นี้ไม่ผูกความสัมพันธ์อัตโนมัติ
B27: • ในชีตแผนงาน ใช้ปุ่มกรอง (▼) ที่หัวคอลัมน์ งานส่วน เพื่อดูหรือกรอกข้อมูลทีละงานส่วนได้
B29: 4. ตั้งค่าโครงการใหม่ / New Project Setup
B30: 1) ชีต ตั้งค่า Setup: กรอกข้อมูลสัญญา • แก้รายชื่องานส่วน (สูงสุด 10) และหมวดงาน (สูงสุด 10)
B31: 2) ชีต แผนงาน Schedule: ลบข้อมูลตัวอย่างในช่องสีเหลืองทั้งหมด แล้วกรอกรายการงาน เลือกงานส่วนและหมวดจาก Drop-down
B32: 3) น้ำหนักงาน: แนะนำให้กรอก 'มูลค่า BOQ' ทุกรายการ ระบบคำนวณน้ำหนักจากสัดส่วนมูลค่าให้ (หรือกรอก 'น้ำหนักกำหนดเอง' แทน) • รวมต้องได้ 100%
B33: 4) ชีต S-Curve: ลบค่าตัวอย่างในคอลัมน์ Actual, AC และเบิกจ่าย • ชีต ขยายเวลา EOT: ลบรายการตัวอย่าง
B35: 5. อัปเดตทุกงวด / Periodic Update
... B42: 6. วิธีวัด % ความคืบหน้าของรายการงาน / Measuring % Complete
B43: ตามปริมาณงาน | C43: งานที่นับ/วัดได้: ปริมาณที่ทำแล้ว ÷ ปริมาณทั้งหมด | D43: ตอกเสาเข็ม 45 จาก 60 ต้น = 75%
B44: แบ่งขั้นตอน | C44: งานหลายขั้นตอน: กำหนดน้ำหนักแต่ละขั้น | D44: ตั้งแบบ 20% ผูกเหล็ก 30% เทคอนกรีต 40% บ่ม 10%
B45: 0 / 50 / 100 | C45: งานสั้นหรือวัดยาก | D45: ยังไม่เริ่ม 0% • กำลังทำ 50% • เสร็จ 100%
B46: ห้ามใช้ | C46: เวลาที่ผ่านไป หรือเงินที่จ่ายไป เป็นเกณฑ์วัด % | D46: จะซ่อนความล่าช้าที่แท้จริง
B48: 7. สัญลักษณ์สี / Color Legend
B49: ช่องพื้นเหลือง ตัวน้ำเงิน | C49: ช่องให้กรอก
B50: ช่องพื้นขาว | C50: สูตร – ล็อกไว้ (ปลดล็อก: Review → Unprotect Sheet ไม่มีรหัสผ่าน)
B51: Gantt ฟ้า / ส้ม / เขียว | C51: ช่วงแผนเดิม / ช่วงทำงานจริงนอกแผน / จริงตรงกับแผน
B52: หัว Gantt สีแดง | C52: งวดที่มีวันตรวจวัด
...

Sheet ตั้งค่า Setup
B1: ตั้งค่าโครงการ / Project Setup
B2: กรอกเฉพาะช่องสีเหลือง • ข้อมูลในไฟล์นี้เป็นข้อมูลตัวอย่าง (EXAMPLE) – แทนที่ด้วยข้อมูลโครงการจริง
B3: รายการ / Item | C3: ค่า / Value | D3: หมายเหตุ / Note
B4: ชื่อโครงการ (ไทย) / Project name (TH) | C4: โครงการตัวอย่าง: ก่อสร้างอาคารพร้อมงานภายนอก | D4: ข้อมูลตัวอย่าง
B5: ชื่อโครงการ (อังกฤษ) / Project name (EN) | C5: Example: Building & External Works
B6: ผู้ว่าจ้าง / Employer
B7: ผู้รับจ้าง / Contractor
B8: เลขที่สัญญา / Contract No.
B9: มูลค่าสัญญา / Contract Value = BAC (บาท) | C9: 24200000 | D9: ตัวอย่าง = ผลรวม BOQ ในชีตแผนงาน
B10: วันเริ่มสัญญา / Commencement Date | C10: 46174
B11: ระยะเวลาสัญญา / Contract Duration (วัน/days) | C11: 300
B12: วันสิ้นสุดตามสัญญาเดิม / Original Completion | C12: =C10+C11-1 -> 46473 | D12: นับวันเริ่มเป็นวันที่ 1 (พิมพ์ทับได้ถ้าสัญญาระบุต่างไป)
B13: ขยายเวลาที่อนุมัติแล้ว / Approved EOT (วัน) | C13: =SUM('ขยายเวลา EOT'!$J$8:$J$57) -> 8 | D13: ดึงจากชีต ขยายเวลา EOT อัตโนมัติ
B14: วันสิ้นสุดหลังขยายเวลา / Revised Completion | C14: =C12+C13 -> 46481
B15: วันที่ตรวจวัดผลงาน / Status Date | C15: 46293 | D15: เปลี่ยนทุกครั้งที่อัปเดตรายงาน
B16: รอบตัดงวด S-Curve / Reporting Period | C16: ทุก 10 วัน / 10-day | D16: ทุก 10 วัน / รายสัปดาห์ / รายเดือน
B17: อัตราค่าปรับต่อวัน / LD Rate (% of contract per day) | C17: 0.001 | D17: ค่าตัวอย่าง – ใส่ตามสัญญาจริง
B18: ค่าปรับขั้นต่ำต่อวัน / Minimum LD per day (บาท) | C18: 100 | D18: ตามสัญญา (ถ้าไม่มีใส่ 0)
B19: เกณฑ์เตือนค่าปรับสะสม / LD Warning Threshold | C19: 0.1 | D19: หลายสัญญาให้สิทธิ์บอกเลิกเมื่อค่าปรับเกิน 10%
B20: ช่วงแผนงานล่วงหน้า / Look-ahead (วัน/days) | C20: 30 | D20: ใช้ในรายงานประจำงวด
B21: รายงานงวดที่ / Report No. | C21: 1
B22: ผู้จัดทำรายงาน / Prepared by
B24: งานส่วน (WBS ระดับ 1) / Work Packages | C24: ชื่อ / Name | D24: หมายเหตุ
B25: เลขลำดับ = หลักแรกของรหัส WBS • ใช้แบ่งตามสิ่งก่อสร้าง เช่น อาคาร รั้ว ถนน
B26: งานส่วนที่ 1 | C26: งานถมดินและปรับพื้นที่ / Earth Filling & Site Prep
B27: งานส่วนที่ 2 | C27: งานก่อสร้างอาคาร / Building
B28: งานส่วนที่ 3 | C28: งานรางระบายน้ำ / Drainage
B29: งานส่วนที่ 4 | C29: งานถนนและลาน / Roads & Hardscape
B30: งานส่วนที่ 5 | C30: งานรั้ว / Fence
B31: งานส่วนที่ 6 | C31: งานโรงจอดรถ / Carport
B32: งานส่วนที่ 7
B33: งานส่วนที่ 8
B34: งานส่วนที่ 9
B35: งานส่วนที่ 10
B36: งานส่วนที่ 11
B37: งานส่วนที่ 12
B38: งานส่วนที่ 13
B39: งานส่วนที่ 14
B40: งานส่วนที่ 15
B41: งานส่วนที่ 16
...

Sheet Dashboard
B1: แดชบอร์ดควบคุมโครงการ / Project Control Dashboard
B2: คำนวณอัตโนมัติทั้งหมด • All values are calculated
B3: ข้อมูลอ้างอิง / Reference | C3: ค่า / Value | D3: ความหมาย / Meaning
B4: โครงการ / Project | C4: ='ตั้งค่า Setup'!C4 -> โครงการตัวอย่าง: ก่อสร้างอาคารพร้อมงานภายนอก
B5: วันที่ตรวจวัด / Status Date | C5: ='ตั้งค่า Setup'!$C$15 -> 46293
B6: แหล่งข้อมูลผลงานจริง / Actual Data Source | C6: =IF(COUNT('แผนงาน Schedule'!$P$7:$P$156)>0,"ชีตแผนงาน (รายรายการ)","ชีต S-Curve (ค่าสะสมล่าสุด)") -> ชีตแผนงาน (รายรายการ) | D6: ถ้ากรอก % จริงรายรายการ จะใช้ข้อมูลรายรายการก่อน
B7: ข้อมูลจริง ณ วันที่ / Data Date | C7: =IF(COUNT('แผนงาน Schedule'!$P$7:$P$156)>0,'ตั้งค่า Setup'!$C$15,IFERROR(INDEX('S-Curve'!$C$7:$C$86,MATCH(9.99E+307,'S-Curve'!$F$7:$F$86)),'ตั้งค่า Setup'!$C$15)) -> 46293 | D7: ถ้าไม่ตรงวันที่ตรวจวัด (สีแดง) = ยังไม่อัปเดตผลงานจริงล่าสุด
B8: ด้านเวลา / SCHEDULE PERFORMANCE | C8: ค่า / Value | D8: ความหมาย / Meaning
B9: วันเริ่มสัญญา / Commencement | C9: ='ตั้งค่า Setup'!$C$10 -> 46174
B10: วันสิ้นสุดสัญญาเดิม / Original Completion | C10: ='ตั้งค่า Setup'!C12 -> 46473
B11: ขยายเวลาที่อนุมัติ / Approved EOT (วัน) | C11: ='ตั้งค่า Setup'!C13 -> 8 | D11: จากทะเบียนขยายเวลา
B12: วันสิ้นสุดหลังขยายเวลา / Revised Completion | C12: ='ตั้งค่า Setup'!$C$14 -> 46481
B13: วันที่ดำเนินการแล้ว / Days Elapsed | C13: ='ตั้งค่า Setup'!$C$15-'ตั้งค่า Setup'!$C$10+1 -> 120 | D13: ณ วันที่ตรวจวัด นับวันเริ่มเป็นวันที่ 1
B14: % เวลาที่ใช้ไป / Time Elapsed | C14: =IFERROR(C13/(C12-C9+1),0) -> 0.38961039 | D14: เทียบกับระยะเวลารวมหลังขยายเวลา
B15: วันคงเหลือ / Days Remaining | C15: =C12-C5 -> 188 | D15: ติดลบ = เลยกำหนดสัญญาแล้ว
B16: % แผนเดิม / Baseline Planned % | C16: =SUMPRODUCT('แผนงาน Schedule'!$G$7:$G$156,('แผนงาน Schedule'!$J$7:$J$156<=C7)+('แผนงาน Schedule'!$I$7:$I$156<=C7)*('แผนงาน Schedule'!$J$7:$J$156>C7)*(C7-'แผนงาน Schedule'!$I$7:$I$156+1)/('แผนงาน Schedule'!$J$7:$J$156-'แผนงาน Schedule'!$I$7:$I$156+1)) -> 0.25365051 | D16: ผลงานที่ควรทำได้ตามแผนสัญญา ณ Data Date
B17: % แผนเร่งรัด / Revised Planned % | C17: =IF(C63,SUMPRODUCT('แผนงาน Schedule'!$G$7:$G$156,('แผนงาน Schedule'!$AB$7:$AB$156<=C7)+('แผนงาน Schedule'!$AA$7:$AA$156<=C7)*('แผนงาน Schedule'!$AB$7:$AB$156>C7)*(C7-'แผนงาน Schedule'!$AA$7:$AA$156+1)/('แผนงาน Schedule'!$AB$7:$AB$156-'แผนงาน Schedule'!$AA$7:$AA$156+1)),C16) -> 0.25365051 | D17: ถ้ายังไม่มีแผนเร่งรัด จะเท่ากับแผนเดิม
B18: ผลต่างเทียบแผนเร่งรัด / Variance vs Revised | C18: =C19-C17 -> -0.065840597 | D18: ใช้ติดตามว่าเดินตามแผนเร่งรัดได้หรือไม่
B19: % ผลงานจริง / Actual % | C19: =IF(COUNT('แผนงาน Schedule'!$P$7:$P$156)>0,'แผนงาน Schedule'!$P$157,IFERROR(INDEX('S-Curve'!$F$7:$F$86,MATCH(9.99E+307,'S-Curve'!$F$7:$F$86)),0)) -> 0.18780992
B20: ผลต่าง / Variance (Actual − Baseline) | C20: =C19-C16 -> -0.065840597 | D20: ติดลบ = ช้ากว่าแผน
B21: ผลต่างคิดเป็นวัน / Variance in Days | C21: =C20*C69 -> -19.752179 | D21: ผลต่าง % × ระยะเวลาสัญญา (วิธีรายงานแบบไทย)
B22: SPI (ดัชนีเวลา) | C22: =IFERROR(C37/C36,0) -> 0.7404279 | D22: EV ÷ PV • ≥1 ตามแผน / 0.9–1 เฝ้าระวัง / <0.9 ล่าช้ามาก
B23: Earned Schedule – ES (วัน) | C23: =C68 -> 101.623 | D23: งานที่ทำได้จริง เท่ากับแผนของวันที่เท่าใด (นับจากวันเริ่ม)
B24: Actual Time – AT (วัน) | C24: =C7-C9+1 -> 120 | D24: เวลาที่ใช้จริงถึง Data Date
B25: SV(t) – ช้ากว่าแผนจริง (วัน) | C25: =C23-C24 -> -18.376996 | D25: ติดลบ = ช้ากว่าแผนกี่วัน
B26: SPI(t) (ดัชนีเวลาเชิงวัน) | C26: =IFERROR(C23/C24,0) -> 0.84685837 | D26: ES ÷ AT
B27: คาดการณ์วันแล้วเสร็จ / Forecast Completion | C27: =IF(C19>=1,C7,IF(COUNT('แผนงาน Schedule'!$P$7:$P$156)>0,MAX('แผนงาน Schedule'!$W$7:$W$156),IFERROR(C9+ROUND(C69/C26,0)-1,"-"))) -> 46473 | D27: มี % รายรายการ = วันเสร็จคาดการณ์ช้าสุด • ไม่มี = ระยะเวลา ÷ SPI(t)
B28: คาดว่าล่าช้ากว่าสัญญา / Forecast Delay (วัน) | C28: =IFERROR(MAX(0,C27-C12),"-") -> 0 | D28: เทียบกับวันสิ้นสุดหลังขยายเวลา
B29: อัตราผลงานจริงเฉลี่ย / Actual Rate (%/วัน) | C29: =IFERROR(C19/C24,0) -> 0.0015650826
B30: อัตราที่ต้องทำ / Required Rate (%/วัน) | C30: =IF(C19>=1,0,IF(C12-C7>0,(1-C19)/(C12-C7),"เลยกำหนดแล้ว")) -> 0.00432016 | D30: เพื่อให้เสร็จทันวันสิ้นสุดหลังขยายเวลา
B31: ต้องเร่งงาน / Acceleration Needed (เท่า) | C31: =IFERROR(C30/C29,"-") -> 2.7603399 | D31: เท่าของอัตราผลงานปัจจุบัน
B32: สถานะโครงการ / Overall Status | C32: =IF(C19>=1,"แล้วเสร็จ / Completed",IF(C22>=1,"ตามแผน / On Track",IF(C22>=0.9,"เฝ้าระวัง / At Risk","ล่าช้ามาก / Critical Delay"))) -> ล่าช้ามาก / Critical Delay
B33: จำนวนรายการที่ล่าช้า / Items Behind | C33: =COUNTIF('แผนงาน Schedule'!$Y$7:$Y$156,"*ล่าช้า*")+COUNTIF('แผนงาน Schedule'!$Y$7:$Y$156,"*เกินกำหนด*") -> 5 | D33: ดูรายงานส่วนในชีต สรุปงานส่วน
B34: ด้านต้นทุน / COST PERFORMANCE (EVM) | C34: ค่า / Value | D34: ความหมาย / Meaning
B35: BAC – งบประมาณรวม / Budget at Completion | C35: ='ตั้งค่า Setup'!$C$9 -> 24200000 | D35: มูลค่าสัญญา
B36: PV – มูลค่างานตามแผน / Planned Value | C36: =C16*C35 -> 6138342.4
B37: EV – มูลค่างานที่ทำได้จริง / Earned Value | C37: =C19*C35 -> 4545000
B38: AC – ต้นทุนจริงสะสม / Actual Cost | C38: =SUMIFS('S-Curve'!$K$7:$K$86,'S-Curve'!$C$7:$C$86,"<="&C7) -> 4634800 | D38: กรอกในชีต S-Curve • ถ้าเป็น 0 จะไม่คำนวณ CPI
B39: SV – ผลต่างด้านเวลา (บาท) | C39: =C37-C36 -> -1593342.4 | D39: EV − PV
B40: CV – ผลต่างด้านต้นทุน | C40: =IF(C38>0,C37-C38,"-") -> -89800 | D40: EV − AC • ติดลบ = ใช้เงินเกิน
...

Sheet สรุปงานส่วน Summary
A1: สรุปผลรายงานส่วนและหมวดงาน / Summary by Work Package & Discipline
A2: แสดงความคืบหน้าของแต่ละงานส่วนที่ดำเนินการขนานกัน • Gantt ด้านขวา: ฟ้า=ช่วงแผน ส้ม=ช่วงทำงานจริง เขียว=จริงตรงกับแผน
A3: ข้อมูลจริง ณ วันที่ / Data Date: | D3: =Dashboard!C7 -> 46293
A5: ความก้าวหน้ารายงานส่วน / PROGRESS BY WORK PACKAGE (WBS ระดับ 1) | U5: =INDEX('S-Curve'!$B$7:$B$86,1) -> 46174 | V5: =INDEX('S-Curve'!$B$7:$B$86,2) -> 46184 | W5: =INDEX('S-Curve'!$B$7:$B$86,3) -> 46194 | X5: =INDEX('S-Curve'!$B$7:$B$86,4) -> 46204 | Y5: =INDEX('S-Curve'!$B$7:$B$86,5) -> 46214 | Z5: =INDEX('S-Curve'!$B$7:$B$86,6) -> 46224 | AA5: =INDEX('S-Curve'!$B$7:$B$86,7) -> 46235 | AB5: =INDEX('S-Curve'!$B$7:$B$86,8) -> 46245 | AC5: =INDEX('S-Curve'!$B$7:$B$86,9) -> 46255 | AD5: =INDEX('S-Curve'!$B$7:$B$86,10) -> 46266 | AE5: =INDEX('S-Curve'!$B$7:$B$86,11) -> 46276 | AF5: =INDEX('S-Curve'!$B$7:$B$86,12) -> 46286 | AG5: =INDEX('S-Curve'!$B$7:$B$86,13) -> 46296 | AH5: =INDEX('S-Curve'!$B$7:$B$86,14) -> 46306 | AI5: =INDEX('S-Curve'!$B$7:$B$86,15) -> 46316 | AJ5: =INDEX('S-Curve'!$B$7:$B$86,16) -> 46327 | AK5: =INDEX('S-Curve'!$B$7:$B$86,17) -> 46337 | AL5: =INDEX('S-Curve'!$B$7:$B$86,18) -> 46347 | AM5: =INDEX('S-Curve'!$B$7:$B$86,19) -> 46357 | AN5: =INDEX('S-Curve'!$B$7:$B$86,20) -> 46367 | AO5: =INDEX('S-Curve'!$B$7:$B$86,21) -> 46377 | AP5: =INDEX('S-Curve'!$B$7:$B$86,22) -> 46388 | AQ5: =INDEX('S-Curve'!$B$7:$B$86,23) -> 46398 | AR5: =INDEX('S-Curve'!$B$7:$B$86,24) -> 46408 | AS5: =INDEX('S-Curve'!$B$7:$B$86,25) -> 46419 | AT5: =INDEX('S-Curve'!$B$7:$B$86,26) -> 46429 | AU5: =INDEX('S-Curve'!$B$7:$B$86,27) -> 46439 | AV5: =INDEX('S-Curve'!$B$7:$B$86,28) -> 46447 | AW5: =INDEX('S-Curve'!$B$7:$B$86,29) -> 46457 | AX5: =INDEX('S-Curve'!$B$7:$B$86,30) -> 46467 | AY5: =INDEX('S-Curve'!$B$7:$B$86,31) -> 46478 | AZ5: =INDEX('S-Curve'!$B$7:$B$86,32) | BA5: =INDEX('S-Curve'!$B$7:$B$86,33) | BB5: =INDEX('S-Curve'!$B$7:$B$86,34) | BC5: =INDEX('S-Curve'!$B$7:$B$86,35) | BD5: =INDEX('S-Curve'!$B$7:$B$86,36) | BE5: =INDEX('S-Curve'!$B$7:$B$86,37) | BF5: =INDEX('S-Curve'!$B$7:$B$86,38) | BG5: =INDEX('S-Curve'!$B$7:$B$86,39) | BH5: =INDEX('S-Curve'!$B$7:$B$86,40) | BI5: =INDEX('S-Curve'!$B$7:$B$86,41) | BJ5: =INDEX('S-Curve'!$B$7:$B$86,42) | BK5: =INDEX('S-Curve'!$B$7:$B$86,43) | BL5: =INDEX('S-Curve'!$B$7:$B$86,44) | BM5: =INDEX('S-Curve'!$B$7:$B$86,45) | BN5: =INDEX('S-Curve'!$B$7:$B$86,46) | BO5: =INDEX('S-Curve'!$B$7:$B$86,47) | BP5: =INDEX('S-Curve'!$B$7:$B$86,48) | BQ5: =INDEX('S-Curve'!$B$7:$B$86,49) | BR5: =INDEX('S-Curve'!$B$7:$B$86,50) | BS5: =INDEX('S-Curve'!$B$7:$B$86,51) | BT5: =INDEX('S-Curve'!$B$7:$B$86,52) | BU5: =INDEX('S-Curve'!$B$7:$B$86,53) | BV5: =INDEX('S-Curve'!$B$7:$B$86,54) | BW5: =INDEX('S-Curve'!$B$7:$B$86,55) | BX5: =INDEX('S-Curve'!$B$7:$B$86,56) | BY5: =INDEX('S-Curve'!$B$7:$B$86,57) | BZ5: =INDEX('S-Curve'!$B$7:$B$86,58) | CA5: =INDEX('S-Curve'!$B$7:$B$86,59) | CB5: =INDEX('S-Curve'!$B$7:$B$86,60) | CC5: =INDEX('S-Curve'!$B$7:$B$86,61) | CD5: =INDEX('S-Curve'!$B$7:$B$86,62) | CE5: =INDEX('S-Curve'!$B$7:$B$86,63) | CF5: =INDEX('S-Curve'!$B$7:$B$86,64) | CG5: =INDEX('S-Curve'!$B$7:$B$86,65) | CH5: =INDEX('S-Curve'!$B$7:$B$86,66) | CI5: =INDEX('S-Curve'!$B$7:$B$86,67) | CJ5: =INDEX('S-Curve'!$B$7:$B$86,68) | CK5: =INDEX('S-Curve'!$B$7:$B$86,69) | CL5: =INDEX('S-Curve'!$B$7:$B$86,70) | CM5: =INDEX('S-Curve'!$B$7:$B$86,71) | CN5: =INDEX('S-Curve'!$B$7:$B$86,72) | CO5: =INDEX('S-Curve'!$B$7:$B$86,73) | CP5: =INDEX('S-Curve'!$B$7:$B$86,74) | CQ5: =INDEX('S-Curve'!$B$7:$B$86,75) | CR5: =INDEX('S-Curve'!$B$7:$B$86,76) | CS5: =INDEX('S-Curve'!$B$7:$B$86,77) | CT5: =INDEX('S-Curve'!$B$7:$B$86,78) | CU5: =INDEX('S-Curve'!$B$7:$B$86,79) | CV5: =INDEX('S-Curve'!$B$7:$B$86,80)
A6: No. | B6: งานส่วน / Work Package | C6: จำนวน รายการ | D6: มูลค่า Budget (฿) | E6: น้ำหนัก Weight | F6: เริ่มแผน BL Start | G6: เสร็จแผน BL Finish | H6: เริ่มจริง Actual Start | I6: % แผน Planned | J6: % จริง Actual | K6: ผลต่าง Variance | L6: SPI | M6: คาดว่าเสร็จ Forecast | N6: ล่าช้า (วัน) Delay | O6: รายการ ล่าช้า | P6: สถานะ Status | Q6: ผลงานแผน (% โครงการ) | R6: ผลงานจริง (% โครงการ) | S6: aEnd | U6: =INDEX('S-Curve'!$C$7:$C$86,1) -> 46183 | V6: =INDEX('S-Curve'!$C$7:$C$86,2) -> 46193 | W6: =INDEX('S-Curve'!$C$7:$C$86,3) -> 46203 | X6: =INDEX('S-Curve'!$C$7:$C$86,4) -> 46213 | Y6: =INDEX('S-Curve'!$C$7:$C$86,5) -> 46223 | Z6: =INDEX('S-Curve'!$C$7:$C$86,6) -> 46234 | AA6: =INDEX('S-Curve'!$C$7:$C$86,7) -> 46244 | AB6: =INDEX('S-Curve'!$C$7:$C$86,8) -> 46254 | AC6: =INDEX('S-Curve'!$C$7:$C$86,9) -> 46265 | AD6: =INDEX('S-Curve'!$C$7:$C$86,10) -> 46275 | AE6: =INDEX('S-Curve'!$C$7:$C$86,11) -> 46285 | AF6: =INDEX('S-Curve'!$C$7:$C$86,12) -> 46295 | AG6: =INDEX('S-Curve'!$C$7:$C$86,13) -> 46305 | AH6: =INDEX('S-Curve'!$C$7:$C$86,14) -> 46315 | AI6: =INDEX('S-Curve'!$C$7:$C$86,15) -> 46326 | AJ6: =INDEX('S-Curve'!$C$7:$C$86,16) -> 46336 | AK6: =INDEX('S-Curve'!$C$7:$C$86,17) -> 46346 | AL6: =INDEX('S-Curve'!$C$7:$C$86,18) -> 46356 | AM6: =INDEX('S-Curve'!$C$7:$C$86,19) -> 46366 | AN6: =INDEX('S-Curve'!$C$7:$C$86,20) -> 46376 | AO6: =INDEX('S-Curve'!$C$7:$C$86,21) -> 46387 | AP6: =INDEX('S-Curve'!$C$7:$C$86,22) -> 46397 | AQ6: =INDEX('S-Curve'!$C$7:$C$86,23) -> 46407 | AR6: =INDEX('S-Curve'!$C$7:$C$86,24) -> 46418 | AS6: =INDEX('S-Curve'!$C$7:$C$86,25) -> 46428 | AT6: =INDEX('S-Curve'!$C$7:$C$86,26) -> 46438 | AU6: =INDEX('S-Curve'!$C$7:$C$86,27) -> 46446 | AV6: =INDEX('S-Curve'!$C$7:$C$86,28) -> 46456 | AW6: =INDEX('S-Curve'!$C$7:$C$86,29) -> 46466 | AX6: =INDEX('S-Curve'!$C$7:$C$86,30) -> 46477 | AY6: =INDEX('S-Curve'!$C$7:$C$86,31) -> 46487 | AZ6: =INDEX('S-Curve'!$C$7:$C$86,32) | BA6: =INDEX('S-Curve'!$C$7:$C$86,33) | BB6: =INDEX('S-Curve'!$C$7:$C$86,34) | BC6: =INDEX('S-Curve'!$C$7:$C$86,35) | BD6: =INDEX('S-Curve'!$C$7:$C$86,36) | BE6: =INDEX('S-Curve'!$C$7:$C$86,37) | BF6: =INDEX('S-Curve'!$C$7:$C$86,38) | BG6: =INDEX('S-Curve'!$C$7:$C$86,39) | BH6: =INDEX('S-Curve'!$C$7:$C$86,40) | BI6: =INDEX('S-Curve'!$C$7:$C$86,41) | BJ6: =INDEX('S-Curve'!$C$7:$C$86,42) | BK6: =INDEX('S-Curve'!$C$7:$C$86,43) | BL6: =INDEX('S-Curve'!$C$7:$C$86,44) | BM6: =INDEX('S-Curve'!$C$7:$C$86,45) | BN6: =INDEX('S-Curve'!$C$7:$C$86,46) | BO6: =INDEX('S-Curve'!$C$7:$C$86,47) | BP6: =INDEX('S-Curve'!$C$7:$C$86,48) | BQ6: =INDEX('S-Curve'!$C$7:$C$86,49) | BR6: =INDEX('S-Curve'!$C$7:$C$86,50) | BS6: =INDEX('S-Curve'!$C$7:$C$86,51) | BT6: =INDEX('S-Curve'!$C$7:$C$86,52) | BU6: =INDEX('S-Curve'!$C$7:$C$86,53) | BV6: =INDEX('S-Curve'!$C$7:$C$86,54) | BW6: =INDEX('S-Curve'!$C$7:$C$86,55) | BX6: =INDEX('S-Curve'!$C$7:$C$86,56) | BY6: =INDEX('S-Curve'!$C$7:$C$86,57) | BZ6: =INDEX('S-Curve'!$C$7:$C$86,58) | CA6: =INDEX('S-Curve'!$C$7:$C$86,59) | CB6: =INDEX('S-Curve'!$C$7:$C$86,60) | CC6: =INDEX('S-Curve'!$C$7:$C$86,61) | CD6: =INDEX('S-Curve'!$C$7:$C$86,62) | CE6: =INDEX('S-Curve'!$C$7:$C$86,63) | CF6: =INDEX('S-Curve'!$C$7:$C$86,64) | CG6: =INDEX('S-Curve'!$C$7:$C$86,65) | CH6: =INDEX('S-Curve'!$C$7:$C$86,66) | CI6: =INDEX('S-Curve'!$C$7:$C$86,67) | CJ6: =INDEX('S-Curve'!$C$7:$C$86,68) | CK6: =INDEX('S-Curve'!$C$7:$C$86,69) | CL6: =INDEX('S-Curve'!$C$7:$C$86,70) | CM6: =INDEX('S-Curve'!$C$7:$C$86,71) | CN6: =INDEX('S-Curve'!$C$7:$C$86,72) | CO6: =INDEX('S-Curve'!$C$7:$C$86,73) | CP6: =INDEX('S-Curve'!$C$7:$C$86,74) | CQ6: =INDEX('S-Curve'!$C$7:$C$86,75) | CR6: =INDEX('S-Curve'!$C$7:$C$86,76) | CS6: =INDEX('S-Curve'!$C$7:$C$86,77) | CT6: =INDEX('S-Curve'!$C$7:$C$86,78) | CU6: =INDEX('S-Curve'!$C$7:$C$86,79) | CV6: =INDEX('S-Curve'!$C$7:$C$86,80)
A7: =IF(B7="","",1) -> 1 | B7: =IF('ตั้งค่า Setup'!$C$26="","",'ตั้งค่า Setup'!$C$26) -> งานถมดินและปรับพื้นที่ / Earth Filling & Site Prep | C7: =IF(B7="","",COUNTIFS('แผนงาน Schedule'!$B$7:$B$156,B7,'แผนงาน Schedule'!$D$7:$D$156,"<>")) -> 3 | D7: =IF(B7="","",SUMIF('แผนงาน Schedule'!$B$7:$B$156,B7,'แผนงาน Schedule'!$H$7:$H$156)) -> 3050000 | E7: =IF(B7="","",SUMIF('แผนงาน Schedule'!$B$7:$B$156,B7,'แผนงาน Schedule'!$G$7:$G$156)) -> 0.12603306 | F7: =IF(OR(B7="",N(C7)=0),"",_xlfn.MINIFS('แผนงาน Schedule'!$I$7:$I$156,'แผนงาน Schedule'!$B$7:$B$156,B7)) -> 46174 | G7: =IF(OR(B7="",N(C7)=0),"",_xlfn.MAXIFS('แผนงาน Schedule'!$J$7:$J$156,'แผนงาน Schedule'!$B$7:$B$156,B7)) -> 46265 | H7: =IF(OR(B7="",COUNTIFS('แผนงาน Schedule'!$B$7:$B$156,B7,'แผนงาน Schedule'!$N$7:$N$156,"<>")=0),"",_xlfn.MINIFS('แผนงาน Schedule'!$N$7:$N$156,'แผนงาน Schedule'!$B$7:$B$156,B7)) -> 46176 | I7: =IF(OR(B7="",N(E7)=0),"",SUMPRODUCT(('แผนงาน Schedule'!$B$7:$B$156=B7)*'แผนงาน Schedule'!$G$7:$G$156*(('แผนงาน Schedule'!$J$7:$J$156<=Dashboard!$C$7)+('แผนงาน Schedule'!$I$7:$I$156<=Dashboard!$C$7)*('แผนงาน Schedule'!$J$7:$J$156>Dashboard!$C$7)*(Dashboard!$C$7-'แผนงาน Schedule'!$I$7:$I$156+1)/('แผนงาน Schedule'!$J$7:$J$156-'แผนงาน Schedule'!$I$7:$I$156+1)))/E7) -> 1 | J7: =IF(OR(B7="",N(E7)=0),"",SUMPRODUCT(('แผนงาน Schedule'!$B$7:$B$156=B7)*'แผนงาน Schedule'!$G$7:$G$156*'แผนงาน Schedule'!$P$7:$P$156)/E7) -> 0.98032787 | K7: =IF(I7="","",J7-I7) -> -0.019672131 | L7: =IF(OR(I7="",N(I7)=0),"",J7/I7) -> 0.98032787 | M7: =IF(OR(B7="",N(C7)=0),"",_xlfn.MAXIFS('แผนงาน Schedule'!$W$7:$W$156,'แผนงาน Schedule'!$B$7:$B$156,B7)) -> 46301 | N7: =IF(OR(M7="",G7=""),"",M7-G7) -> 36 | O7: =IF(B7="","",COUNTIFS('แผนงาน Schedule'!$B$7:$B$156,B7,'แผนงาน Schedule'!$Y$7:$Y$156,"*ล่าช้า*")+COUNTIFS('แผนงาน Schedule'!$B$7:$B$156,B7,'แผนงาน Schedule'!$Y$7:$Y$156,"*เกินกำหนด*")) -> 1 | P7: =IF(OR(B7="",N(C7)=0),"",IF(N(J7)>=1,"แล้วเสร็จ / Completed",IF(AND(N(I7)=0,N(J7)=0),"ยังไม่เริ่ม / Not Started",IF(N(J7)>=N(I7),"ตามแผน / On Track",IF(N(J7)/I7>=0.9,"เฝ้าระวัง / At Risk","ล่าช้า / Behind"))))) -> เฝ้าระวัง / At Risk | Q7: =IF(B7="","",N(I7)*N(E7)) -> 0.12603306 | R7: =IF(B7="","",N(J7)*N(E7)) -> 0.12355372 | S7: =IF(H7="","",IF(COUNTIFS('แผนงาน Schedule'!$B$7:$B$156,B7,'แผนงาน Schedule'!$D$7:$D$156,"<>",'แผนงาน Schedule'!$O$7:$O$156,"")=0,_xlfn.MAXIFS('แผนงาน Schedule'!$O$7:$O$156,'แผนงาน Schedule'!$B$7:$B$156,B7),'ตั้งค่า Setup'!$C$15)) -> 46293
A8: =IF(B8="","",2) -> 2 | B8: =IF('ตั้งค่า Setup'!$C$27="","",'ตั้งค่า Setup'!$C$27) -> งานก่อสร้างอาคาร / Building | C8: =IF(B8="","",COUNTIFS('แผนงาน Schedule'!$B$7:$B$156,B8,'แผนงาน Schedule'!$D$7:$D$156,"<>")) -> 8 | D8: =IF(B8="","",SUMIF('แผนงาน Schedule'!$B$7:$B$156,B8,'แผนงาน Schedule'!$H$7:$H$156)) -> 13200000 | E8: =IF(B8="","",SUMIF('แผนงาน Schedule'!$B$7:$B$156,B8,'แผนงาน Schedule'!$G$7:$G$156)) -> 0.54545455 | F8: =IF(OR(B8="",N(C8)=0),"",_xlfn.MINIFS('แผนงาน Schedule'!$I$7:$I$156,'แผนงาน Schedule'!$B$7:$B$156,B8)) -> 46266 | G8: =IF(OR(B8="",N(C8)=0),"",_xlfn.MAXIFS('แผนงาน Schedule'!$J$7:$J$156,'แผนงาน Schedule'!$B$7:$B$156,B8)) -> 46473 | H8: =IF(OR(B8="",COUNTIFS('แผนงาน Schedule'!$B$7:$B$156,B8,'แผนงาน Schedule'!$N$7:$N$156,"<>")=0),"",_xlfn.MINIFS('แผนงาน Schedule'!$N$7:$N$156,'แผนงาน Schedule'!$B$7:$B$156,B8)) -> 46273 | I8: =IF(OR(B8="",N(E8)=0),"",SUMPRODUCT(('แผนงาน Schedule'!$B$7:$B$156=B8)*'แผนงาน Schedule'!$G$7:$G$156*(('แผนงาน Schedule'!$J$7:$J$156<=Dashboard!$C$7)+('แผนงาน Schedule'!$I$7:$I$156<=Dashboard!$C$7)*('แผนงาน Schedule'!$J$7:$J$156>Dashboard!$C$7)*(Dashboard!$C$7-'แผนงาน Schedule'!$I$7:$I$156+1)/('แผนงาน Schedule'!$J$7:$J$156-'แผนงาน Schedule'!$I$7:$I$156+1)))/E8) -> 0.084848485 | J8: =IF(OR(B8="",N(E8)=0),"",SUMPRODUCT(('แผนงาน Schedule'!$B$7:$B$156=B8)*'แผนงาน Schedule'!$G$7:$G$156*'แผนงาน Schedule'!$P$7:$P$156)/E8) -> 0.047727273 | K8: =IF(I8="","",J8-I8) -> -0.037121212 | L8: =IF(OR(I8="",N(I8)=0),"",J8/I8) -> 0.5625 | M8: =IF(OR(B8="",N(C8)=0),"",_xlfn.MAXIFS('แผนงาน Schedule'!$W$7:$W$156,'แผนงาน Schedule'!$B$7:$B$156,B8)) -> 46473 | N8: =IF(OR(M8="",G8=""),"",M8-G8) -> 0 | O8: =IF(B8="","",COUNTIFS('แผนงาน Schedule'!$B$7:$B$156,B8,'แผนงาน Schedule'!$Y$7:$Y$156,"*ล่าช้า*")+COUNTIFS('แผนงาน Schedule'!$B$7:$B$156,B8,'แผนงาน Schedule'!$Y$7:$Y$156,"*เกินกำหนด*")) -> 1 | P8: =IF(OR(B8="",N(C8)=0),"",IF(N(J8)>=1,"แล้วเสร็จ / Completed",IF(AND(N(I8)=0,N(J8)=0),"ยังไม่เริ่ม / Not Started",IF(N(J8)>=N(I8),"ตามแผน / On Track",IF(N(J8)/I8>=0.9,"เฝ้าระวัง / At Risk","ล่าช้า / Behind"))))) -> ล่าช้า / Behind | Q8: =IF(B8="","",N(I8)*N(E8)) -> 0.046280992 | R8: =IF(B8="","",N(J8)*N(E8)) -> 0.026033058 | S8: =IF(H8="","",IF(COUNTIFS('แผนงาน Schedule'!$B$7:$B$156,B8,'แผนงาน Schedule'!$D$7:$D$156,"<>",'แผนงาน Schedule'!$O$7:$O$156,"")=0,_xlfn.MAXIFS('แผนงาน Schedule'!$O$7:$O$156,'แผนงาน Schedule'!$B$7:$B$156,B8),'ตั้งค่า Setup'!$C$15)) -> 46293
A9: =IF(B9="","",3) -> 3 | B9: =IF('ตั้งค่า Setup'!$C$28="","",'ตั้งค่า Setup'!$C$28) -> งานรางระบายน้ำ / Drainage | C9: =IF(B9="","",COUNTIFS('แผนงาน Schedule'!$B$7:$B$156,B9,'แผนงาน Schedule'!$D$7:$D$156,"<>")) -> 2 | D9: =IF(B9="","",SUMIF('แผนงาน Schedule'!$B$7:$B$156,B9,'แผนงาน Schedule'!$H$7:$H$156)) -> 1900000 | E9: =IF(B9="","",SUMIF('แผนงาน Schedule'!$B$7:$B$156,B9,'แผนงาน Schedule'!$G$7:$G$156)) -> 0.078512397 | F9: =IF(OR(B9="",N(C9)=0),"",_xlfn.MINIFS('แผนงาน Schedule'!$I$7:$I$156,'แผนงาน Schedule'!$B$7:$B$156,B9)) -> 46235 | G9: =IF(OR(B9="",N(C9)=0),"",_xlfn.MAXIFS('แผนงาน Schedule'!$J$7:$J$156,'แผนงาน Schedule'!$B$7:$B$156,B9)) -> 46326 | H9: =IF(OR(B9="",COUNTIFS('แผนงาน Schedule'!$B$7:$B$156,B9,'แผนงาน Schedule'!$N$7:$N$156,"<>")=0),"",_xlfn.MINIFS('แผนงาน Schedule'!$N$7:$N$156,'แผนงาน Schedule'!$B$7:$B$156,B9)) -> 46244 | I9: =IF(OR(B9="",N(E9)=0),"",SUMPRODUCT(('แผนงาน Schedule'!$B$7:$B$156=B9)*'แผนงาน Schedule'!$G$7:$G$156*(('แผนงาน Schedule'!$J$7:$J$156<=Dashboard!$C$7)+('แผนงาน Schedule'!$I$7:$I$156<=Dashboard!$C$7)*('แผนงาน Schedule'!$J$7:$J$156>Dashboard!$C$7)*(Dashboard!$C$7-'แผนงาน Schedule'!$I$7:$I$156+1)/('แผนงาน Schedule'!$J$7:$J$156-'แผนงาน Schedule'!$I$7:$I$156+1)))/E9) -> 0.80672994 | J9: =IF(OR(B9="",N(E9)=0),"",SUMPRODUCT(('แผนงาน Schedule'!$B$7:$B$156=B9)*'แผนงาน Schedule'!$G$7:$G$156*'แผนงาน Schedule'!$P$7:$P$156)/E9) -> 0.37631579 | K9: =IF(I9="","",J9-I9) -> -0.43041415 | L9: =IF(OR(I9="",N(I9)=0),"",J9/I9) -> 0.46647059 | M9: =IF(OR(B9="",N(C9)=0),"",_xlfn.MAXIFS('แผนงาน Schedule'!$W$7:$W$156,'แผนงาน Schedule'!$B$7:$B$156,B9)) -> 46353 | N9: =IF(OR(M9="",G9=""),"",M9-G9) -> 27 | O9: =IF(B9="","",COUNTIFS('แผนงาน Schedule'!$B$7:$B$156,B9,'แผนงาน Schedule'!$Y$7:$Y$156,"*ล่าช้า*")+COUNTIFS('แผนงาน Schedule'!$B$7:$B$156,B9,'แผนงาน Schedule'!$Y$7:$Y$156,"*เกินกำหนด*")) -> 2 | P9: =IF(OR(B9="",N(C9)=0),"",IF(N(J9)>=1,"แล้วเสร็จ / Completed",IF(AND(N(I9)=0,N(J9)=0),"ยังไม่เริ่ม / Not Started",IF(N(J9)>=N(I9),"ตามแผน / On Track",IF(N(J9)/I9>=0.9,"เฝ้าระวัง / At Risk","ล่าช้า / Behind"))))) -> ล่าช้า / Behind | Q9: =IF(B9="","",N(I9)*N(E9)) -> 0.063338301 | R9: =IF(B9="","",N(J9)*N(E9)) -> 0.029545455 | S9: =IF(H9="","",IF(COUNTIFS('แผนงาน Schedule'!$B$7:$B$156,B9,'แผนงาน Schedule'!$D$7:$D$156,"<>",'แผนงาน Schedule'!$O$7:$O$156,"")=0,_xlfn.MAXIFS('แผนงาน Schedule'!$O$7:$O$156,'แผนงาน Schedule'!$B$7:$B$156,B9),'ตั้งค่า Setup'!$C$15)) -> 46293
A10: =IF(B10="","",4) -> 4 | B10: =IF('ตั้งค่า Setup'!$C$29="","",'ตั้งค่า Setup'!$C$29) -> งานถนนและลาน / Roads & Hardscape | C10: =IF(B10="","",COUNTIFS('แผนงาน Schedule'!$B$7:$B$156,B10,'แผนงาน Schedule'!$D$7:$D$156,"<>")) -> 3 | D10: =IF(B10="","",SUMIF('แผนงาน Schedule'!$B$7:$B$156,B10,'แผนงาน Schedule'!$H$7:$H$156)) -> 3250000 | E10: =IF(B10="","",SUMIF('แผนงาน Schedule'!$B$7:$B$156,B10,'แผนงาน Schedule'!$G$7:$G$156)) -> 0.13429752 | F10: =IF(OR(B10="",N(C10)=0),"",_xlfn.MINIFS('แผนงาน Schedule'!$I$7:$I$156,'แผนงาน Schedule'!$B$7:$B$156,B10)) -> 46296 | G10: =IF(OR(B10="",N(C10)=0),"",_xlfn.MAXIFS('แผนงาน Schedule'!$J$7:$J$156,'แผนงาน Schedule'!$B$7:$B$156,B10)) -> 46418 | H10: =IF(OR(B10="",COUNTIFS('แผนงาน Schedule'!$B$7:$B$156,B10,'แผนงาน Schedule'!$N$7:$N$156,"<>")=0),"",_xlfn.MINIFS('แผนงาน Schedule'!$N$7:$N$156,'แผนงาน Schedule'!$B$7:$B$156,B10)) | I10: =IF(OR(B10="",N(E10)=0),"",SUMPRODUCT(('แผนงาน Schedule'!$B$7:$B$156=B10)*'แผนงาน Schedule'!$G$7:$G$156*(('แผนงาน Schedule'!$J$7:$J$156<=Dashboard!$C$7)+('แผนงาน Schedule'!$I$7:$I$156<=Dashboard!$C$7)*('แผนงาน Schedule'!$J$7:$J$156>Dashboard!$C$7)*(Dashboard!$C$7-'แผนงาน Schedule'!$I$7:$I$156+1)/('แผนงาน Schedule'!$J$7:$J$156-'แผนงาน Schedule'!$I$7:$I$156+1)))/E10) -> 0 | J10: =IF(OR(B10="",N(E10)=0),"",SUMPRODUCT(('แผนงาน Schedule'!$B$7:$B$156=B10)*'แผนงาน Schedule'!$G$7:$G$156*'แผนงาน Schedule'!$P$7:$P$156)/E10) -> 0 | K10: =IF(I10="","",J10-I10) -> 0 | L10: =IF(OR(I10="",N(I10)=0),"",J10/I10) | M10: =IF(OR(B10="",N(C10)=0),"",_xlfn.MAXIFS('แผนงาน Schedule'!$W$7:$W$156,'แผนงาน Schedule'!$B$7:$B$156,B10)) -> 46418 | N10: =IF(OR(M10="",G10=""),"",M10-G10) -> 0 | O10: =IF(B10="","",COUNTIFS('แผนงาน Schedule'!$B$7:$B$156,B10,'แผนงาน Schedule'!$Y$7:$Y$156,"*ล่าช้า*")+COUNTIFS('แผนงาน Schedule'!$B$7:$B$156,B10,'แผนงาน Schedule'!$Y$7:$Y$156,"*เกินกำหนด*")) -> 0 | P10: =IF(OR(B10="",N(C10)=0),"",IF(N(J10)>=1,"แล้วเสร็จ / Completed",IF(AND(N(I10)=0,N(J10)=0),"ยังไม่เริ่ม / Not Started",IF(N(J10)>=N(I10),"ตามแผน / On Track",IF(N(J10)/I10>=0.9,"เฝ้าระวัง / At Risk","ล่าช้า / Behind"))))) -> ยังไม่เริ่ม / Not Started | Q10: =IF(B10="","",N(I10)*N(E10)) -> 0 | R10: =IF(B10="","",N(J10)*N(E10)) -> 0 | S10: =IF(H10="","",IF(COUNTIFS('แผนงาน Schedule'!$B$7:$B$156,B10,'แผนงาน Schedule'!$D$7:$D$156,"<>",'แผนงาน Schedule'!$O$7:$O$156,"")=0,_xlfn.MAXIFS('แผนงาน Schedule'!$O$7:$O$156,'แผนงาน Schedule'!$B$7:$B$156,B10),'ตั้งค่า Setup'!$C$15))
A11: =IF(B11="","",5) -> 5 | B11: =IF('ตั้งค่า Setup'!$C$30="","",'ตั้งค่า Setup'!$C$30) -> งานรั้ว / Fence | C11: =IF(B11="","",COUNTIFS('แผนงาน Schedule'!$B$7:$B$156,B11,'แผนงาน Schedule'!$D$7:$D$156,"<>")) -> 2 | D11: =IF(B11="","",SUMIF('แผนงาน Schedule'!$B$7:$B$156,B11,'แผนงาน Schedule'!$H$7:$H$156)) -> 1600000 | E11: =IF(B11="","",SUMIF('แผนงาน Schedule'!$B$7:$B$156,B11,'แผนงาน Schedule'!$G$7:$G$156)) -> 0.066115702 | F11: =IF(OR(B11="",N(C11)=0),"",_xlfn.MINIFS('แผนงาน Schedule'!$I$7:$I$156,'แผนงาน Schedule'!$B$7:$B$156,B11)) -> 46266 | G11: =IF(OR(B11="",N(C11)=0),"",_xlfn.MAXIFS('แผนงาน Schedule'!$J$7:$J$156,'แผนงาน Schedule'!$B$7:$B$156,B11)) -> 46371 | H11: =IF(OR(B11="",COUNTIFS('แผนงาน Schedule'!$B$7:$B$156,B11,'แผนงาน Schedule'!$N$7:$N$156,"<>")=0),"",_xlfn.MINIFS('แผนงาน Schedule'!$N$7:$N$156,'แผนงาน Schedule'!$B$7:$B$156,B11)) -> 46277 | I11: =IF(OR(B11="",N(E11)=0),"",SUMPRODUCT(('แผนงาน Schedule'!$B$7:$B$156=B11)*'แผนงาน Schedule'!$G$7:$G$156*(('แผนงาน Schedule'!$J$7:$J$156<=Dashboard!$C$7)+('แผนงาน Schedule'!$I$7:$I$156<=Dashboard!$C$7)*('แผนงาน Schedule'!$J$7:$J$156>Dashboard!$C$7)*(Dashboard!$C$7-'แผนงาน Schedule'!$I$7:$I$156+1)/('แผนงาน Schedule'!$J$7:$J$156-'แผนงาน Schedule'!$I$7:$I$156+1)))/E11) -> 0.27222222 | J11: =IF(OR(B11="",N(E11)=0),"",SUMPRODUCT(('แผนงาน Schedule'!$B$7:$B$156=B11)*'แผนงาน Schedule'!$G$7:$G$156*'แผนงาน Schedule'!$P$7:$P$156)/E11) -> 0.13125 | K11: =IF(I11="","",J11-I11) -> -0.14097222 | L11: =IF(OR(I11="",N(I11)=0),"",J11/I11) -> 0.48214286 | M11: =IF(OR(B11="",N(C11)=0),"",_xlfn.MAXIFS('แผนงาน Schedule'!$W$7:$W$156,'แผนงาน Schedule'!$B$7:$B$156,B11)) -> 46371 | N11: =IF(OR(M11="",G11=""),"",M11-G11) -> 0 | O11: =IF(B11="","",COUNTIFS('แผนงาน Schedule'!$B$7:$B$156,B11,'แผนงาน Schedule'!$Y$7:$Y$156,"*ล่าช้า*")+COUNTIFS('แผนงาน Schedule'!$B$7:$B$156,B11,'แผนงาน Schedule'!$Y$7:$Y$156,"*เกินกำหนด*")) -> 1 | P11: =IF(OR(B11="",N(C11)=0),"",IF(N(J11)>=1,"แล้วเสร็จ / Completed",IF(AND(N(I11)=0,N(J11)=0),"ยังไม่เริ่ม / Not Started",IF(N(J11)>=N(I11),"ตามแผน / On Track",IF(N(J11)/I11>=0.9,"เฝ้าระวัง / At Risk","ล่าช้า / Behind"))))) -> ล่าช้า / Behind | Q11: =IF(B11="","",N(I11)*N(E11)) -> 0.017998163 | R11: =IF(B11="","",N(J11)*N(E11)) -> 0.008677686 | S11: =IF(H11="","",IF(COUNTIFS('แผนงาน Schedule'!$B$7:$B$156,B11,'แผนงาน Schedule'!$D$7:$D$156,"<>",'แผนงาน Schedule'!$O$7:$O$156,"")=0,_xlfn.MAXIFS('แผนงาน Schedule'!$O$7:$O$156,'แผนงาน Schedule'!$B$7:$B$156,B11),'ตั้งค่า Setup'!$C$15)) -> 46293
A12: =IF(B12="","",6) -> 6 | B12: =IF('ตั้งค่า Setup'!$C$31="","",'ตั้งค่า Setup'!$C$31) -> งานโรงจอดรถ / Carport | C12: =IF(B12="","",COUNTIFS('แผนงาน Schedule'!$B$7:$B$156,B12,'แผนงาน Schedule'!$D$7:$D$156,"<>")) -> 3 | D12: =IF(B12="","",SUMIF('แผนงาน Schedule'!$B$7:$B$156,B12,'แผนงาน Schedule'!$H$7:$H$156)) -> 1200000 | E12: =IF(B12="","",SUMIF('แผนงาน Schedule'!$B$7:$B$156,B12,'แผนงาน Schedule'!$G$7:$G$156)) -> 0.049586777 | F12: =IF(OR(B12="",N(C12)=0),"",_xlfn.MINIFS('แผนงาน Schedule'!$I$7:$I$156,'แผนงาน Schedule'!$B$7:$B$156,B12)) -> 46357 | G12: =IF(OR(B12="",N(C12)=0),"",_xlfn.MAXIFS('แผนงาน Schedule'!$J$7:$J$156,'แผนงาน Schedule'!$B$7:$B$156,B12)) -> 46456 | H12: =IF(OR(B12="",COUNTIFS('แผนงาน Schedule'!$B$7:$B$156,B12,'แผนงาน Schedule'!$N$7:$N$156,"<>")=0),"",_xlfn.MINIFS('แผนงาน Schedule'!$N$7:$N$156,'แผนงาน Schedule'!$B$7:$B$156,B12)) | I12: =IF(OR(B12="",N(E12)=0),"",SUMPRODUCT(('แผนงาน Schedule'!$B$7:$B$156=B12)*'แผนงาน Schedule'!$G$7:$G$156*(('แผนงาน Schedule'!$J$7:$J$156<=Dashboard!$C$7)+('แผนงาน Schedule'!$I$7:$I$156<=Dashboard!$C$7)*('แผนงาน Schedule'!$J$7:$J$156>Dashboard!$C$7)*(Dashboard!$C$7-'แผนงาน Schedule'!$I$7:$I$156+1)/('แผนงาน Schedule'!$J$7:$J$156-'แผนงาน Schedule'!$I$7:$I$156+1)))/E12) -> 0 | J12: =IF(OR(B12="",N(E12)=0),"",SUMPRODUCT(('แผนงาน Schedule'!$B$7:$B$156=B12)*'แผนงาน Schedule'!$G$7:$G$156*'แผนงาน Schedule'!$P$7:$P$156)/E12) -> 0 | K12: =IF(I12="","",J12-I12) -> 0 | L12: =IF(OR(I12="",N(I12)=0),"",J12/I12) | M12: =IF(OR(B12="",N(C12)=0),"",_xlfn.MAXIFS('แผนงาน Schedule'!$W$7:$W$156,'แผนงาน Schedule'!$B$7:$B$156,B12)) -> 46456 | N12: =IF(OR(M12="",G12=""),"",M12-G12) -> 0 | O12: =IF(B12="","",COUNTIFS('แผนงาน Schedule'!$B$7:$B$156,B12,'แผนงาน Schedule'!$Y$7:$Y$156,"*ล่าช้า*")+COUNTIFS('แผนงาน Schedule'!$B$7:$B$156,B12,'แผนงาน Schedule'!$Y$7:$Y$156,"*เกินกำหนด*")) -> 0 | P12: =IF(OR(B12="",N(C12)=0),"",IF(N(J12)>=1,"แล้วเสร็จ / Completed",IF(AND(N(I12)=0,N(J12)=0),"ยังไม่เริ่ม / Not Started",IF(N(J12)>=N(I12),"ตามแผน / On Track",IF(N(J12)/I12>=0.9,"เฝ้าระวัง / At Risk","ล่าช้า / Behind"))))) -> ยังไม่เริ่ม / Not Started | Q12: =IF(B12="","",N(I12)*N(E12)) -> 0 | R12: =IF(B12="","",N(J12)*N(E12)) -> 0 | S12: =IF(H12="","",IF(COUNTIFS('แผนงาน Schedule'!$B$7:$B$156,B12,'แผนงาน Schedule'!$D$7:$D$156,"<>",'แผนงาน Schedule'!$O$7:$O$156,"")=0,_xlfn.MAXIFS('แผนงาน Schedule'!$O$7:$O$156,'แผนงาน Schedule'!$B$7:$B$156,B12),'ตั้งค่า Setup'!$C$15))
A13: =IF(B13="","",7) | B13: =IF('ตั้งค่า Setup'!$C$32="","",'ตั้งค่า Setup'!$C$32) | C13: =IF(B13="","",COUNTIFS('แผนงาน Schedule'!$B$7:$B$156,B13,'แผนงาน Schedule'!$D$7:$D$156,"<>")) | D13: =IF(B13="","",SUMIF('แผนงาน Schedule'!$B$7:$B$156,B13,'แผนงาน Schedule'!$H$7:$H$156)) | E13: =IF(B13="","",SUMIF('แผนงาน Schedule'!$B$7:$B$156,B13,'แผนงาน Schedule'!$G$7:$G$156)) | F13: =IF(OR(B13="",N(C13)=0),"",_xlfn.MINIFS('แผนงาน Schedule'!$I$7:$I$156,'แผนงาน Schedule'!$B$7:$B$156,B13)) | G13: =IF(OR(B13="",N(C13)=0),"",_xlfn.MAXIFS('แผนงาน Schedule'!$J$7:$J$156,'แผนงาน Schedule'!$B$7:$B$156,B13)) | H13: =IF(OR(B13="",COUNTIFS('แผนงาน Schedule'!$B$7:$B$156,B13,'แผนงาน Schedule'!$N$7:$N$156,"<>")=0),"",_xlfn.MINIFS('แผนงาน Schedule'!$N$7:$N$156,'แผนงาน Schedule'!$B$7:$B$156,B13)) | I13: =IF(OR(B13="",N(E13)=0),"",SUMPRODUCT(('แผนงาน Schedule'!$B$7:$B$156=B13)*'แผนงาน Schedule'!$G$7:$G$156*(('แผนงาน Schedule'!$J$7:$J$156<=Dashboard!$C$7)+('แผนงาน Schedule'!$I$7:$I$156<=Dashboard!$C$7)*('แผนงาน Schedule'!$J$7:$J$156>Dashboard!$C$7)*(Dashboard!$C$7-'แผนงาน Schedule'!$I$7:$I$156+1)/('แผนงาน Schedule'!$J$7:$J$156-'แผนงาน Schedule'!$I$7:$I$156+1)))/E13) | J13: =IF(OR(B13="",N(E13)=0),"",SUMPRODUCT(('แผนงาน Schedule'!$B$7:$B$156=B13)*'แผนงาน Schedule'!$G$7:$G$156*'แผนงาน Schedule'!$P$7:$P$156)/E13) | K13: =IF(I13="","",J13-I13) | L13: =IF(OR(I13="",N(I13)=0),"",J13/I13) | M13: =IF(OR(B13="",N(C13)=0),"",_xlfn.MAXIFS('แผนงาน Schedule'!$W$7:$W$156,'แผนงาน Schedule'!$B$7:$B$156,B13)) | N13: =IF(OR(M13="",G13=""),"",M13-G13) | O13: =IF(B13="","",COUNTIFS('แผนงาน Schedule'!$B$7:$B$156,B13,'แผนงาน Schedule'!$Y$7:$Y$156,"*ล่าช้า*")+COUNTIFS('แผนงาน Schedule'!$B$7:$B$156,B13,'แผนงาน Schedule'!$Y$7:$Y$156,"*เกินกำหนด*")) | P13: =IF(OR(B13="",N(C13)=0),"",IF(N(J13)>=1,"แล้วเสร็จ / Completed",IF(AND(N(I13)=0,N(J13)=0),"ยังไม่เริ่ม / Not Started",IF(N(J13)>=N(I13),"ตามแผน / On Track",IF(N(J13)/I13>=0.9,"เฝ้าระวัง / At Risk","ล่าช้า / Behind"))))) | Q13: =IF(B13="","",N(I13)*N(E13)) | R13: =IF(B13="","",N(J13)*N(E13)) | S13: =IF(H13="","",IF(COUNTIFS('แผนงาน Schedule'!$B$7:$B$156,B13,'แผนงาน Schedule'!$D$7:$D$156,"<>",'แผนงาน Schedule'!$O$7:$O$156,"")=0,_xlfn.MAXIFS('แผนงาน Schedule'!$O$7:$O$156,'แผนงาน Schedule'!$B$7:$B$156,B13),'ตั้งค่า Setup'!$C$15))
A14: =IF(B14="","",8) | B14: =IF('ตั้งค่า Setup'!$C$33="","",'ตั้งค่า Setup'!$C$33) | C14: =IF(B14="","",COUNTIFS('แผนงาน Schedule'!$B$7:$B$156,B14,'แผนงาน Schedule'!$D$7:$D$156,"<>")) | D14: =IF(B14="","",SUMIF('แผนงาน Schedule'!$B$7:$B$156,B14,'แผนงาน Schedule'!$H$7:$H$156)) | E14: =IF(B14="","",SUMIF('แผนงาน Schedule'!$B$7:$B$156,B14,'แผนงาน Schedule'!$G$7:$G$156)) | F14: =IF(OR(B14="",N(C14)=0),"",_xlfn.MINIFS('แผนงาน Schedule'!$I$7:$I$156,'แผนงาน Schedule'!$B$7:$B$156,B14)) | G14: =IF(OR(B14="",N(C14)=0),"",_xlfn.MAXIFS('แผนงาน Schedule'!$J$7:$J$156,'แผนงาน Schedule'!$B$7:$B$156,B14)) | H14: =IF(OR(B14="",COUNTIFS('แผนงาน Schedule'!$B$7:$B$156,B14,'แผนงาน Schedule'!$N$7:$N$156,"<>")=0),"",_xlfn.MINIFS('แผนงาน Schedule'!$N$7:$N$156,'แผนงาน Schedule'!$B$7:$B$156,B14)) | I14: =IF(OR(B14="",N(E14)=0),"",SUMPRODUCT(('แผนงาน Schedule'!$B$7:$B$156=B14)*'แผนงาน Schedule'!$G$7:$G$156*(('แผนงาน Schedule'!$J$7:$J$156<=Dashboard!$C$7)+('แผนงาน Schedule'!$I$7:$I$156<=Dashboard!$C$7)*('แผนงาน Schedule'!$J$7:$J$156>Dashboard!$C$7)*(Dashboard!$C$7-'แผนงาน Schedule'!$I$7:$I$156+1)/('แผนงาน Schedule'!$J$7:$J$156-'แผนงาน Schedule'!$I$7:$I$156+1)))/E14) | J14: =IF(OR(B14="",N(E14)=0),"",SUMPRODUCT(('แผนงาน Schedule'!$B$7:$B$156=B14)*'แผนงาน Schedule'!$G$7:$G$156*'แผนงาน Schedule'!$P$7:$P$156)/E14) | K14: =IF(I14="","",J14-I14) | L14: =IF(OR(I14="",N(I14)=0),"",J14/I14) | M14: =IF(OR(B14="",N(C14)=0),"",_xlfn.MAXIFS('แผนงาน Schedule'!$W$7:$W$156,'แผนงาน Schedule'!$B$7:$B$156,B14)) | N14: =IF(OR(M14="",G14=""),"",M14-G14) | O14: =IF(B14="","",COUNTIFS('แผนงาน Schedule'!$B$7:$B$156,B14,'แผนงาน Schedule'!$Y$7:$Y$156,"*ล่าช้า*")+COUNTIFS('แผนงาน Schedule'!$B$7:$B$156,B14,'แผนงาน Schedule'!$Y$7:$Y$156,"*เกินกำหนด*")) | P14: =IF(OR(B14="",N(C14)=0),"",IF(N(J14)>=1,"แล้วเสร็จ / Completed",IF(AND(N(I14)=0,N(J14)=0),"ยังไม่เริ่ม / Not Started",IF(N(J14)>=N(I14),"ตามแผน / On Track",IF(N(J14)/I14>=0.9,"เฝ้าระวัง / At Risk","ล่าช้า / Behind"))))) | Q14: =IF(B14="","",N(I14)*N(E14)) | R14: =IF(B14="","",N(J14)*N(E14)) | S14: =IF(H14="","",IF(COUNTIFS('แผนงาน Schedule'!$B$7:$B$156,B14,'แผนงาน Schedule'!$D$7:$D$156,"<>",'แผนงาน Schedule'!$O$7:$O$156,"")=0,_xlfn.MAXIFS('แผนงาน Schedule'!$O$7:$O$156,'แผนงาน Schedule'!$B$7:$B$156,B14),'ตั้งค่า Setup'!$C$15))
A15: =IF(B15="","",9) | B15: =IF('ตั้งค่า Setup'!$C$34="","",'ตั้งค่า Setup'!$C$34) | C15: =IF(B15="","",COUNTIFS('แผนงาน Schedule'!$B$7:$B$156,B15,'แผนงาน Schedule'!$D$7:$D$156,"<>")) | D15: =IF(B15="","",SUMIF('แผนงาน Schedule'!$B$7:$B$156,B15,'แผนงาน Schedule'!$H$7:$H$156)) | E15: =IF(B15="","",SUMIF('แผนงาน Schedule'!$B$7:$B$156,B15,'แผนงาน Schedule'!$G$7:$G$156)) | F15: =IF(OR(B15="",N(C15)=0),"",_xlfn.MINIFS('แผนงาน Schedule'!$I$7:$I$156,'แผนงาน Schedule'!$B$7:$B$156,B15)) | G15: =IF(OR(B15="",N(C15)=0),"",_xlfn.MAXIFS('แผนงาน Schedule'!$J$7:$J$156,'แผนงาน Schedule'!$B$7:$B$156,B15)) | H15: =IF(OR(B15="",COUNTIFS('แผนงาน Schedule'!$B$7:$B$156,B15,'แผนงาน Schedule'!$N$7:$N$156,"<>")=0),"",_xlfn.MINIFS('แผนงาน Schedule'!$N$7:$N$156,'แผนงาน Schedule'!$B$7:$B$156,B15)) | I15: =IF(OR(B15="",N(E15)=0),"",SUMPRODUCT(('แผนงาน Schedule'!$B$7:$B$156=B15)*'แผนงาน Schedule'!$G$7:$G$156*(('แผนงาน Schedule'!$J$7:$J$156<=Dashboard!$C$7)+('แผนงาน Schedule'!$I$7:$I$156<=Dashboard!$C$7)*('แผนงาน Schedule'!$J$7:$J$156>Dashboard!$C$7)*(Dashboard!$C$7-'แผนงาน Schedule'!$I$7:$I$156+1)/('แผนงาน Schedule'!$J$7:$J$156-'แผนงาน Schedule'!$I$7:$I$156+1)))/E15) | J15: =IF(OR(B15="",N(E15)=0),"",SUMPRODUCT(('แผนงาน Schedule'!$B$7:$B$156=B15)*'แผนงาน Schedule'!$G$7:$G$156*'แผนงาน Schedule'!$P$7:$P$156)/E15) | K15: =IF(I15="","",J15-I15) | L15: =IF(OR(I15="",N(I15)=0),"",J15/I15) | M15: =IF(OR(B15="",N(C15)=0),"",_xlfn.MAXIFS('แผนงาน Schedule'!$W$7:$W$156,'แผนงาน Schedule'!$B$7:$B$156,B15)) | N15: =IF(OR(M15="",G15=""),"",M15-G15) | O15: =IF(B15="","",COUNTIFS('แผนงาน Schedule'!$B$7:$B$156,B15,'แผนงาน Schedule'!$Y$7:$Y$156,"*ล่าช้า*")+COUNTIFS('แผนงาน Schedule'!$B$7:$B$156,B15,'แผนงาน Schedule'!$Y$7:$Y$156,"*เกินกำหนด*")) | P15: =IF(OR(B15="",N(C15)=0),"",IF(N(J15)>=1,"แล้วเสร็จ / Completed",IF(AND(N(I15)=0,N(J15)=0),"ยังไม่เริ่ม / Not Started",IF(N(J15)>=N(I15),"ตามแผน / On Track",IF(N(J15)/I15>=0.9,"เฝ้าระวัง / At Risk","ล่าช้า / Behind"))))) | Q15: =IF(B15="","",N(I15)*N(E15)) | R15: =IF(B15="","",N(J15)*N(E15)) | S15: =IF(H15="","",IF(COUNTIFS('แผนงาน Schedule'!$B$7:$B$156,B15,'แผนงาน Schedule'!$D$7:$D$156,"<>",'แผนงาน Schedule'!$O$7:$O$156,"")=0,_xlfn.MAXIFS('แผนงาน Schedule'!$O$7:$O$156,'แผนงาน Schedule'!$B$7:$B$156,B15),'ตั้งค่า Setup'!$C$15))
A16: =IF(B16="","",10) | B16: =IF('ตั้งค่า Setup'!$C$35="","",'ตั้งค่า Setup'!$C$35) | C16: =IF(B16="","",COUNTIFS('แผนงาน Schedule'!$B$7:$B$156,B16,'แผนงาน Schedule'!$D$7:$D$156,"<>")) | D16: =IF(B16="","",SUMIF('แผนงาน Schedule'!$B$7:$B$156,B16,'แผนงาน Schedule'!$H$7:$H$156)) | E16: =IF(B16="","",SUMIF('แผนงาน Schedule'!$B$7:$B$156,B16,'แผนงาน Schedule'!$G$7:$G$156)) | F16: =IF(OR(B16="",N(C16)=0),"",_xlfn.MINIFS('แผนงาน Schedule'!$I$7:$I$156,'แผนงาน Schedule'!$B$7:$B$156,B16)) | G16: =IF(OR(B16="",N(C16)=0),"",_xlfn.MAXIFS('แผนงาน Schedule'!$J$7:$J$156,'แผนงาน Schedule'!$B$7:$B$156,B16)) | H16: =IF(OR(B16="",COUNTIFS('แผนงาน Schedule'!$B$7:$B$156,B16,'แผนงาน Schedule'!$N$7:$N$156,"<>")=0),"",_xlfn.MINIFS('แผนงาน Schedule'!$N$7:$N$156,'แผนงาน Schedule'!$B$7:$B$156,B16)) | I16: =IF(OR(B16="",N(E16)=0),"",SUMPRODUCT(('แผนงาน Schedule'!$B$7:$B$156=B16)*'แผนงาน Schedule'!$G$7:$G$156*(('แผนงาน Schedule'!$J$7:$J$156<=Dashboard!$C$7)+('แผนงาน Schedule'!$I$7:$I$156<=Dashboard!$C$7)*('แผนงาน Schedule'!$J$7:$J$156>Dashboard!$C$7)*(Dashboard!$C$7-'แผนงาน Schedule'!$I$7:$I$156+1)/('แผนงาน Schedule'!$J$7:$J$156-'แผนงาน Schedule'!$I$7:$I$156+1)))/E16) | J16: =IF(OR(B16="",N(E16)=0),"",SUMPRODUCT(('แผนงาน Schedule'!$B$7:$B$156=B16)*'แผนงาน Schedule'!$G$7:$G$156*'แผนงาน Schedule'!$P$7:$P$156)/E16) | K16: =IF(I16="","",J16-I16) | L16: =IF(OR(I16="",N(I16)=0),"",J16/I16) | M16: =IF(OR(B16="",N(C16)=0),"",_xlfn.MAXIFS('แผนงาน Schedule'!$W$7:$W$156,'แผนงาน Schedule'!$B$7:$B$156,B16)) | N16: =IF(OR(M16="",G16=""),"",M16-G16) | O16: =IF(B16="","",COUNTIFS('แผนงาน Schedule'!$B$7:$B$156,B16,'แผนงาน Schedule'!$Y$7:$Y$156,"*ล่าช้า*")+COUNTIFS('แผนงาน Schedule'!$B$7:$B$156,B16,'แผนงาน Schedule'!$Y$7:$Y$156,"*เกินกำหนด*")) | P16: =IF(OR(B16="",N(C16)=0),"",IF(N(J16)>=1,"แล้วเสร็จ / Completed",IF(AND(N(I16)=0,N(J16)=0),"ยังไม่เริ่ม / Not Started",IF(N(J16)>=N(I16),"ตามแผน / On Track",IF(N(J16)/I16>=0.9,"เฝ้าระวัง / At Risk","ล่าช้า / Behind"))))) | Q16: =IF(B16="","",N(I16)*N(E16)) | R16: =IF(B16="","",N(J16)*N(E16)) | S16: =IF(H16="","",IF(COUNTIFS('แผนงาน Schedule'!$B$7:$B$156,B16,'แผนงาน Schedule'!$D$7:$D$156,"<>",'แผนงาน Schedule'!$O$7:$O$156,"")=0,_xlfn.MAXIFS('แผนงาน Schedule'!$O$7:$O$156,'แผนงาน Schedule'!$B$7:$B$156,B16),'ตั้งค่า Setup'!$C$15))
A17: =IF(B17="","",11) | B17: =IF('ตั้งค่า Setup'!$C$36="","",'ตั้งค่า Setup'!$C$36) | C17: =IF(B17="","",COUNTIFS('แผนงาน Schedule'!$B$7:$B$156,B17,'แผนงาน Schedule'!$D$7:$D$156,"<>")) | D17: =IF(B17="","",SUMIF('แผนงาน Schedule'!$B$7:$B$156,B17,'แผนงาน Schedule'!$H$7:$H$156)) | E17: =IF(B17="","",SUMIF('แผนงาน Schedule'!$B$7:$B$156,B17,'แผนงาน Schedule'!$G$7:$G$156)) | F17: =IF(OR(B17="",N(C17)=0),"",_xlfn.MINIFS('แผนงาน Schedule'!$I$7:$I$156,'แผนงาน Schedule'!$B$7:$B$156,B17)) | G17: =IF(OR(B17="",N(C17)=0),"",_xlfn.MAXIFS('แผนงาน Schedule'!$J$7:$J$156,'แผนงาน Schedule'!$B$7:$B$156,B17)) | H17: =IF(OR(B17="",COUNTIFS('แผนงาน Schedule'!$B$7:$B$156,B17,'แผนงาน Schedule'!$N$7:$N$156,"<>")=0),"",_xlfn.MINIFS('แผนงาน Schedule'!$N$7:$N$156,'แผนงาน Schedule'!$B$7:$B$156,B17)) | I17: =IF(OR(B17="",N(E17)=0),"",SUMPRODUCT(('แผนงาน Schedule'!$B$7:$B$156=B17)*'แผนงาน Schedule'!$G$7:$G$156*(('แผนงาน Schedule'!$J$7:$J$156<=Dashboard!$C$7)+('แผนงาน Schedule'!$I$7:$I$156<=Dashboard!$C$7)*('แผนงาน Schedule'!$J$7:$J$156>Dashboard!$C$7)*(Dashboard!$C$7-'แผนงาน Schedule'!$I$7:$I$156+1)/('แผนงาน Schedule'!$J$7:$J$156-'แผนงาน Schedule'!$I$7:$I$156+1)))/E17) | J17: =IF(OR(B17="",N(E17)=0),"",SUMPRODUCT(('แผนงาน Schedule'!$B$7:$B$156=B17)*'แผนงาน Schedule'!$G$7:$G$156*'แผนงาน Schedule'!$P$7:$P$156)/E17) | K17: =IF(I17="","",J17-I17) | L17: =IF(OR(I17="",N(I17)=0),"",J17/I17) | M17: =IF(OR(B17="",N(C17)=0),"",_xlfn.MAXIFS('แผนงาน Schedule'!$W$7:$W$156,'แผนงาน Schedule'!$B$7:$B$156,B17)) | N17: =IF(OR(M17="",G17=""),"",M17-G17) | O17: =IF(B17="","",COUNTIFS('แผนงาน Schedule'!$B$7:$B$156,B17,'แผนงาน Schedule'!$Y$7:$Y$156,"*ล่าช้า*")+COUNTIFS('แผนงาน Schedule'!$B$7:$B$156,B17,'แผนงาน Schedule'!$Y$7:$Y$156,"*เกินกำหนด*")) | P17: =IF(OR(B17="",N(C17)=0),"",IF(N(J17)>=1,"แล้วเสร็จ / Completed",IF(AND(N(I17)=0,N(J17)=0),"ยังไม่เริ่ม / Not Started",IF(N(J17)>=N(I17),"ตามแผน / On Track",IF(N(J17)/I17>=0.9,"เฝ้าระวัง / At Risk","ล่าช้า / Behind"))))) | Q17: =IF(B17="","",N(I17)*N(E17)) | R17: =IF(B17="","",N(J17)*N(E17)) | S17: =IF(H17="","",IF(COUNTIFS('แผนงาน Schedule'!$B$7:$B$156,B17,'แผนงาน Schedule'!$D$7:$D$156,"<>",'แผนงาน Schedule'!$O$7:$O$156,"")=0,_xlfn.MAXIFS('แผนงาน Schedule'!$O$7:$O$156,'แผนงาน Schedule'!$B$7:$B$156,B17),'ตั้งค่า Setup'!$C$15))
A18: =IF(B18="","",12) | B18: =IF('ตั้งค่า Setup'!$C$37="","",'ตั้งค่า Setup'!$C$37) | C18: =IF(B18="","",COUNTIFS('แผนงาน Schedule'!$B$7:$B$156,B18,'แผนงาน Schedule'!$D$7:$D$156,"<>")) | D18: =IF(B18="","",SUMIF('แผนงาน Schedule'!$B$7:$B$156,B18,'แผนงาน Schedule'!$H$7:$H$156)) | E18: =IF(B18="","",SUMIF('แผนงาน Schedule'!$B$7:$B$156,B18,'แผนงาน Schedule'!$G$7:$G$156)) | F18: =IF(OR(B18="",N(C18)=0),"",_xlfn.MINIFS('แผนงาน Schedule'!$I$7:$I$156,'แผนงาน Schedule'!$B$7:$B$156,B18)) | G18: =IF(OR(B18="",N(C18)=0),"",_xlfn.MAXIFS('แผนงาน Schedule'!$J$7:$J$156,'แผนงาน Schedule'!$B$7:$B$156,B18)) | H18: =IF(OR(B18="",COUNTIFS('แผนงาน Schedule'!$B$7:$B$156,B18,'แผนงาน Schedule'!$N$7:$N$156,"<>")=0),"",_xlfn.MINIFS('แผนงาน Schedule'!$N$7:$N$156,'แผนงาน Schedule'!$B$7:$B$156,B18)) | I18: =IF(OR(B18="",N(E18)=0),"",SUMPRODUCT(('แผนงาน Schedule'!$B$7:$B$156=B18)*'แผนงาน Schedule'!$G$7:$G$156*(('แผนงาน Schedule'!$J$7:$J$156<=Dashboard!$C$7)+('แผนงาน Schedule'!$I$7:$I$156<=Dashboard!$C$7)*('แผนงาน Schedule'!$J$7:$J$156>Dashboard!$C$7)*(Dashboard!$C$7-'แผนงาน Schedule'!$I$7:$I$156+1)/('แผนงาน Schedule'!$J$7:$J$156-'แผนงาน Schedule'!$I$7:$I$156+1)))/E18) | J18: =IF(OR(B18="",N(E18)=0),"",SUMPRODUCT(('แผนงาน Schedule'!$B$7:$B$156=B18)*'แผนงาน Schedule'!$G$7:$G$156*'แผนงาน Schedule'!$P$7:$P$156)/E18) | K18: =IF(I18="","",J18-I18) | L18: =IF(OR(I18="",N(I18)=0),"",J18/I18) | M18: =IF(OR(B18="",N(C18)=0),"",_xlfn.MAXIFS('แผนงาน Schedule'!$W$7:$W$156,'แผนงาน Schedule'!$B$7:$B$156,B18)) | N18: =IF(OR(M18="",G18=""),"",M18-G18) | O18: =IF(B18="","",COUNTIFS('แผนงาน Schedule'!$B$7:$B$156,B18,'แผนงาน Schedule'!$Y$7:$Y$156,"*ล่าช้า*")+COUNTIFS('แผนงาน Schedule'!$B$7:$B$156,B18,'แผนงาน Schedule'!$Y$7:$Y$156,"*เกินกำหนด*")) | P18: =IF(OR(B18="",N(C18)=0),"",IF(N(J18)>=1,"แล้วเสร็จ / Completed",IF(AND(N(I18)=0,N(J18)=0),"ยังไม่เริ่ม / Not Started",IF(N(J18)>=N(I18),"ตามแผน / On Track",IF(N(J18)/I18>=0.9,"เฝ้าระวัง / At Risk","ล่าช้า / Behind"))))) | Q18: =IF(B18="","",N(I18)*N(E18)) | R18: =IF(B18="","",N(J18)*N(E18)) | S18: =IF(H18="","",IF(COUNTIFS('แผนงาน Schedule'!$B$7:$B$156,B18,'แผนงาน Schedule'!$D$7:$D$156,"<>",'แผนงาน Schedule'!$O$7:$O$156,"")=0,_xlfn.MAXIFS('แผนงาน Schedule'!$O$7:$O$156,'แผนงาน Schedule'!$B$7:$B$156,B18),'ตั้งค่า Setup'!$C$15))
A19: =IF(B19="","",13) | B19: =IF('ตั้งค่า Setup'!$C$38="","",'ตั้งค่า Setup'!$C$38) | C19: =IF(B19="","",COUNTIFS('แผนงาน Schedule'!$B$7:$B$156,B19,'แผนงาน Schedule'!$D$7:$D$156,"<>")) | D19: =IF(B19="","",SUMIF('แผนงาน Schedule'!$B$7:$B$156,B19,'แผนงาน Schedule'!$H$7:$H$156)) | E19: =IF(B19="","",SUMIF('แผนงาน Schedule'!$B$7:$B$156,B19,'แผนงาน Schedule'!$G$7:$G$156)) | F19: =IF(OR(B19="",N(C19)=0),"",_xlfn.MINIFS('แผนงาน Schedule'!$I$7:$I$156,'แผนงาน Schedule'!$B$7:$B$156,B19)) | G19: =IF(OR(B19="",N(C19)=0),"",_xlfn.MAXIFS('แผนงาน Schedule'!$J$7:$J$156,'แผนงาน Schedule'!$B$7:$B$156,B19)) | H19: =IF(OR(B19="",COUNTIFS('แผนงาน Schedule'!$B$7:$B$156,B19,'แผนงาน Schedule'!$N$7:$N$156,"<>")=0),"",_xlfn.MINIFS('แผนงาน Schedule'!$N$7:$N$156,'แผนงาน Schedule'!$B$7:$B$156,B19)) | I19: =IF(OR(B19="",N(E19)=0),"",SUMPRODUCT(('แผนงาน Schedule'!$B$7:$B$156=B19)*'แผนงาน Schedule'!$G$7:$G$156*(('แผนงาน Schedule'!$J$7:$J$156<=Dashboard!$C$7)+('แผนงาน Schedule'!$I$7:$I$156<=Dashboard!$C$7)*('แผนงาน Schedule'!$J$7:$J$156>Dashboard!$C$7)*(Dashboard!$C$7-'แผนงาน Schedule'!$I$7:$I$156+1)/('แผนงาน Schedule'!$J$7:$J$156-'แผนงาน Schedule'!$I$7:$I$156+1)))/E19) | J19: =IF(OR(B19="",N(E19)=0),"",SUMPRODUCT(('แผนงาน Schedule'!$B$7:$B$156=B19)*'แผนงาน Schedule'!$G$7:$G$156*'แผนงาน Schedule'!$P$7:$P$156)/E19) | K19: =IF(I19="","",J19-I19) | L19: =IF(OR(I19="",N(I19)=0),"",J19/I19) | M19: =IF(OR(B19="",N(C19)=0),"",_xlfn.MAXIFS('แผนงาน Schedule'!$W$7:$W$156,'แผนงาน Schedule'!$B$7:$B$156,B19)) | N19: =IF(OR(M19="",G19=""),"",M19-G19) | O19: =IF(B19="","",COUNTIFS('แผนงาน Schedule'!$B$7:$B$156,B19,'แผนงาน Schedule'!$Y$7:$Y$156,"*ล่าช้า*")+COUNTIFS('แผนงาน Schedule'!$B$7:$B$156,B19,'แผนงาน Schedule'!$Y$7:$Y$156,"*เกินกำหนด*")) | P19: =IF(OR(B19="",N(C19)=0),"",IF(N(J19)>=1,"แล้วเสร็จ / Completed",IF(AND(N(I19)=0,N(J19)=0),"ยังไม่เริ่ม / Not Started",IF(N(J19)>=N(I19),"ตามแผน / On Track",IF(N(J19)/I19>=0.9,"เฝ้าระวัง / At Risk","ล่าช้า / Behind"))))) | Q19: =IF(B19="","",N(I19)*N(E19)) | R19: =IF(B19="","",N(J19)*N(E19)) | S19: =IF(H19="","",IF(COUNTIFS('แผนงาน Schedule'!$B$7:$B$156,B19,'แผนงาน Schedule'!$D$7:$D$156,"<>",'แผนงาน Schedule'!$O$7:$O$156,"")=0,_xlfn.MAXIFS('แผนงาน Schedule'!$O$7:$O$156,'แผนงาน Schedule'!$B$7:$B$156,B19),'ตั้งค่า Setup'!$C$15))
A20: =IF(B20="","",14) | B20: =IF('ตั้งค่า Setup'!$C$39="","",'ตั้งค่า Setup'!$C$39) | C20: =IF(B20="","",COUNTIFS('แผนงาน Schedule'!$B$7:$B$156,B20,'แผนงาน Schedule'!$D$7:$D$156,"<>")) | D20: =IF(B20="","",SUMIF('แผนงาน Schedule'!$B$7:$B$156,B20,'แผนงาน Schedule'!$H$7:$H$156)) | E20: =IF(B20="","",SUMIF('แผนงาน Schedule'!$B$7:$B$156,B20,'แผนงาน Schedule'!$G$7:$G$156)) | F20: =IF(OR(B20="",N(C20)=0),"",_xlfn.MINIFS('แผนงาน Schedule'!$I$7:$I$156,'แผนงาน Schedule'!$B$7:$B$156,B20)) | G20: =IF(OR(B20="",N(C20)=0),"",_xlfn.MAXIFS('แผนงาน Schedule'!$J$7:$J$156,'แผนงาน Schedule'!$B$7:$B$156,B20)) | H20: =IF(OR(B20="",COUNTIFS('แผนงาน Schedule'!$B$7:$B$156,B20,'แผนงาน Schedule'!$N$7:$N$156,"<>")=0),"",_xlfn.MINIFS('แผนงาน Schedule'!$N$7:$N$156,'แผนงาน Schedule'!$B$7:$B$156,B20)) | I20: =IF(OR(B20="",N(E20)=0),"",SUMPRODUCT(('แผนงาน Schedule'!$B$7:$B$156=B20)*'แผนงาน Schedule'!$G$7:$G$156*(('แผนงาน Schedule'!$J$7:$J$156<=Dashboard!$C$7)+('แผนงาน Schedule'!$I$7:$I$156<=Dashboard!$C$7)*('แผนงาน Schedule'!$J$7:$J$156>Dashboard!$C$7)*(Dashboard!$C$7-'แผนงาน Schedule'!$I$7:$I$156+1)/('แผนงาน Schedule'!$J$7:$J$156-'แผนงาน Schedule'!$I$7:$I$156+1)))/E20) | J20: =IF(OR(B20="",N(E20)=0),"",SUMPRODUCT(('แผนงาน Schedule'!$B$7:$B$156=B20)*'แผนงาน Schedule'!$G$7:$G$156*'แผนงาน Schedule'!$P$7:$P$156)/E20) | K20: =IF(I20="","",J20-I20) | L20: =IF(OR(I20="",N(I20)=0),"",J20/I20) | M20: =IF(OR(B20="",N(C20)=0),"",_xlfn.MAXIFS('แผนงาน Schedule'!$W$7:$W$156,'แผนงาน Schedule'!$B$7:$B$156,B20)) | N20: =IF(OR(M20="",G20=""),"",M20-G20) | O20: =IF(B20="","",COUNTIFS('แผนงาน Schedule'!$B$7:$B$156,B20,'แผนงาน Schedule'!$Y$7:$Y$156,"*ล่าช้า*")+COUNTIFS('แผนงาน Schedule'!$B$7:$B$156,B20,'แผนงาน Schedule'!$Y$7:$Y$156,"*เกินกำหนด*")) | P20: =IF(OR(B20="",N(C20)=0),"",IF(N(J20)>=1,"แล้วเสร็จ / Completed",IF(AND(N(I20)=0,N(J20)=0),"ยังไม่เริ่ม / Not Started",IF(N(J20)>=N(I20),"ตามแผน / On Track",IF(N(J20)/I20>=0.9,"เฝ้าระวัง / At Risk","ล่าช้า / Behind"))))) | Q20: =IF(B20="","",N(I20)*N(E20)) | R20: =IF(B20="","",N(J20)*N(E20)) | S20: =IF(H20="","",IF(COUNTIFS('แผนงาน Schedule'!$B$7:$B$156,B20,'แผนงาน Schedule'!$D$7:$D$156,"<>",'แผนงาน Schedule'!$O$7:$O$156,"")=0,_xlfn.MAXIFS('แผนงาน Schedule'!$O$7:$O$156,'แผนงาน Schedule'!$B$7:$B$156,B20),'ตั้งค่า Setup'!$C$15))
A21: =IF(B21="","",15) | B21: =IF('ตั้งค่า Setup'!$C$40="","",'ตั้งค่า Setup'!$C$40) | C21: =IF(B21="","",COUNTIFS('แผนงาน Schedule'!$B$7:$B$156,B21,'แผนงาน Schedule'!$D$7:$D$156,"<>")) | D21: =IF(B21="","",SUMIF('แผนงาน Schedule'!$B$7:$B$156,B21,'แผนงาน Schedule'!$H$7:$H$156)) | E21: =IF(B21="","",SUMIF('แผนงาน Schedule'!$B$7:$B$156,B21,'แผนงาน Schedule'!$G$7:$G$156)) | F21: =IF(OR(B21="",N(C21)=0),"",_xlfn.MINIFS('แผนงาน Schedule'!$I$7:$I$156,'แผนงาน Schedule'!$B$7:$B$156,B21)) | G21: =IF(OR(B21="",N(C21)=0),"",_xlfn.MAXIFS('แผนงาน Schedule'!$J$7:$J$156,'แผนงาน Schedule'!$B$7:$B$156,B21)) | H21: =IF(OR(B21="",COUNTIFS('แผนงาน Schedule'!$B$7:$B$156,B21,'แผนงาน Schedule'!$N$7:$N$156,"<>")=0),"",_xlfn.MINIFS('แผนงาน Schedule'!$N$7:$N$156,'แผนงาน Schedule'!$B$7:$B$156,B21)) | I21: =IF(OR(B21="",N(E21)=0),"",SUMPRODUCT(('แผนงาน Schedule'!$B$7:$B$156=B21)*'แผนงาน Schedule'!$G$7:$G$156*(('แผนงาน Schedule'!$J$7:$J$156<=Dashboard!$C$7)+('แผนงาน Schedule'!$I$7:$I$156<=Dashboard!$C$7)*('แผนงาน Schedule'!$J$7:$J$156>Dashboard!$C$7)*(Dashboard!$C$7-'แผนงาน Schedule'!$I$7:$I$156+1)/('แผนงาน Schedule'!$J$7:$J$156-'แผนงาน Schedule'!$I$7:$I$156+1)))/E21) | J21: =IF(OR(B21="",N(E21)=0),"",SUMPRODUCT(('แผนงาน Schedule'!$B$7:$B$156=B21)*'แผนงาน Schedule'!$G$7:$G$156*'แผนงาน Schedule'!$P$7:$P$156)/E21) | K21: =IF(I21="","",J21-I21) | L21: =IF(OR(I21="",N(I21)=0),"",J21/I21) | M21: =IF(OR(B21="",N(C21)=0),"",_xlfn.MAXIFS('แผนงาน Schedule'!$W$7:$W$156,'แผนงาน Schedule'!$B$7:$B$156,B21)) | N21: =IF(OR(M21="",G21=""),"",M21-G21) | O21: =IF(B21="","",COUNTIFS('แผนงาน Schedule'!$B$7:$B$156,B21,'แผนงาน Schedule'!$Y$7:$Y$156,"*ล่าช้า*")+COUNTIFS('แผนงาน Schedule'!$B$7:$B$156,B21,'แผนงาน Schedule'!$Y$7:$Y$156,"*เกินกำหนด*")) | P21: =IF(OR(B21="",N(C21)=0),"",IF(N(J21)>=1,"แล้วเสร็จ / Completed",IF(AND(N(I21)=0,N(J21)=0),"ยังไม่เริ่ม / Not Started",IF(N(J21)>=N(I21),"ตามแผน / On Track",IF(N(J21)/I21>=0.9,"เฝ้าระวัง / At Risk","ล่าช้า / Behind"))))) | Q21: =IF(B21="","",N(I21)*N(E21)) | R21: =IF(B21="","",N(J21)*N(E21)) | S21: =IF(H21="","",IF(COUNTIFS('แผนงาน Schedule'!$B$7:$B$156,B21,'แผนงาน Schedule'!$D$7:$D$156,"<>",'แผนงาน Schedule'!$O$7:$O$156,"")=0,_xlfn.MAXIFS('แผนงาน Schedule'!$O$7:$O$156,'แผนงาน Schedule'!$B$7:$B$156,B21),'ตั้งค่า Setup'!$C$15))
A22: =IF(B22="","",16) | B22: =IF('ตั้งค่า Setup'!$C$41="","",'ตั้งค่า Setup'!$C$41) | C22: =IF(B22="","",COUNTIFS('แผนงาน Schedule'!$B$7:$B$156,B22,'แผนงาน Schedule'!$D$7:$D$156,"<>")) | D22: =IF(B22="","",SUMIF('แผนงาน Schedule'!$B$7:$B$156,B22,'แผนงาน Schedule'!$H$7:$H$156)) | E22: =IF(B22="","",SUMIF('แผนงาน Schedule'!$B$7:$B$156,B22,'แผนงาน Schedule'!$G$7:$G$156)) | F22: =IF(OR(B22="",N(C22)=0),"",_xlfn.MINIFS('แผนงาน Schedule'!$I$7:$I$156,'แผนงาน Schedule'!$B$7:$B$156,B22)) | G22: =IF(OR(B22="",N(C22)=0),"",_xlfn.MAXIFS('แผนงาน Schedule'!$J$7:$J$156,'แผนงาน Schedule'!$B$7:$B$156,B22)) | H22: =IF(OR(B22="",COUNTIFS('แผนงาน Schedule'!$B$7:$B$156,B22,'แผนงาน Schedule'!$N$7:$N$156,"<>")=0),"",_xlfn.MINIFS('แผนงาน Schedule'!$N$7:$N$156,'แผนงาน Schedule'!$B$7:$B$156,B22)) | I22: =IF(OR(B22="",N(E22)=0),"",SUMPRODUCT(('แผนงาน Schedule'!$B$7:$B$156=B22)*'แผนงาน Schedule'!$G$7:$G$156*(('แผนงาน Schedule'!$J$7:$J$156<=Dashboard!$C$7)+('แผนงาน Schedule'!$I$7:$I$156<=Dashboard!$C$7)*('แผนงาน Schedule'!$J$7:$J$156>Dashboard!$C$7)*(Dashboard!$C$7-'แผนงาน Schedule'!$I$7:$I$156+1)/('แผนงาน Schedule'!$J$7:$J$156-'แผนงาน Schedule'!$I$7:$I$156+1)))/E22) | J22: =IF(OR(B22="",N(E22)=0),"",SUMPRODUCT(('แผนงาน Schedule'!$B$7:$B$156=B22)*'แผนงาน Schedule'!$G$7:$G$156*'แผนงาน Schedule'!$P$7:$P$156)/E22) | K22: =IF(I22="","",J22-I22) | L22: =IF(OR(I22="",N(I22)=0),"",J22/I22) | M22: =IF(OR(B22="",N(C22)=0),"",_xlfn.MAXIFS('แผนงาน Schedule'!$W$7:$W$156,'แผนงาน Schedule'!$B$7:$B$156,B22)) | N22: =IF(OR(M22="",G22=""),"",M22-G22) | O22: =IF(B22="","",COUNTIFS('แผนงาน Schedule'!$B$7:$B$156,B22,'แผนงาน Schedule'!$Y$7:$Y$156,"*ล่าช้า*")+COUNTIFS('แผนงาน Schedule'!$B$7:$B$156,B22,'แผนงาน Schedule'!$Y$7:$Y$156,"*เกินกำหนด*")) | P22: =IF(OR(B22="",N(C22)=0),"",IF(N(J22)>=1,"แล้วเสร็จ / Completed",IF(AND(N(I22)=0,N(J22)=0),"ยังไม่เริ่ม / Not Started",IF(N(J22)>=N(I22),"ตามแผน / On Track",IF(N(J22)/I22>=0.9,"เฝ้าระวัง / At Risk","ล่าช้า / Behind"))))) | Q22: =IF(B22="","",N(I22)*N(E22)) | R22: =IF(B22="","",N(J22)*N(E22)) | S22: =IF(H22="","",IF(COUNTIFS('แผนงาน Schedule'!$B$7:$B$156,B22,'แผนงาน Schedule'!$D$7:$D$156,"<>",'แผนงาน Schedule'!$O$7:$O$156,"")=0,_xlfn.MAXIFS('แผนงาน Schedule'!$O$7:$O$156,'แผนงาน Schedule'!$B$7:$B$156,B22),'ตั้งค่า Setup'!$C$15))
A23: =IF(B23="","",17) | B23: =IF('ตั้งค่า Setup'!$C$42="","",'ตั้งค่า Setup'!$C$42) | C23: =IF(B23="","",COUNTIFS('แผนงาน Schedule'!$B$7:$B$156,B23,'แผนงาน Schedule'!$D$7:$D$156,"<>")) | D23: =IF(B23="","",SUMIF('แผนงาน Schedule'!$B$7:$B$156,B23,'แผนงาน Schedule'!$H$7:$H$156)) | E23: =IF(B23="","",SUMIF('แผนงาน Schedule'!$B$7:$B$156,B23,'แผนงาน Schedule'!$G$7:$G$156)) | F23: =IF(OR(B23="",N(C23)=0),"",_xlfn.MINIFS('แผนงาน Schedule'!$I$7:$I$156,'แผนงาน Schedule'!$B$7:$B$156,B23)) | G23: =IF(OR(B23="",N(C23)=0),"",_xlfn.MAXIFS('แผนงาน Schedule'!$J$7:$J$156,'แผนงาน Schedule'!$B$7:$B$156,B23)) | H23: =IF(OR(B23="",COUNTIFS('แผนงาน Schedule'!$B$7:$B$156,B23,'แผนงาน Schedule'!$N$7:$N$156,"<>")=0),"",_xlfn.MINIFS('แผนงาน Schedule'!$N$7:$N$156,'แผนงาน Schedule'!$B$7:$B$156,B23)) | I23: =IF(OR(B23="",N(E23)=0),"",SUMPRODUCT(('แผนงาน Schedule'!$B$7:$B$156=B23)*'แผนงาน Schedule'!$G$7:$G$156*(('แผนงาน Schedule'!$J$7:$J$156<=Dashboard!$C$7)+('แผนงาน Schedule'!$I$7:$I$156<=Dashboard!$C$7)*('แผนงาน Schedule'!$J$7:$J$156>Dashboard!$C$7)*(Dashboard!$C$7-'แผนงาน Schedule'!$I$7:$I$156+1)/('แผนงาน Schedule'!$J$7:$J$156-'แผนงาน Schedule'!$I$7:$I$156+1)))/E23) | J23: =IF(OR(B23="",N(E23)=0),"",SUMPRODUCT(('แผนงาน Schedule'!$B$7:$B$156=B23)*'แผนงาน Schedule'!$G$7:$G$156*'แผนงาน Schedule'!$P$7:$P$156)/E23) | K23: =IF(I23="","",J23-I23) | L23: =IF(OR(I23="",N(I23)=0),"",J23/I23) | M23: =IF(OR(B23="",N(C23)=0),"",_xlfn.MAXIFS('แผนงาน Schedule'!$W$7:$W$156,'แผนงาน Schedule'!$B$7:$B$156,B23)) | N23: =IF(OR(M23="",G23=""),"",M23-G23) | O23: =IF(B23="","",COUNTIFS('แผนงาน Schedule'!$B$7:$B$156,B23,'แผนงาน Schedule'!$Y$7:$Y$156,"*ล่าช้า*")+COUNTIFS('แผนงาน Schedule'!$B$7:$B$156,B23,'แผนงาน Schedule'!$Y$7:$Y$156,"*เกินกำหนด*")) | P23: =IF(OR(B23="",N(C23)=0),"",IF(N(J23)>=1,"แล้วเสร็จ / Completed",IF(AND(N(I23)=0,N(J23)=0),"ยังไม่เริ่ม / Not Started",IF(N(J23)>=N(I23),"ตามแผน / On Track",IF(N(J23)/I23>=0.9,"เฝ้าระวัง / At Risk","ล่าช้า / Behind"))))) | Q23: =IF(B23="","",N(I23)*N(E23)) | R23: =IF(B23="","",N(J23)*N(E23)) | S23: =IF(H23="","",IF(COUNTIFS('แผนงาน Schedule'!$B$7:$B$156,B23,'แผนงาน Schedule'!$D$7:$D$156,"<>",'แผนงาน Schedule'!$O$7:$O$156,"")=0,_xlfn.MAXIFS('แผนงาน Schedule'!$O$7:$O$156,'แผนงาน Schedule'!$B$7:$B$156,B23),'ตั้งค่า Setup'!$C$15))
